Workbook

Sheet Plant utilization
G1: Work days | H1: xxxx | J1: Date : | K1: xxxx | AG1: 2600 | AH1: =AG1/D48 -> 3.7142857
A2: Resource Capacity Utilization Report -Month xxxx | J2: Project Name : | AG2: T SWAMY | AO2: NAGARAJAN | AW2: A.K. SINGH
A3: S.No. | B3: Description | C3: Budget | E3: Unit | F3: Actual (for the day) | J3: Cumulative for the Month | O3: Site conditions (Actual) | S3: =4400*0.6 -> 2640 | Z3: 44 | AA3: 50
C4: Unit | D4: Prod'vity Norm | F4: Work done Quantity for the day | G4: Budgeted Days | H4: Actual Days | I4: % of Utiliz'tn | J4: Cumulative Work done | K4: Budgeted Days | L4: Actual Days | M4: % of Utiliz'tn | S4: =4400/S3 -> 1.6666667 | T4: =100% -> 1 | Z4: 11 | AA4: 16 | AG4: Work done Quantity for the day | AH4: Budgeted Days | AI4: Actual Days | AJ4: % of Utiliz'tn | AK4: Cumulative Work done | AL4: Budgeted Days | AM4: Actual Days | AN4: % of Utiliz'tn | AO4: Work done Quantity for the day | AP4: Budgeted Days | AQ4: Actual Days | AR4: % of Utiliz'tn | AS4: Cumulative Work done | AT4: Budgeted Days | AU4: Actual Days | AV4: % of Utiliz'tn | AW4: Work done Quantity for the day | AX4: Budgeted Days | AY4: Actual Days | AZ4: % of Utiliz'tn | BA4: Cumulative Work done | BB4: Budgeted Days | BC4: Actual Days | BD4: % of Utiliz'tn
O5: Prod'vity Norm | P5: Budgeted Days | Q5: % Utiliz'tn (Actual)
A7: 1 | B7: Bull Dozer | G7: =SUM(G8:G17) -> 0 | I7: =IFERROR(G7/H7,0) -> 0 | K7: =SUM(K8:K17) -> 0 | M7: =IFERROR(K7/L7,0) -> 0 | P7: =SUM(P8:P17) -> 0 | Q7: =P7/L7 -> #DIV/0! | T7: =K7-L7 -> 0 | U7: 103.56 | V7: =T7*U7 -> 0 | Z7: 7 | AH7: =SUM(AH8:AH17) -> #REF! | AI7: =VLOOKUP($B7,'[5]Eqpmnt & MP Days'!$B$4:$H$11,2,0) -> 3.75 | AJ7: =IFERROR(AH7/AI7,"") | AL7: =SUM(AL8:AL17) -> #REF! | AM7: =VLOOKUP($B7,'[5]Eqpmnt & MP Days'!$B$4:$H$11,3,0) -> 90 | AN7: =IFERROR(AL7/AM7,"") | AP7: =SUM(AP8:AP17) -> #REF! | AQ7: =VLOOKUP($B7,'[5]Eqpmnt & MP Days'!$B$4:$H$11,4,0) -> 1.75 | AR7: =IFERROR(AP7/AQ7,"") | AT7: =SUM(AT8:AT17) -> #REF! | AU7: =VLOOKUP($B7,'[5]Eqpmnt & MP Days'!$B$4:$H$11,5,0) -> 42 | AV7: =IFERROR(AT7/AU7,"") | AX7: =IFERROR(SUM(AX8:AX17),"") | AY7: =IFERROR(VLOOKUP($B7,'[5]Eqpmnt & MP Days'!$B$4:$H$11,6,0),"") -> 0 | AZ7: =IFERROR(AX7/AY7,"") | BB7: =SUM(BB8:BB17) -> #REF! | BC7: =VLOOKUP($B7,'[5]Eqpmnt & MP Days'!$B$4:$H$11,7,0) -> 0 | BD7: =IFERROR(BB7/BC7,"")
B8: Clearing & grubbing | C8: Sqm/Day | D8: 4000 | E8: Sqm | K8: =J8/D8 -> 0 | O8: 4000 | P8: =J8/O8 -> 0 | AG8: =#REF!+#REF! -> #REF! | AH8: =AG8/$D8 -> #REF! | AK8: =#REF!+#REF! -> #REF! | AL8: =AK8/$D8 -> #REF! | AO8: =#REF!+#REF! -> #REF! | AP8: =AO8/$D8 -> #REF! | AS8: =#REF!+#REF! -> #REF! | AT8: =AS8/$D8 -> #REF! | AW8: =#REF!+#REF! -> #REF! | AX8: =AW8/$D8 -> #REF! | BA8: =#REF!+#REF! -> #REF! | BB8: =BA8/$D8 -> #REF!
B9: Unclassified Excavation | C9: Cum/day | D9: 900 | E9: Cum | K9: =J9/D9 -> 0 | O9: 900 | P9: =J9/O9 -> 0 | AG9: =#REF!+#REF!+#REF! -> #REF! | AH9: =AG9/$D9 -> #REF! | AK9: =#REF!+#REF!+#REF! -> #REF! | AL9: =AK9/$D9 -> #REF! | AO9: =#REF!+#REF!+#REF! -> #REF! | AP9: =AO9/$D9 -> #REF! | AS9: =#REF!+#REF!+#REF! -> #REF! | AT9: =AS9/$D9 -> #REF! | AW9: =#REF!+#REF!+#REF! -> #REF! | AX9: =AW9/$D9 -> #REF! | BA9: =#REF!+#REF!+#REF! -> #REF! | BB9: =BA9/$D9 -> #REF!
B10: Collection of material for EMB | C10: Cum/day | D10: =1000/1.2 -> 833.33333 | E10: Cum | K10: =J10/D10 -> 0 | O10: =1000/(1.4) -> 714.28571 | P10: =J10/O10 -> 0 | AG10: =(#REF!+#REF!) -> #REF! | AH10: =AG10/$D10 -> #REF! | AK10: =(#REF!+#REF!) -> #REF! | AL10: =AK10/$D10 -> #REF! | AO10: =(#REF!+#REF!) -> #REF! | AP10: =AO10/$D10 -> #REF! | AS10: =(#REF!+#REF!) -> #REF! | AT10: =AS10/$D10 -> #REF! | AW10: =(#REF!+#REF!) -> #REF! | AX10: =AW10/$D10 -> #REF! | BA10: =(#REF!+#REF!) -> #REF! | BB10: =BA10/$D10 -> #REF!
B11: Subgrade Preparation in cut | C11: Sqm/Day | D11: 1000 | E11: Sqm | K11: =J11/D11 -> 0 | O11: 1000 | P11: 0 | AG11: =#REF!*0.5 -> #REF! | AH11: =AG11/$D11 -> #REF! | AK11: =#REF! -> #REF! | AL11: =AK11/$D11 -> #REF! | AO11: =#REF!*0.5 -> #REF! | AP11: =AO11/$D11 -> #REF! | AS11: =#REF! -> #REF! | AT11: =AS11/$D11 -> #REF! | AW11: =#REF!*0.5 -> #REF! | AX11: =AW11/$D11 -> #REF! | BA11: =#REF! -> #REF! | BB11: =BA11/$D11 -> #REF!
B12: Collection of material for GSB | C12: Cum/day | D12: =1000/1.1 -> 909.09091 | E12: Cum | K12: =J12/D12 -> 0 | O12: 1154 | P12: =J12/O12 -> 0 | AG12: =(#REF!+#REF!+#REF!)*1 -> #REF! | AH12: =AG12/$D12 -> #REF! | AK12: =(#REF!+#REF!+#REF!) -> #REF! | AL12: =AK12/$D12 -> #REF! | AO12: =(#REF!+#REF!+#REF!)*1 -> #REF! | AP12: =AO12/$D12 -> #REF! | AS12: =(#REF!+#REF!+#REF!) -> #REF! | AT12: =AS12/$D12 -> #REF! | AW12: =(#REF!+#REF!+#REF!)*1 -> #REF! | AX12: =AW12/$D12 -> #REF! | BA12: =(#REF!+#REF!+#REF!) -> #REF! | BB12: =BA12/$D12 -> #REF!
B13: Extraction of ABC material | C13: Cum/day | D13: =1200/1.4 -> 857.14286 | E13: Cum | K13: =J13/D13 -> 0 | O13: 857 | P13: =J13/O13 -> 0 | AG13: =#REF! -> #REF! | AH13: =AG13/$D13 -> #REF! | AK13: =#REF! -> #REF! | AL13: =AK13/$D13 -> #REF! | AO13: =#REF! -> #REF! | AP13: =AO13/$D13 -> #REF! | AS13: =#REF! -> #REF! | AT13: =AS13/$D13 -> #REF! | AW13: =#REF! -> #REF! | AX13: =AW13/$D13 -> #REF! | BA13: =#REF! -> #REF! | BB13: =BA13/$D13 -> #REF!
B14: BBC/BWC Aggregate borrow excavation | C14: Cum/day | D14: =1200/(1.6*1.3) -> 576.92308 | E14: Cum | K14: =J14/D14 -> 0 | O14: 577 | P14: =J14/O14 -> 0 | AG14: =#REF!+#REF!+#REF!+#REF!+#REF! -> #REF! | AH14: =AG14/$D14 -> #REF! | AK14: =#REF!+#REF!+#REF!+#REF!+#REF! -> #REF! | AL14: =AK14/$D14 -> #REF! | AO14: =#REF!+#REF!+#REF!+#REF!+#REF! -> #REF! | AS14: =#REF!+#REF!+#REF!+#REF!+#REF! -> #REF! | AW14: =#REF!+#REF!+#REF!+#REF!+#REF! -> #REF! | AX14: =AW14/$D14 -> #REF! | BA14: =#REF!+#REF!+#REF!+#REF!+#REF! -> #REF! | BB14: =BA14/$D14 -> #REF!
B15: Maintenance and protection of Trafic | C15: Cum/day | D15: =1000/1.2 -> 833.33333 | E15: Cum | G15: =F15/D15 -> 0 | K15: =J15/D15 -> 0 | O15: 1000 | P15: =J15/O15 -> 0 | AH15: =AG15/$D15 -> 0 | AL15: =AK15/$D15 -> 0 | AP15: =AO15/$D15 -> 0 | AT15: =AS15/$D15 -> 0 | AX15: =AW15/$D15 -> 0 | BB15: =BA15/$D15 -> 0
B16: Maintenance of Access Roads / Area levelling | G16: 0 | K16: 0
B17: Mobile Crusher | C17: Cum/day | D17: 550 | E17: Cum | G17: =F17/D17 -> 0 | K17: =J17/D17 -> 0 | O17: 550 | P17: =J17/O17 -> 0 | AH17: =AG17/$D17 -> 0 | AL17: =AK17/$D17 -> 0 | AP17: =AO17/$D17 -> 0 | AT17: =AS17/$D17 -> 0 | AX17: =AW17/$D17 -> 0 | BB17: =BA17/$D17 -> 0
A18: 2 | B18: Front End Loader | G18: =SUM(G19:G44) -> 0 | I18: =IFERROR(G18/H18,0) -> 0 | K18: =SUM(K19:K44) -> 0 | M18: =IFERROR(K18/L18,0) -> 0 | P18: =SUM(P19:P44) -> 0 | Q18: =P18/L18 -> #DIV/0! | T18: =K18-L18 -> 0 | U18: 84.75 | V18: =T18*U18 -> 0 | AH18: =SUM(AH19:AH44) -> #REF! | AI18: =VLOOKUP($B18,'[5]Eqpmnt & MP Days'!$B$4:$H$11,2,0) -> 11.75 | AJ18: =IFERROR(AH18/AI18,"") | AL18: =SUM(AL19:AL44) -> #REF! | AM18: =VLOOKUP($B18,'[5]Eqpmnt & MP Days'!$B$4:$H$11,3,0) -> 282 | AN18: =IFERROR(AL18/AM18,"") | AP18: =SUM(AP19:AP44) -> #REF! | AQ18: =VLOOKUP($B18,'[5]Eqpmnt & MP Days'!$B$4:$H$11,4,0) -> 4.75 | AR18: =IFERROR(AP18/AQ18,"") | AT18: =SUM(AT19:AT44) -> #REF! | AU18: =VLOOKUP($B18,'[5]Eqpmnt & MP Days'!$B$4:$H$11,5,0) -> 114 | AV18: =IFERROR(AT18/AU18,"") | AX18: =SUM(AX19:AX44) -> #REF! | AY18: =VLOOKUP($B18,'[5]Eqpmnt & MP Days'!$B$4:$H$11,6,0) -> 1 | AZ18: =IFERROR(AX18/AY18,"") | BB18: =SUM(BB19:BB44) -> #REF! | BC18: =VLOOKUP($B18,'[5]Eqpmnt & MP Days'!$B$4:$H$11,7,0) -> 24 | BD18: =IFERROR(BB18/BC18,"")
B19: Clearing & grubbing | C19: Sqm/Day | D19: 3000 | E19: Sqm | F19: =F8 -> 0 | G19: =F19/D19 -> 0 | J19: =J8 -> 0 | K19: =J19/D19 -> 0 | O19: 3000 | P19: =J19/O19 -> 0 | AG19: =AG8 -> #REF! | AH19: =AG19/$D19 -> #REF! | AK19: =AK8 -> #REF! | AL19: =AK19/$D19 -> #REF! | AO19: =AO8 -> #REF! | AP19: =AO19/$D19 -> #REF! | AS19: =AS8 -> #REF! | AT19: =AS19/$D19 -> #REF! | AW19: =AW8 -> #REF! | AX19: =AW19/$D19 -> #REF! | BA19: =BA8 -> #REF! | BB19: =BA19/$D19 -> #REF!
B20: Unclassified Excavation | C20: Cum/day | D20: 600 | E20: Cum | F20: =F9 -> 0 | G20: =F20/D20 -> 0 | J20: =J9 -> 0 | K20: =J20/D20 -> 0 | O20: 600 | P20: =J20/O20 -> 0 | AG20: =AG9 -> #REF! | AH20: =AG20/$D20 -> #REF! | AK20: =AK9 -> #REF! | AL20: =AK20/$D20 -> #REF! | AO20: =AO9 -> #REF! | AP20: =AO20/$D20 -> #REF! | AS20: =AS9 -> #REF! | AT20: =AS20/$D20 -> #REF! | AW20: =AW9 -> #REF! | AX20: =AW20/$D20 -> #REF! | BA20: =BA9 -> #REF! | BB20: =BA20/$D20 -> #REF!
B21: Feeding to Tippers (Bar Screen) | C21: Cum/day | D21: 727 | E21: Cum | O21: =D21 -> 727 | P21: =J21/O21 -> 0 | AG21: =AG10*0 -> #REF! | AH21: =AG21/$D21 -> #REF! | AK21: =AK10*0 -> #REF! | AL21: =AK21/$D21 -> #REF! | AO21: =AO10*0 -> #REF! | AP21: =AO21/$D21 -> #REF! | AS21: =AS10*0 -> #REF! | AT21: =AS21/$D21 -> #REF! | AW21: =AW10*0 -> #REF! | AX21: =AW21/$D21 -> #REF! | BA21: =BA10*0 -> #REF! | BB21: =BA21/$D21 -> #REF!
B22: Asphalt Removal | C22: Cum/day | D22: 60 | E22: Cum | AG22: =#REF! -> #REF! | AH22: =AG22/$D22 -> #REF! | AK22: =#REF! -> #REF! | AL22: =AK22/$D22 -> #REF! | AO22: =#REF! -> #REF! | AP22: =AO22/$D22 -> #REF! | AS22: =#REF! -> #REF! | AT22: =AS22/$D22 -> #REF! | AW22: =#REF! -> #REF! | AX22: =AW22/$D22 -> #REF! | BA22: =#REF! -> #REF! | BB22: =BA22/$D22 -> #REF!
B23: Collection of screened material for Embankment | C23: Cum/day | D23: =800/1.1 -> 727.27273 | E23: Cum | O23: 1250 | P23: =J23/O23 -> 0 | AG23: =+AG10 -> #REF! | AH23: =AG23/$D23 -> #REF! | AK23: =AK10 -> #REF! | AL23: =AK23/$D23 -> #REF! | AO23: =+AO10 -> #REF! | AP23: =AO23/$D23 -> #REF! | AS23: =AS10 -> #REF! | AT23: =AS23/$D23 -> #REF! | AW23: =+AW10 -> #REF! | AX23: =AW23/$D23 -> #REF! | BA23: =BA10 -> #REF! | BB23: =BA23/$D23 -> #REF!
B24: Subgrade Preparation in cut | C24: Cum/day | D24: 1000 | E24: Cum | AG24: =#REF! -> #REF! | AH24: =AG24/$D24 -> #REF! | AK24: =#REF! -> #REF! | AL24: =AK24/$D24 -> #REF! | AO24: =#REF! -> #REF! | AP24: =AO24/$D24 -> #REF! | AS24: =#REF! -> #REF! | AT24: =AS24/$D24 -> #REF! | AW24: =#REF! -> #REF! | AX24: =AW24/$D24 -> #REF! | BA24: =#REF! -> #REF! | BB24: =BA24/$D24 -> #REF!
B25: Granular sub base - Extraction & screening | C25: Cum/day | D25: 636 | E25: Cum | O25: 1154 | P25: =J25/O25 -> 0 | AG25: =+AG12 -> #REF! | AH25: =AG25/$D25 -> #REF! | AK25: =+AK12 -> #REF! | AL25: =AK25/$D25 -> #REF! | AO25: =+AO12 -> #REF! | AP25: =AO25/$D25 -> #REF! | AS25: =+AS12 -> #REF! | AT25: =AS25/$D25 -> #REF! | AW25: =+AW12 -> #REF! | AX25: =AW25/$D25 -> #REF! | BA25: =+BA12 -> #REF! | BB25: =BA25/$D25 -> #REF!
B26: ABC - Extraction & screening | C26: Cum/day | D26: 700 | E26: Cum | O26: 1190 | P26: =J26/O26 -> 0 | AG26: =#REF! -> #REF! | AH26: =AG26/$D26 -> #REF! | AK26: =#REF! -> #REF! | AL26: =AK26/$D26 -> #REF! | AO26: =#REF! -> #REF! | AP26: =AO26/$D26 -> #REF! | AS26: =#REF! -> #REF! | AT26: =AS26/$D26 -> #REF! | AW26: =#REF! -> #REF! | AX26: =AW26/$D26 -> #REF! | BA26: =#REF! -> #REF! | BB26: =BA26/$D26 -> #REF!
B27: Loading & Mixing of Embankment material | C27: Cum/day | D27: 700 | E27: Cum | O27: 900 | P27: =J27/O27 -> 0 | AG27: =#REF! -> #REF! | AH27: =AG27/$D27 -> #REF! | AK27: =#REF! -> #REF! | AL27: =AK27/$D27 -> #REF! | AO27: =#REF! -> #REF! | AP27: =AO27/$D27 -> #REF! | AS27: =#REF! -> #REF! | AT27: =AS27/$D27 -> #REF! | AW27: =#REF! -> #REF! | AX27: =AW27/$D27 -> #REF! | BA27: =#REF! -> #REF! | BB27: =BA27/$D27 -> #REF!
B28: Loading & Mixing of GSB material | C28: Cum/day | D28: 900 | E28: Cum | O28: 900 | P28: =J28/O28 -> 0 | AG28: =#REF!+#REF! -> #REF! | AH28: =AG28/$D28 -> #REF! | AK28: =#REF!+#REF! -> #REF! | AL28: =AK28/$D28 -> #REF! | AO28: =#REF!+#REF! -> #REF! | AP28: =AO28/$D28 -> #REF! | AS28: =#REF!+#REF! -> #REF! | AT28: =AS28/$D28 -> #REF! | AW28: =#REF!+#REF! -> #REF! | AX28: =AW28/$D28 -> #REF! | BA28: =#REF!+#REF! -> #REF! | BB28: =BA28/$D28 -> #REF!
B29: ABC - Loading to ABC plant | C29: Cum/day | D29: 700 | E29: Cum | O29: 700 | P29: =J29/O29 -> 0 | AG29: 0 | AH29: =AG29/$D29 -> 0 | AK29: 0 | AL29: =AK29/$D29 -> 0 | AO29: 0 | AP29: =AO29/$D29 -> 0 | AS29: 0 | AT29: =AS29/$D29 -> 0 | AW29: 0 | AX29: =AW29/$D29 -> 0 | BA29: 0 | BB29: =BA29/$D29 -> 0
B30: ABC - Loading to ABC plant | C30: Cum/day | D30: 500 | E30: Cum | O30: 500 | P30: =J30/O30 -> 0 | AG30: =#REF!+#REF! -> #REF! | AH30: =AG30/$D30 -> #REF! | AK30: =#REF!+#REF! -> #REF! | AL30: =AK30/$D30 -> #REF! | AO30: =#REF!+#REF! -> #REF! | AP30: =AO30/$D30 -> #REF! | AS30: =#REF!+#REF! -> #REF! | AT30: =AS30/$D30 -> #REF! | AW30: =#REF!+#REF! -> #REF! | AX30: =AW30/$D30 -> #REF! | BA30: =#REF!+#REF! -> #REF! | BB30: =BA30/$D30 -> #REF!
B31: ABC - Mixing and Loading to site | C31: Cum/day | D31: 550 | E31: Cum | O31: 550 | P31: =J31/O31 -> 0 | AG31: =#REF!+#REF! -> #REF! | AH31: =AG31/$D31 -> #REF! | AK31: =#REF!+#REF! -> #REF! | AL31: =AK31/$D31 -> #REF! | AO31: =#REF!+#REF! -> #REF! | AP31: =AO31/$D31 -> #REF! | AS31: =#REF!+#REF! -> #REF! | AT31: =AS31/$D31 -> #REF! | AW31: =#REF!+#REF! -> #REF! | AX31: =AW31/$D31 -> #REF! | BA31: =#REF!+#REF! -> #REF! | BB31: =BA31/$D31 -> #REF!
B32: BBC/BWC Aggregate borrow excavation | C32: Cum/day | D32: 385 | E32: Cum | O32: 385 | P32: =J32/O32 -> 0 | AG32: =AG14 -> #REF! | AH32: =AG32/$D32 -> #REF! | AK32: =AK14 -> #REF! | AL32: =AK32/$D32 -> #REF! | AO32: =AO14 -> #REF! | AP32: =AO32/$D32 -> #REF! | AS32: =AS14 -> #REF! | AT32: =AS32/$D32 -> #REF! | AW32: =AW14 -> #REF! | AX32: =AW32/$D32 -> #REF! | BA32: =BA14 -> #REF! | BB32: =BA32/$D32 -> #REF!
B33: Maintenance and protection of Trafic | C33: Cum/day | D33: 800 | E33: Cum | O33: 800 | P33: =J33/O33 -> 0 | AH33: =AG33/$D33 -> 0 | AL33: =AK33/$D33 -> 0 | AP33: =AO33/$D33 -> 0 | AT33: =AS33/$D33 -> 0 | AX33: =AW33/$D33 -> 0 | BB33: =BA33/$D33 -> 0
B34: Shoulder preparation | C34: Cum/day | D34: 300 | E34: Cum | O34: 200 | P34: =J34/O34 -> 0 | AH34: =AG34/$D34 -> 0 | AL34: =AK34/$D34 -> 0 | AP34: =AO34/$D34 -> 0 | AT34: =AS34/$D34 -> 0 | AX34: =AW34/$D34 -> 0 | BB34: =BA34/$D34 -> 0
B35: Service ducts | C35: Cum/day | D35: 150 | E35: Cum | O35: 150 | P35: =J35/O35 -> 0 | AG35: =(#REF!+#REF!+#REF!+#REF!+#REF!+#REF!)*0.6 -> #REF! | AH35: =AG35/$D35 -> #REF! | AK35: =#REF!*0.6+#REF!+#REF!+#REF!+#REF!*0.7 -> #REF! | AL35: =AK35/$D35 -> #REF! | AO35: =(#REF!+#REF!+#REF!+#REF!+#REF!+#REF!)*0.6 -> #REF! | AP35: =AO35/$D35 -> #REF! | AS35: =#REF!*0.6+#REF!+#REF!+#REF!+#REF!*0.7 -> #REF! | AT35: =AS35/$D35 -> #REF! | AW35: =(#REF!+#REF!+#REF!+#REF!+#REF!+#REF!)*0.6 -> #REF! | AX35: =AW35/$D35 -> #REF! | BA35: =#REF!*0.6+#REF!+#REF!+#REF!+#REF!*0.7 -> #REF! | BB35: =BA35/$D35 -> #REF!
B36: Structural excavation | C36: Cum/day | D36: 200 | E36: Cum | O36: 200 | P36: =J36/O36 -> 0 | AG36: =#REF!+#REF!+#REF!+#REF! -> #REF! | AH36: =AG36/$D36 -> #REF! | AK36: =#REF!+#REF!+#REF!+#REF! -> #REF! | AL36: =AK36/$D36 -> #REF! | AO36: =#REF!+#REF!+#REF!+#REF! -> #REF! | AP36: =AO36/$D36 -> #REF! | AS36: =#REF!+#REF!+#REF!+#REF! -> #REF! | AT36: =AS36/$D36 -> #REF! | AW36: =#REF!+#REF!+#REF!+#REF! -> #REF! | AX36: =AW36/$D36 -> #REF! | BA36: =#REF!+#REF!+#REF!+#REF! -> #REF! | BB36: =BA36/$D36 -> #REF!
A37: Rock | B37: Crusher works (VSI + Static crusher) | C37: Cum/day | D37: 1000 | E37: Cum | O37: 1000 | P37: =J37/O37 -> 0 | AH37: =AG37/$D37 -> 0 | AL37: =AK37/$D37 -> 0 | AP37: =AO37/$D37 -> 0 | AT37: =AS37/$D37 -> 0 | AX37: =AW37/$D37 -> 0 | BB37: =BA37/$D37 -> 0
B38: Mobile Crusher | C38: Cum/day | D38: 200 | E38: Cum | O38: 550 | P38: =J38/O38 -> 0 | AG38: =(#REF!+#REF!)*0 -> #REF! | AH38: =AG38/$D38 -> #REF! | AK38: =(#REF!+#REF!)*0 -> #REF! | AL38: =AK38/$D38 -> #REF! | AO38: =(#REF!+#REF!)*0 -> #REF! | AP38: =AO38/$D38 -> #REF! | AS38: =(#REF!+#REF!)*0 -> #REF! | AT38: =AS38/$D38 -> #REF! | AW38: =(#REF!+#REF!)*0 -> #REF! | AX38: =AW38/$D38 -> #REF! | BA38: =(#REF!+#REF!)*0 -> #REF! | BB38: =BA38/$D38 -> #REF!
B39: Social Work ( Mussanah MOH) | C39: day | E39: day | P39: =K39 -> 0
B40: Bolder shifting from 19km B/P to Crusher top | C40: Cum/day | D40: 900 | E40: Cum | O40: 900 | P40: =J40/O40 -> 0 | AG40: =AG132 -> 0 | AH40: =AG40/$D40 -> 0 | AK40: =AK132 -> 0 | AL40: =AK40/$D40 -> 0 | AO40: =AO132 -> 0 | AP40: =AO40/$D40 -> 0 | AS40: =AS132 -> 0 | AT40: =AS40/$D40 -> 0 | AW40: =AW132 -> 0 | AX40: =AW40/$D40 -> 0 | BA40: =BA132 -> 0 | BB40: =BA40/$D40 -> 0
B41: Aggregate shifting for VSI from 19km B/p | C41: Cum/day | D41: 900 | E41: Cum | O41: 900 | P41: =J41/O41 -> 0 | AG41: =AG133 -> 0 | AH41: =AG41/$D41 -> 0 | AK41: =AK133 -> 0 | AL41: =AK41/$D41 -> 0 | AO41: =AO133 -> 0 | AP41: =AO41/$D41 -> 0 | AS41: =AS133 -> 0 | AT41: =AS41/$D41 -> 0 | AW41: =AW133 -> 0 | AX41: =AW41/$D41 -> 0 | BA41: =BA133 -> 0 | BB41: =BA41/$D41 -> 0
...

Sheet Manpower utilization
G1: Work days | H1: ='Plant utilization'!H1 -> xxxx | K1: Date : | L1: ='Plant utilization'!K1 -> xxxx | AC1: T SWAMY | AK1: NAGARAJAN | AS1: A.K. SINGH
A2: ='Plant utilization'!A2 -> Resource Capacity Utilization Report -Month xxxx | J2: Project Name : | BC2: =30/0.6 -> 50
A3: S.No. | B3: Description | C3: Budget | E3: Unit | F3: Actual (For the day) | J3: Cumulative (For the month) | O3: Remarks | R3: Site conditions (Actual f.t. Month) | AC3: Actual (For the day) | AG3: Cumulative (For the month) | AK3: Actual (For the day) | AO3: Cumulative (For the month) | AS3: Actual (For the day) | AW3: Cumulative (For the month)
C4: Unit | D4: Prod'vity Norm | F4: Work done Quantity for the day | G4: Budgeted Days | H4: Actual Days | I4: % of Utiliz'tn | J4: Cumulative Work done | K4: Budgeted Days | L4: Actual Days | M4: Actual Prod'vity | N4: % of Utiliz'tn | R4: Prod'vity Norm | S4: Budgeted Days | T4: % Utiliz'tn (Actual) | AC4: Work done Quantity for the day | AD4: Budgeted Days | AE4: Actual Days | AF4: % of Utiliz'tn | AG4: Cumulative Work done | AH4: Budgeted Days | AI4: Projected Days | AJ4: % of Utiliz'tn | AK4: Work done Quantity for the day | AL4: Budgeted Days | AM4: Actual Days | AN4: % of Utiliz'tn | AO4: Cumulative Work done | AP4: Budgeted Days | AQ4: Projected Days | AR4: % of Utiliz'tn | AS4: Work done Quantity for the day | AT4: Budgeted Days | AU4: Actual Days | AV4: % of Utiliz'tn | AW4: Cumulative Work done | AX4: Budgeted Days | AY4: Projected Days | AZ4: % of Utiliz'tn
A7: 1 | B7: Mason | G7: =SUM(G8:G27) -> 0 | I7: =IFERROR(G7/H7,0) -> 0 | K7: =SUM(K8:K27) -> 0 | N7: =IFERROR(L7/M7,0) -> 0 | S7: =SUM(S8:S27) -> 0 | T7: =S7/L7 -> #DIV/0! | AD7: =SUM(AD8:AD27) -> #REF! | AE7: =VLOOKUP($B7,'[5]Eqpmnt & MP Days'!$B$14:$H$17,2,0) -> 2 | AF7: =IFERROR(AD7/AE7,"") | AH7: =SUM(AH8:AH27) -> #REF! | AI7: =VLOOKUP($B7,'[5]Eqpmnt & MP Days'!$B$14:$H$17,3,0) -> 56 | AJ7: =IFERROR(AH7/AI7,"") | AL7: =SUM(AL8:AL27) -> #REF! | AM7: =VLOOKUP($B7,'[5]Eqpmnt & MP Days'!$B$14:$H$17,4,0) -> 0 | AN7: =IFERROR(AL7/AM7,"") | AP7: =SUM(AP8:AP27) -> #REF! | AQ7: =VLOOKUP($B7,'[5]Eqpmnt & MP Days'!$B$14:$H$17,5,0) -> 0 | AR7: =IFERROR(AP7/AQ7,"") | AT7: =SUM(AT8:AT27) -> #REF! | AU7: =VLOOKUP($B7,'[5]Eqpmnt & MP Days'!$B$14:$H$17,6,0) -> 37 | AV7: =IFERROR(AT7/AU7,"") | AX7: =SUM(AX8:AX27) -> #REF! | AY7: =VLOOKUP($B7,'[5]Eqpmnt & MP Days'!$B$14:$H$17,7,0) -> 1006 | AZ7: =IFERROR(AX7/AY7,"") | BB7: Week1 | BC7: Week2 | BD7: Week3 | BE7: Week4 | BH7: Week1 | BI7: Week2 | BJ7: Week3 | BK7: Week4
B8: Blinding | C8: Cum/day | D8: 8 | E8: Cum | M8: =J8/L8 -> #DIV/0! | R8: 8 | S8: =J8/R8 -> 0 | AC8: =#REF!+#REF! -> #REF! | AD8: =AC8/D8 -> #REF! | AG8: =#REF!+#REF! -> #REF! | AH8: =AG8/D8 -> #REF! | AK8: =#REF!+#REF! -> #REF! | AL8: =AK8/$D8 -> #REF! | AO8: =#REF!+#REF! -> #REF! | AP8: =AO8/D8 -> #REF! | AS8: =#REF!+#REF! -> #REF! | AT8: =AS8/$D8 -> #REF! | AW8: =#REF!+#REF! -> #REF! | AX8: =AW8/$D8 -> #REF! | BB8: =#REF!+#REF! -> #REF! | BC8: =#REF!+#REF! -> #REF! | BD8: =#REF!+#REF! -> #REF! | BE8: =#REF!+#REF! -> #REF! | BF8: =SUM(BB8:BE8) -> #REF! | BG8: =J8-BF8 -> #REF! | BH8: =BB8/$D8 -> #REF! | BI8: =BC8/$D8 -> #REF! | BJ8: =BD8/$D8 -> #REF! | BK8: =BE8/$D8 -> #REF!
B9: Box Culvert- C30/20 | C9: Cum/day | D9: 7 | E9: Cum | M9: =J9/L9 -> #DIV/0! | R9: 7 | S9: =J9/R9 -> 0 | AC9: =#REF!+#REF! -> #REF! | AD9: =AC9/D9 -> #REF! | AG9: =#REF!+#REF! -> #REF! | AH9: =AG9/D9 -> #REF! | AK9: =#REF!+#REF! -> #REF! | AL9: =AK9/$D9 -> #REF! | AO9: =#REF!+#REF! -> #REF! | AP9: =AO9/D9 -> #REF! | AS9: =#REF!+#REF! -> #REF! | AT9: =AS9/$D9 -> #REF! | AW9: =#REF!+#REF! -> #REF! | AX9: =AW9/$D9 -> #REF! | BB9: =#REF!+#REF! -> #REF! | BC9: =#REF!+#REF! -> #REF! | BD9: =#REF!+#REF! -> #REF! | BE9: =#REF!+#REF! -> #REF! | BF9: =SUM(BB9:BE9) -> #REF! | BG9: =J9-BF9 -> #REF! | BH9: =BB9/$D9 -> #REF! | BI9: =BC9/$D9 -> #REF! | BJ9: =BD9/$D9 -> #REF! | BK9: =BE9/$D9 -> #REF!
B10: Bituminous paint | C10: Sqm/day | D10: 10 | E10: Sqm | R10: 10 | S10: =J10/R10 -> 0 | AC10: =#REF!+#REF! -> #REF! | AD10: =AC10/D10 -> #REF! | AG10: =#REF!+#REF! -> #REF! | AH10: =AG10/D10 -> #REF! | AK10: =#REF!+#REF! -> #REF! | AO10: =#REF!+#REF! -> #REF! | AP10: =AO10/D10 -> #REF! | AS10: =#REF!+#REF! -> #REF! | AT10: =AS10/$D10 -> #REF! | AW10: =#REF!*0.5+#REF! -> #REF! | AX10: =AW10/$D10 -> #REF! | BB10: =#REF!+#REF! -> #REF! | BC10: =#REF!+#REF! -> #REF! | BD10: =#REF!+#REF! -> #REF! | BE10: =#REF!+#REF! -> #REF! | BF10: =SUM(BB10:BE10) -> #REF! | BG10: =J10-BF10 -> #REF! | BH10: =BB10/$D10 -> #REF! | BI10: =BC10/$D10 -> #REF! | BJ10: =BD10/$D10 -> #REF! | BK10: =BE10/$D10 -> #REF!
B11: Bridges-C30/20 (Retaining Wall) | C11: Cum/day | D11: 7 | E11: Cum | M11: =J11/L11 -> #DIV/0! | R11: 7 | S11: =J11/R11 -> 0 | AC11: =#REF!+#REF! -> #REF! | AD11: =AC11/D11 -> #REF! | AG11: =#REF!+#REF! -> #REF! | AH11: =AG11/D11 -> #REF! | AK11: =#REF!+#REF! -> #REF! | AL11: =AK11/$D11 -> #REF! | AO11: =#REF!+#REF! -> #REF! | AP11: =AO11/D11 -> #REF! | AS11: =#REF!+#REF! -> #REF! | AT11: =AS11/$D11 -> #REF! | AW11: =#REF!+#REF! -> #REF! | AX11: =AW11/$D11 -> #REF! | BB11: =#REF!+#REF! -> #REF! | BC11: =#REF!+#REF! -> #REF! | BD11: =#REF!+#REF! -> #REF! | BE11: =#REF!+#REF! -> #REF! | BF11: =SUM(BB11:BE11) -> #REF! | BG11: =J11-BF11 -> #REF! | BH11: =BB11/$D11 -> #REF! | BI11: =BC11/$D11 -> #REF! | BJ11: =BD11/$D11 -> #REF! | BK11: =BE11/$D11 -> #REF!
B12: Bridges-C30/20 (Bridge) | C12: Cum/day | D12: 5 | E12: Cum | R12: 4 | S12: =J12/R12 -> 0 | AC12: =#REF!+#REF!+#REF!+#REF!+#REF!+#REF! -> #REF! | AD12: =AC12/D12 -> #REF! | AG12: =#REF!+#REF!+#REF!+#REF!+#REF!+#REF! -> #REF! | AH12: =AG12/D12 -> #REF! | AK12: =#REF!+#REF!+#REF!+#REF!+#REF!+#REF! -> #REF! | AL12: =AK12/$D12 -> #REF! | AO12: =#REF!+#REF!+#REF!+#REF!+#REF!+#REF! -> #REF! | AP12: =AO12/D12 -> #REF! | AS12: =#REF!+#REF!+#REF!+#REF!+#REF!+#REF! -> #REF! | AT12: =AS12/$D12 -> #REF! | AW12: =#REF!+#REF!+#REF!+#REF!+#REF!+#REF! -> #REF! | AX12: =AW12/$D12 -> #REF! | BB12: =#REF!+#REF!+#REF!+#REF!+#REF!+#REF! -> #REF! | BC12: =#REF!+#REF!+#REF!+#REF!+#REF!+#REF! -> #REF! | BD12: =#REF!+#REF!+#REF!+#REF!+#REF!+#REF! -> #REF! | BE12: =#REF!+#REF!+#REF!+#REF!+#REF!+#REF! -> #REF! | BF12: =SUM(BB12:BE12) -> #REF! | BG12: =J12-BF12 -> #REF! | BH12: =BB12/$D12 -> #REF! | BI12: =BC12/$D12 -> #REF! | BJ12: =BD12/$D12 -> #REF! | BK12: =BE12/$D12 -> #REF!
B13: Bridges-C45/20 (Bridge Girders) | C13: Cum/day | D13: 8 | E13: Cum | R13: 8 | S13: =J13/R13 -> 0 | AC13: =#REF! -> #REF! | AD13: =AC13/D13 -> #REF! | AG13: =#REF! -> #REF! | AH13: =AG13/D13 -> #REF! | AK13: =#REF! -> #REF! | AL13: =AK13/$D13 -> #REF! | AO13: =#REF! -> #REF! | AP13: =AO13/D13 -> #REF! | AS13: =#REF! -> #REF! | AT13: =AS13/$D13 -> #REF! | AW13: =#REF! -> #REF! | AX13: =AW13/$D13 -> #REF! | BB13: =#REF! -> #REF! | BC13: =#REF! -> #REF! | BD13: =#REF! -> #REF! | BE13: =#REF! -> #REF! | BF13: =SUM(BB13:BE13) -> #REF! | BG13: =J13-BF13 -> #REF! | BH13: =BB13/$D13 -> #REF! | BI13: =BC13/$D13 -> #REF! | BJ13: =BD13/$D13 -> #REF! | BK13: =BE13/$D13 -> #REF!
B14: Storm Sewer HDPE Pipe | C14: linm/day | D14: 3.5 | E14: linm | R14: 5 | S14: =J14/R14 -> 0 | AC14: =#REF!*0.375+#REF!*0.6 -> #REF! | AD14: =AC14/D14 -> #REF! | AG14: =#REF!*0.375+#REF!*0.6 -> #REF! | AH14: =AG14/D14 -> #REF! | AK14: =#REF!*0.375+#REF!*0.6 -> #REF! | AL14: =AK14/$D14 -> #REF! | AO14: =#REF!*0.375+#REF!*0.6 -> #REF! | AP14: =AO14/D14 -> #REF! | AS14: =#REF!*0.375+#REF!*0.6 -> #REF! | AT14: =AS14/$D14 -> #REF! | AW14: =#REF!*0.375+#REF!*0.6 -> #REF! | AX14: =AW14/$D14 -> #REF! | BB14: =#REF!*0.375+#REF! -> #REF! | BC14: =#REF!*0.375+#REF! -> #REF! | BD14: =#REF!*0.375+#REF! -> #REF! | BE14: =#REF!*0.375+#REF! -> #REF! | BF14: =SUM(BB14:BE14) -> #REF! | BG14: =J14-BF14 -> #REF! | BH14: =BB14/$D14 -> #REF! | BI14: =BC14/$D14 -> #REF! | BJ14: =BD14/$D14 -> #REF! | BK14: =BE14/$D14 -> #REF!
B15: Precasting of Barrier works | C15: Cum/day | D15: 5 | E15: Cum | R15: 5 | S15: =J15/R15 -> 0 | AC15: =#REF!*0.41 -> #REF! | AD15: =AC15/D15 -> #REF! | AG15: =#REF!*0.41 -> #REF! | AH15: =AG15/D15 -> #REF! | AK15: =#REF!*0.41 -> #REF! | AL15: =AK15/$D15 -> #REF! | AO15: =#REF!*0.41 -> #REF! | AP15: =AO15/D15 -> #REF! | AS15: =#REF!*0.41 -> #REF! | AT15: =AS15/$D15 -> #REF! | AW15: =#REF!*0.41 -> #REF! | AX15: =AW15/$D15 -> #REF! | BB15: =#REF!*0.41 -> #REF! | BC15: =#REF!*0.41 -> #REF! | BD15: =#REF!*0.41 -> #REF! | BE15: =#REF!*0.41 -> #REF! | BF15: =SUM(BB15:BE15) -> #REF! | BG15: =J15-BF15 -> #REF! | BH15: =BB15/$D15 -> #REF! | BI15: =BC15/$D15 -> #REF! | BJ15: =BD15/$D15 -> #REF! | BK15: =BE15/$D15 -> #REF!
B16: Precasting of Water Line Slab works | C16: Cum/day | D16: 5 | E16: Cum | R16: 5 | S16: =J16/R16 -> 0 | AC16: =#REF!*0.16 -> #REF! | AD16: =AC16/D16 -> #REF! | AG16: =#REF!*0.16 -> #REF! | AH16: =AG16/D16 -> #REF! | AK16: =#REF!*0.16 -> #REF! | AL16: =AK16/$D16 -> #REF! | AO16: =#REF!*0.16 -> #REF! | AP16: =AO16/D16 -> #REF! | AS16: =#REF!*0.16 -> #REF! | AT16: =AS16/$D16 -> #REF! | AW16: =#REF!*0.16 -> #REF! | AX16: =AW16/$D16 -> #REF! | BB16: =#REF!*0.16 -> #REF! | BC16: =#REF!*0.16 -> #REF! | BD16: =#REF!*0.16 -> #REF! | BE16: =#REF!*0.16 -> #REF! | BF16: =SUM(BB16:BE16) -> #REF! | BG16: =J16-BF16 -> #REF! | BH16: =BB16/$D16 -> #REF! | BI16: =BC16/$D16 -> #REF! | BJ16: =BD16/$D16 -> #REF! | BK16: =BE16/$D16 -> #REF!
B17: 100mm dia UPVC Pipe | C17: Cum/day | D17: 5 | E17: Cum | R17: 5 | S17: =J17/R17 -> 0 | AC17: =#REF!*0.4 -> #REF! | AD17: =AC17/D17 -> #REF! | AG17: =#REF!*0.4 -> #REF! | AH17: =AG17/D17 -> #REF! | AK17: =#REF!*0.4 -> #REF! | AL17: =AK17/$D17 -> #REF! | AO17: =#REF!*0.4 -> #REF! | AP17: =AO17/D17 -> #REF! | AS17: =#REF!*0.4 -> #REF! | AT17: =AS17/$D17 -> #REF! | AW17: =#REF!*0.4 -> #REF! | AX17: =AW17/$D17 -> #REF! | BB17: =#REF!*0.4 -> #REF! | BC17: =#REF!*0.4 -> #REF! | BD17: =#REF!*0.4 -> #REF! | BE17: =#REF!*0.4 -> #REF! | BF17: =SUM(BB17:BE17) -> #REF! | BG17: =J17-BF17 -> #REF! | BH17: =BB17/$D17 -> #REF! | BI17: =BC17/$D17 -> #REF! | BJ17: =BD17/$D17 -> #REF! | BK17: =BE17/$D17 -> #REF!
B18: Service Duct (100 mm dia) | C18: Cum/day | D18: 4 | E18: Cum | R18: 4 | S18: =J18/R18 -> 0 | AC18: =#REF!*0.28 -> #REF! | AD18: =AC18/D18 -> #REF! | AG18: =#REF!*0.28 -> #REF! | AH18: =AG18/D18 -> #REF! | AK18: =#REF!*0.28 -> #REF! | AL18: =AK18/$D18 -> #REF! | AO18: =#REF!*0.28 -> #REF! | AP18: =AO18/D18 -> #REF! | AS18: =#REF!*0.28 -> #REF! | AT18: =AS18/$D18 -> #REF! | AW18: =#REF!*0.28 -> #REF! | AX18: =AW18/$D18 -> #REF! | BB18: =#REF!*0.28 -> #REF! | BC18: =#REF!*0.28 -> #REF! | BD18: =#REF!*0.28 -> #REF! | BE18: =#REF!*0.28 -> #REF! | BF18: =SUM(BB18:BE18) -> #REF! | BG18: =J18-BF18 -> #REF! | BH18: =BB18/$D18 -> #REF! | BI18: =BC18/$D18 -> #REF! | BJ18: =BD18/$D18 -> #REF! | BK18: =BE18/$D18 -> #REF!
B19: Service Duct(150 mm dia) | C19: Cum/day | D19: 4 | E19: Cum | R19: 4 | S19: =J19/R19 -> 0 | U19: =1.2*1.5*0.2 -> 0.36 | AC19: =#REF!*0.3*0 -> #REF! | AD19: =AC19/D19 -> #REF! | AG19: =#REF!*0.3 -> #REF! | AH19: =AG19/D19 -> #REF! | AK19: =#REF!*0.3 -> #REF! | AL19: =AK19/$D19 -> #REF! | AO19: =#REF!*0.3 -> #REF! | AP19: =AO19/D19 -> #REF! | AS19: =#REF!*0.3 -> #REF! | AT19: =AS19/$D19 -> #REF! | AW19: =#REF!*0.3 -> #REF! | AX19: =AW19/$D19 -> #REF! | BB19: =#REF!*0.3 -> #REF! | BC19: =#REF!*0.3 -> #REF! | BD19: =#REF!*0.3 -> #REF! | BE19: =#REF!*0.3 -> #REF! | BF19: =SUM(BB19:BE19) -> #REF! | BG19: =J19-BF19 -> #REF! | BH19: =BB19/$D19 -> #REF! | BI19: =BC19/$D19 -> #REF! | BJ19: =BD19/$D19 -> #REF! | BK19: =BE19/$D19 -> #REF!
B20: Waterline protection works | C20: Cum/day | D20: 4 | E20: Cum | R20: 4 | S20: =J20/R20 -> 0 | U20: 1.2 | V20: 0.36 | W20: =V20/U20 -> 0.3 | AC20: =#REF!*0.3 -> #REF! | AD20: =AC20/D20 -> #REF! | AG20: =#REF!*0.3 -> #REF! | AH20: =AG20/D20 -> #REF! | AK20: =#REF!*0.3 -> #REF! | AL20: =AK20/$D20 -> #REF! | AO20: =#REF!*0.3 -> #REF! | AP20: =AO20/D20 -> #REF! | AS20: =#REF!*0.3 -> #REF! | AT20: =AS20/$D20 -> #REF! | AW20: =#REF!*0.3 -> #REF! | AX20: =AW20/$D20 -> #REF! | BB20: =#REF!*0.3 -> #REF! | BC20: =#REF!*0.3 -> #REF! | BD20: =#REF!*0.3 -> #REF! | BE20: =#REF!*0.3 -> #REF! | BF20: =SUM(BB20:BE20) -> #REF! | BG20: =J20-BF20 -> #REF! | BH20: =BB20/$D20 -> #REF! | BI20: =BC20/$D20 -> #REF! | BJ20: =BD20/$D20 -> #REF! | BK20: =BE20/$D20 -> #REF!
B21: Bed Preparation (Culvert) | C21: sqm/day | D21: 10 | E21: Sqm | R21: 10 | S21: =J21/R21 -> 0 | AC21: =AC8/0.1*0.5 -> #REF! | AD21: =AC21/D21 -> #REF! | AG21: =AG8/0.1 -> #REF! | AH21: =AG21/D21 -> #REF! | AK21: =AK8/0.1*0.5 -> #REF! | AL21: =AK21/$D21 -> #REF! | AO21: =AO8/0.1 -> #REF! | AP21: =AO21/D21 -> #REF! | AS21: =AS8/0.1*0.5 -> #REF! | AT21: =AS21/$D21 -> #REF! | AW21: =AW8/0.1 -> #REF! | AX21: =AW21/$D21 -> #REF! | BB21: =BB8/0.1 -> #REF! | BC21: =BC8/0.1 -> #REF! | BD21: =BD8/0.1 -> #REF! | BE21: =BE8/0.1 -> #REF! | BF21: =SUM(BB21:BE21) -> #REF! | BG21: =J21-BF21 -> #REF! | BH21: =BB21/$D21 -> #REF! | BI21: =BC21/$D21 -> #REF! | BJ21: =BD21/$D21 -> #REF! | BK21: =BE21/$D21 -> #REF!
B22: Riprap Work (Bed Preparation) | C22: sqm/day | D22: 100 | E22: sqm | S22: =K22 -> 0 | U22: 3 | V22: 1.23 | W22: =V22/U22 -> 0.41 | AC22: =#REF!/0.3*0 -> #REF! | AD22: =AC22/D22 -> #REF! | AG22: =#REF!/0.3 -> #REF! | AH22: =AG22/D22 -> #REF! | AK22: =#REF!/0.3 -> #REF! | AL22: =AK22/$D22 -> #REF! | AO22: =#REF!/0.3 -> #REF! | AP22: =AO22/D22 -> #REF! | AS22: =#REF!/0.3 -> #REF! | AT22: =AS22/$D22 -> #REF! | AW22: =#REF!/0.3 -> #REF! | AX22: =AW22/$D22 -> #REF! | BB22: =#REF!/0.3 -> #REF! | BC22: =#REF!/0.3 -> #REF! | BD22: =#REF!/0.3 -> #REF! | BE22: =#REF!/0.3 -> #REF! | BF22: =SUM(BB22:BE22) -> #REF! | BG22: =J22-BF22 -> #REF! | BH22: =BB22/$D22 -> #REF! | BI22: =BC22/$D22 -> #REF! | BJ22: =BD22/$D22 -> #REF! | BK22: =BE22/$D22 -> #REF!
B23: MSE Wall Casting | C23: sqm/day | D23: 17 | E23: Sqm | AC23: =#REF! -> #REF! | AD23: =AC23/D23 -> #REF! | AG23: =#REF! -> #REF! | AH23: =AG23/D23 -> #REF! | AK23: =#REF! -> #REF! | AL23: =AK23/$D23 -> #REF! | AO23: =#REF! -> #REF! | AP23: =AO23/D23 -> #REF! | AS23: =#REF! -> #REF! | AT23: =AS23/$D23 -> #REF! | AW23: =#REF! -> #REF! | AX23: =AW23/$D23 -> #REF! | BB23: =#REF! -> #REF! | BC23: =#REF! -> #REF! | BD23: =#REF! -> #REF! | BE23: =#REF! -> #REF! | BF23: =SUM(BB23:BE23) -> #REF! | BG23: =J23-BF23 -> #REF! | BH23: =BB23/$D23 -> #REF! | BI23: =BC23/$D23 -> #REF! | BJ23: =BD23/$D23 -> #REF! | BK23: =BE23/$D23 -> #REF!
B24: MSE Wall Erection | C24: sqm/day | D24: 20 | E24: Sqm | BB24: =#REF! -> #REF! | BC24: =#REF! -> #REF! | BD24: =#REF! -> #REF! | BE24: =#REF! -> #REF! | BF24: =SUM(BB24:BE24) -> #REF! | BG24: =J24-BF24 -> #REF! | BH24: =BB24/$D24 -> #REF! | BI24: =BC24/$D24 -> #REF! | BJ24: =BD24/$D24 -> #REF! | BK24: =BE24/$D24 -> #REF!
B25: Catchpit (Type A) | C25: Nr | D25: 1 | E25: Nr | AC25: =#REF! -> #REF! | AD25: =AC25/D25 -> #REF! | AG25: =#REF! -> #REF! | AH25: =AG25/D25 -> #REF! | AK25: =#REF! -> #REF! | AL25: =AK25/$D25 -> #REF! | AO25: =#REF! -> #REF! | AP25: =AO25/D25 -> #REF! | AS25: =#REF! -> #REF! | AT25: =AS25/$D25 -> #REF! | AW25: =#REF! -> #REF! | AX25: =AW25/$D25 -> #REF! | BB25: =#REF! -> #REF! | BC25: =#REF! -> #REF! | BD25: =#REF! -> #REF! | BE25: =#REF! -> #REF! | BF25: =SUM(BB25:BE25) -> #REF! | BG25: =J25-BF25 -> #REF! | BH25: =BB25/$D25 -> #REF! | BI25: =BC25/$D25 -> #REF! | BJ25: =BD25/$D25 -> #REF! | BK25: =BE25/$D25 -> #REF!
B26: Cover block making (Camp casting yard) | D26: 400 | E26: nos | R26: 400 | S26: =J26/R26 -> 0 | AC26: =(AC9+AC11+AC12+AC13)*10 -> #REF! | AD26: =AC26/D26 -> #REF! | AG26: =(AG9+AG11+AG12+AG13)*10 -> #REF! | AH26: =AG26/D26 -> #REF! | AK26: =(AK9+AK11+AK12+AK13)*10 -> #REF! | AL26: =AK26/$D26 -> #REF! | AO26: =(AO9+AO11+AO12+AO13)*10 -> #REF! | AP26: =AO26/D26 -> #REF! | AS26: =(AS9+AS11+AS12+AS13)*10 -> #REF! | AT26: =AS26/$D26 -> #REF! | AW26: =(AW9+AW11+AW12+AW13)*10 -> #REF! | AX26: =AW26/$D26 -> #REF! | BB26: =(BB9+BB11+BB12+BB13)*10 -> #REF! | BC26: =(BC9+BC11+BC12+BC13)*10 -> #REF! | BD26: =(BD9+BD11+BD12+BD13)*10 -> #REF! | BE26: =(BE9+BE11+BE12+BE13)*10 -> #REF! | BF26: =SUM(BB26:BE26) -> #REF! | BG26: =J26-BF26 -> #REF! | BH26: =BB26/$D26 -> #REF! | BI26: =BC26/$D26 -> #REF! | BJ26: =BD26/$D26 -> #REF! | BK26: =BE26/$D26 -> #REF!
B27: Camp Work | E27: nos | S27: =K27 -> 0 | BF27: =SUM(BB27:BE27) -> 0 | BG27: =J27-BF27 -> 0 | BH27: =$G$27*6 -> 0 | BI27: =BH27 -> 0
A28: 2 | B28: Carpenter | G28: =SUM(G29:G46) -> 0 | I28: =IFERROR(G28/H28,0) -> 0 | K28: =SUM(K29:K46) -> 0 | N28: =IFERROR(L28/M28,0) -> 0 | P28: =L28/26 -> 0 | S28: =SUM(S29:S46) -> 0 | T28: =S28/L28 -> #DIV/0! | AD28: =SUM(AD29:AD46) -> #REF! | AE28: =VLOOKUP($B28,'[5]Eqpmnt & MP Days'!$B$14:$H$17,2,0) -> 11 | AF28: =IFERROR(AD28/AE28,"") | AH28: =SUM(AH29:AH46) -> #REF! | AI28: =VLOOKUP($B28,'[5]Eqpmnt & MP Days'!$B$14:$H$17,3,0) -> 308 | AJ28: =IFERROR(AH28/AI28,"") | AL28: =SUM(AL29:AL46) -> #REF! | AM28: =VLOOKUP($B28,'[5]Eqpmnt & MP Days'!$B$14:$H$17,4,0) -> 4 | AN28: =IFERROR(AL28/AM28,"") | AP28: =SUM(AP29:AP46) -> #REF! | AQ28: =VLOOKUP($B28,'[5]Eqpmnt & MP Days'!$B$14:$H$17,5,0) -> 112 | AR28: =IFERROR(AP28/AQ28,"") | AT28: =SUM(AT29:AT46) -> #REF! | AU28: =VLOOKUP($B28,'[5]Eqpmnt & MP Days'!$B$14:$H$17,6,0) -> 132 | AV28: =IFERROR(AT28/AU28,"") | AX28: =SUM(AX29:AX46) -> #REF! | AY28: =VLOOKUP($B28,'[5]Eqpmnt & MP Days'!$B$14:$H$17,7,0) -> 3501 | AZ28: =IFERROR(AX28/AY28,"") | BF28: =SUM(BB28:BE28) -> 0 | BG28: =J28-BF28 -> 0
B29: Blinding | C29: Cum/day | D29: 6 | E29: Cum | M29: =J29/L29 -> #DIV/0! | R29: 6 | S29: =J29/R29 -> 0 | AC29: =AC8 -> #REF! | AD29: =AC29/D29 -> #REF! | AG29: =AG8 -> #REF! | AH29: =AG29/D29 -> #REF! | AK29: =AK8 -> #REF! | AL29: =AK29/$D29 -> #REF! | AO29: =AO8 -> #REF! | AP29: =AO29/D29 -> #REF! | AS29: =AS8 -> #REF! | AT29: =AS29/$D29 -> #REF! | AW29: =AW8 -> #REF! | AX29: =AW29/$D29 -> #REF! | BB29: =BB8 -> #REF! | BC29: =BC8 -> #REF! | BD29: =BD8 -> #REF! | BE29: =BE8 -> #REF! | BF29: =SUM(BB29:BE29) -> #REF! | BG29: =J29-BF29 -> #REF! | BH29: =BB29/$D29 -> #REF! | BI29: =BC29/$D29 -> #REF! | BJ29: =BD29/$D29 -> #REF! | BK29: =BE29/$D29 -> #REF!
B30: Box Culvert- C30/20 | C30: Sqm/day | D30: 3.5 | E30: Sqm | M30: =J30/L30 -> #DIV/0! | R30: 3.5 | S30: =J30/R30 -> 0 | AC30: =AC9*3.5 -> #REF! | AD30: =AC30/D30 -> #REF! | AG30: =AG9*3.5 -> #REF! | AH30: =AG30/D30 -> #REF! | AK30: =AK9*3.5 -> #REF! | AL30: =AK30/$D30 -> #REF! | AO30: =AO9*3.5 -> #REF! | AP30: =AO30/D30 -> #REF! | AS30: =AS9*3.5 -> #REF! | AT30: =AS30/$D30 -> #REF! | AW30: =AW9*3.5 -> #REF! | AX30: =AW30/$D30 -> #REF! | BB30: =BB9*3.5 -> #REF! | BC30: =BC9*3.5 -> #REF! | BD30: =BD9*3.5 -> #REF! | BE30: =BE9*3.5 -> #REF! | BF30: =SUM(BB30:BE30) -> #REF! | BG30: =J30-BF30 -> #REF! | BH30: =BB30/$D30 -> #REF! | BI30: =BC30/$D30 -> #REF! | BJ30: =BD30/$D30 -> #REF! | BK30: =BE30/$D30 -> #REF!
B31: Bridges-C30/20 (Retaining Wall) | C31: Sqm/day | D31: 4 | E31: Sqm | R31: 4 | S31: =J31/R31 -> 0 | AC31: =AC11*3.5 -> #REF! | AD31: =AC31/D31 -> #REF! | AG31: =AG11*3.5 -> #REF! | AH31: =AG31/D31 -> #REF! | AK31: =AK11*3.5 -> #REF! | AL31: =AK31/$D31 -> #REF! | AO31: =AO11*3.5 -> #REF! | AP31: =AO31/D31 -> #REF! | AS31: =AS11*3.5 -> #REF! | AT31: =AS31/$D31 -> #REF! | AW31: =AW11*3.5 -> #REF! | AX31: =AW31/$D31 -> #REF! | BB31: =BB11*3.5 -> #REF! | BC31: =BC11*3.5 -> #REF! | BD31: =BD11*3.5 -> #REF! | BE31: =BE11*3.5 -> #REF! | BF31: =SUM(BB31:BE31) -> #REF! | BG31: =J31-BF31 -> #REF! | BH31: =BB31/$D31 -> #REF! | BI31: =BC31/$D31 -> #REF! | BJ31: =BD31/$D31 -> #REF! | BK31: =BE31/$D31 -> #REF!
B32: Bridges-C30/20 | C32: Sqm/day | D32: 4 | E32: sqm | M32: =J32/L32 -> #DIV/0! | R32: 4 | S32: =J32/R32 -> 0 | AC32: =AC12*4 -> #REF! | AD32: =AC32/D32 -> #REF! | AG32: =AG12*4 -> #REF! | AH32: =AG32/D32 -> #REF! | AK32: =AK12*4 -> #REF! | AL32: =AK32/$D32 -> #REF! | AO32: =AO12*4 -> #REF! | AP32: =AO32/D32 -> #REF! | AS32: =AS12*4 -> #REF! | AT32: =AS32/$D32 -> #REF! | AW32: =AW12*4 -> #REF! | AX32: =AW32/$D32 -> #REF! | BB32: =BB12*4 -> #REF! | BC32: =BC12*4 -> #REF! | BD32: =BD12*4 -> #REF! | BE32: =BE12*4 -> #REF! | BF32: =SUM(BB32:BE32) -> #REF! | BG32: =J32-BF32 -> #REF! | BH32: =BB32/$D32 -> #REF! | BI32: =BC32/$D32 -> #REF! | BJ32: =BD32/$D32 -> #REF! | BK32: =BE32/$D32 -> #REF!
B33: Scaffolding Works | C33: Cum/day | D33: 20 | E33: Cum | R33: 20 | S33: =J33/R33 -> 0 | AC33: =(AC9+AC12)*7*0.4 -> #REF! | AD33: =AC33/D33 -> #REF! | AG33: =(AG9+AG12)*7*0.4 -> #REF! | AH33: =AG33/D33 -> #REF! | AK33: =(AK9+AK12)*7*0.4 -> #REF! | AL33: =AK33/$D33 -> #REF! | AO33: =(AO9+AO12)*7*0.4 -> #REF! | AP33: =AO33/D33 -> #REF! | AS33: =(AS9+AS12)*7*0.4 -> #REF! | AT33: =AS33/$D33 -> #REF! | AW33: =(AW9+AW12)*7*0.4 -> #REF! | AX33: =AW33/$D33 -> #REF! | BB33: =(BB9+BB12)*7*0.3 -> #REF! | BC33: =(BC9+BC12)*7*0.3 -> #REF! | BD33: =(BD9+BD12)*7*0.3 -> #REF! | BE33: =(BE9+BE12)*7*0.3 -> #REF! | BF33: =SUM(BB33:BE33) -> #REF! | BG33: =J33-BF33 -> #REF! | BH33: =BB33/$D33 -> #REF! | BI33: =BC33/$D33 -> #REF! | BJ33: =BD33/$D33 -> #REF! | BK33: =BE33/$D33 -> #REF!
B34: RJR erection - Bridges & Ics | C34: Cum/day | D34: 10 | E34: Cum | R34: 20 | S34: =J34/R34 -> 0 | AC34: =AC12*7 -> #REF! | AD34: =AC34/D34 -> #REF! | AG34: =AG12*7 -> #REF! | AH34: =AG34/D34 -> #REF! | AK34: =AK12*7 -> #REF! | AL34: =AK34/$D34 -> #REF! | AO34: =AO12*7 -> #REF! | AP34: =AO34/D34 -> #REF! | AS34: =AS12*7 -> #REF! | AT34: =AS34/$D34 -> #REF! | AW34: =AW12*7 -> #REF! | AX34: =AW34/$D34 -> #REF! | BB34: =BB12 -> #REF! | BC34: =BC12 -> #REF! | BD34: =BD12 -> #REF! | BE34: =BE12 -> #REF! | BF34: =SUM(BB34:BE34) -> #REF! | BG34: =J34-BF34 -> #REF! | BH34: =BB34/$D34 -> #REF! | BI34: =BC34/$D34 -> #REF! | BJ34: =BD34/$D34 -> #REF! | BK34: =BE34/$D34 -> #REF!
B35: Storm Sewer HDPE Pipe | C35: linm/day | D35: 3.5 | E35: linm | R35: 8 | S35: =J35/R35 -> 0 | AC35: =AC14 -> #REF! | AD35: =AC35/D35 -> #REF! | AG35: =AG14 -> #REF! | AH35: =AG35/D35 -> #REF! | AK35: =AK14 -> #REF! | AL35: =AK35/$D35 -> #REF! | AO35: =AO14 -> #REF! | AP35: =AO35/D35 -> #REF! | AS35: =AS14 -> #REF! | AT35: =AS35/$D35 -> #REF! | AW35: =AW14 -> #REF! | AX35: =AW35/$D35 -> #REF! | BB35: =BB14 -> #REF! | BC35: =BC14 -> #REF! | BD35: =BD14 -> #REF! | BE35: =BE14 -> #REF! | BF35: =SUM(BB35:BE35) -> #REF! | BG35: =J35-BF35 -> #REF! | BH35: =BB35/$D35 -> #REF! | BI35: =BC35/$D35 -> #REF! | BJ35: =BD35/$D35 -> #REF! | BK35: =BE35/$D35 -> #REF!
B36: 100mm dia UPVC Pipe | C36: Sqm/day | D36: 5 | E36: Sqm | R36: 5 | S36: =J36/R36 -> 0 | AC36: =AC17 -> #REF! | AD36: =AC36/D36 -> #REF! | AG36: =AG17 -> #REF! | AH36: =AG36/D36 -> #REF! | AK36: =AK17 -> #REF! | AL36: =AK36/$D36 -> #REF! | AO36: =AO17 -> #REF! | AP36: =AO36/D36 -> #REF! | AS36: =AS17 -> #REF! | AT36: =AS36/$D36 -> #REF! | AW36: =AW17 -> #REF! | AX36: =AW36/$D36 -> #REF! | BB36: =BB17 -> #REF! | BC36: =BC17 -> #REF! | BD36: =BD17 -> #REF! | BE36: =BE17 -> #REF! | BF36: =SUM(BB36:BE36) -> #REF! | BG36: =J36-BF36 -> #REF! | BH36: =BB36/$D36 -> #REF! | BI36: =BC36/$D36 -> #REF! | BJ36: =BD36/$D36 -> #REF! | BK36: =BE36/$D36 -> #REF!
B37: Barrier Precasting | C37: Sqm/day | D37: 4 | E37: Sqm | R37: 4 | S37: =J37/R37 -> 0 | AC37: =#REF!*3.67 -> #REF! | AD37: =AC37/D37 -> #REF! | AG37: =#REF!*3.67 -> #REF! | AH37: =AG37/D37 -> #REF! | AK37: =#REF!*3.67 -> #REF! | AL37: =AK37/$D37 -> #REF! | AO37: =#REF!*3.67 -> #REF! | AP37: =AO37/D37 -> #REF! | AS37: =#REF!*3.67 -> #REF! | AT37: =AS37/$D37 -> #REF! | AW37: =#REF!*3.67 -> #REF! | AX37: =AW37/$D37 -> #REF! | BB37: =#REF!*3.67 -> #REF! | BC37: =#REF!*3.67 -> #REF! | BD37: =#REF!*3.67 -> #REF! | BE37: =#REF!*3.67 -> #REF! | BF37: =SUM(BB37:BE37) -> #REF! | BG37: =J37-BF37 -> #REF! | BH37: =BB37/$D37 -> #REF! | BI37: =BC37/$D37 -> #REF! | BJ37: =BD37/$D37 -> #REF! | BK37: =BE37/$D37 -> #REF!
B38: Waterline protection works - Precasting | C38: sqm/day | D38: 2 | E38: Sqm | R38: 2 | S38: =J38/R38 -> 0 | AC38: =#REF!*0.8 -> #REF! | AD38: =AC38/D38 -> #REF! | AG38: =#REF!*0.8 -> #REF! | AH38: =AG38/D38 -> #REF! | AK38: =#REF!*0.8 -> #REF! | AL38: =AK38/$D38 -> #REF! | AO38: =#REF!*0.8 -> #REF! | AP38: =AO38/D38 -> #REF! | AS38: =#REF!*0.8 -> #REF! | AT38: =AS38/$D38 -> #REF! | AW38: =#REF!*0.8 -> #REF! | AX38: =AW38/$D38 -> #REF! | BB38: =#REF!*0.8 -> #REF! | BC38: =#REF!*0.8 -> #REF! | BD38: =#REF!*0.8 -> #REF! | BE38: =#REF!*0.8 -> #REF! | BF38: =SUM(BB38:BE38) -> #REF! | BG38: =J38-BF38 -> #REF! | BH38: =BB38/$D38 -> #REF! | BI38: =BC38/$D38 -> #REF! | BJ38: =BD38/$D38 -> #REF! | BK38: =BE38/$D38 -> #REF!
B39: Water bar , Dowel Bar Fixing | C39: Cum/day | D39: 30 | E39: Cum | R39: 30 | S39: =J39/R39 -> 0 | AC39: =AC9 -> #REF! | AD39: =AC39/D39 -> #REF! | AG39: =AG9 -> #REF! | AH39: =AG39/D39 -> #REF! | AK39: =AK9 -> #REF! | AL39: =AK39/$D39 -> #REF! | AO39: =AO9 -> #REF! | AP39: =AO39/D39 -> #REF! | AS39: =AS9 -> #REF! | AT39: =AS39/$D39 -> #REF! | AW39: =AW9 -> #REF! | AX39: =AW39/$D39 -> #REF! | BB39: =BB9 -> #REF! | BC39: =BC9 -> #REF! | BD39: =BD9 -> #REF! | BE39: =BE9 -> #REF! | BF39: =SUM(BB39:BE39) -> #REF! | BG39: =J39-BF39 -> #REF! | BH39: =BB39/$D39 -> #REF! | BI39: =BC39/$D39 -> #REF! | BJ39: =BD39/$D39 -> #REF! | BK39: =BE39/$D39 -> #REF!
B40: Bridge deck void formers 700mm dia. | C40: Linm | D40: 3 | E40: linm | AC40: =AC59 -> #REF! | AD40: =AC40/D40 -> #REF! | AG40: =AG59 -> #REF! | AH40: =AG40/D40 -> #REF! | AK40: =AK59 -> #REF! | AL40: =AK40/$D40 -> #REF! | AO40: =AO59 -> #REF! | AP40: =AO40/D40 -> #REF! | AS40: =AS59 -> #REF! | AT40: =AS40/$D40 -> #REF! | AW40: =AW59 -> #REF! | AX40: =AW40/$D40 -> #REF! | BB40: =BB59 -> #REF! | BC40: =BC59 -> #REF! | BD40: =BD59 -> #REF! | BE40: =BE59 -> #REF! | BF40: =SUM(BB40:BE40) -> #REF! | BG40: =J40-BF40 -> #REF! | BH40: =BB40/$D40 -> #REF! | BI40: =BC40/$D40 -> #REF! | BJ40: =BD40/$D40 -> #REF! | BK40: =BE40/$D40 -> #REF!
B41: MSE Wall Casting | C41: sqm/day | D41: 17 | E41: Sqm | AC41: =AC23 -> #REF! | AD41: =AC41/D41 -> #REF! | AG41: =AG23 -> #REF! | AH41: =AG41/D41 -> #REF! | AK41: =AK23 -> #REF! | AL41: =AK41/$D41 -> #REF! | AO41: =AO23 -> #REF! | AP41: =AO41/D41 -> #REF! | AS41: =AS23 -> #REF! | AT41: =AS41/$D41 -> #REF! | AW41: =AW23 -> #REF! | AX41: =AW41/$D41 -> #REF! | BB41: =BB23 -> #REF! | BC41: =BC23 -> #REF! | BD41: =BD23 -> #REF! | BE41: =BE23 -> #REF! | BF41: =SUM(BB41:BE41) -> #REF! | BG41: =J41-BF41 -> #REF! | BH41: =BB41/$D41 -> #REF! | BI41: =BC41/$D41 -> #REF! | BJ41: =BD41/$D41 -> #REF! | BK41: =BE41/$D41 -> #REF! | BM41: =100/6 -> 16.666667
B42: MSE Wall Erection | C42: sqm/day | D42: 10 | E42: Sqm | BB42: =#REF! -> #REF! | BC42: =#REF! -> #REF! | BD42: =#REF! -> #REF! | BE42: =#REF! -> #REF! | BF42: =SUM(BB42:BE42) -> #REF! | BG42: =J42-BF42 -> #REF! | BH42: =BB42/$D42 -> #REF! | BI42: =BC42/$D42 -> #REF! | BJ42: =BD42/$D42 -> #REF! | BK42: =BE42/$D42 -> #REF!
...

Sheet SUMMARY
C1: Work days | E1: ='Plant utilization'!H1 -> xxxx
C3: Date : | E3: ='Plant utilization'!K1 -> xxxx | H3: Sept-2017 | K3: Site norms
C4: For the Day | F4: For the Month | K4: Month (Cumulative) | M4: T SWAMY | O4: NAGARAJAN | Q4: A.K.SINGH
B5: Equipment | C5: Budg. Days | D5: Actual Days | E5: % of Util | F5: Budg. Days | G5: Actual Days | H5: % of Util | M5: For the Day | N5: For the Month | O5: For the Day | P5: For the Month | Q5: For the Day | R5: For the Month
B6: Bull Dozer | C6: =VLOOKUP($B6,'Plant utilization'!$B$7:$M$158,6,0) -> 0 | D6: =VLOOKUP($B6,'Plant utilization'!$B$7:$M$158,7,0) -> 0 | E6: =IFERROR(C6/D6,0) -> 0 | F6: =VLOOKUP($B6,'Plant utilization'!$B$7:$M$158,10,0) -> 0 | G6: =VLOOKUP($B6,'Plant utilization'!$B$7:$M$158,11,0) -> 0 | H6: =IFERROR(F6/G6,0) -> 0 | K6: ='Plant utilization'!Q7 -> #DIV/0! | M6: ='Plant utilization'!AJ7 | N6: ='Plant utilization'!AN7 | O6: ='Plant utilization'!AR7 | P6: ='Plant utilization'!AV7 | Q6: ='Plant utilization'!AZ7 | R6: ='Plant utilization'!BD7
B7: Front End Loader | C7: =VLOOKUP($B7,'Plant utilization'!$B$7:$M$158,6,0) -> 0 | D7: =VLOOKUP($B7,'Plant utilization'!$B$7:$M$158,7,0) -> 0 | E7: =IFERROR(C7/D7,0) -> 0 | F7: =VLOOKUP($B7,'Plant utilization'!$B$7:$M$158,10,0) -> 0 | G7: =VLOOKUP($B7,'Plant utilization'!$B$7:$M$158,11,0) -> 0 | H7: =IFERROR(F7/G7,0) -> 0 | K7: ='Plant utilization'!Q18 -> #DIV/0! | M7: ='Plant utilization'!AJ18 | N7: ='Plant utilization'!AN18 | O7: ='Plant utilization'!AR18 | P7: ='Plant utilization'!AV18 | Q7: ='Plant utilization'!AZ18 | R7: ='Plant utilization'!BD18
B8: Motor Grader | C8: =VLOOKUP($B8,'Plant utilization'!$B$7:$M$158,6,0) -> 0 | D8: =VLOOKUP($B8,'Plant utilization'!$B$7:$M$158,7,0) -> 0 | E8: =IFERROR(C8/D8,0) -> 0 | F8: =VLOOKUP($B8,'Plant utilization'!$B$7:$M$158,10,0) -> 0 | G8: =VLOOKUP($B8,'Plant utilization'!$B$7:$M$158,11,0) -> 0 | H8: =IFERROR(F8/G8,0) -> 0 | K8: ='Plant utilization'!Q45 -> #DIV/0! | M8: ='Plant utilization'!AJ45 | N8: ='Plant utilization'!AN45 | O8: ='Plant utilization'!AR45 | P8: ='Plant utilization'!AV45 | Q8: ='Plant utilization'!AZ45 | R8: ='Plant utilization'!BD45
B9: Excavator | C9: =VLOOKUP($B9,'Plant utilization'!$B$7:$M$158,6,0) -> 0 | D9: =VLOOKUP($B9,'Plant utilization'!$B$7:$M$158,7,0) -> 0 | E9: =IFERROR(C9/D9,0) -> 0 | F9: =VLOOKUP($B9,'Plant utilization'!$B$7:$M$158,10,0) -> 0 | G9: =VLOOKUP($B9,'Plant utilization'!$B$7:$M$158,11,0) -> 0 | H9: =IFERROR(F9/G9,0) -> 0 | K9: ='Plant utilization'!Q59 -> #DIV/0! | M9: ='Plant utilization'!AJ59 | N9: ='Plant utilization'!AN59 | O9: ='Plant utilization'!AR59 | P9: ='Plant utilization'!AV59 | Q9: ='Plant utilization'!AZ59 | R9: ='Plant utilization'!BD59
B10: Vibratory Roller | C10: =VLOOKUP($B10,'Plant utilization'!$B$7:$M$158,6,0) -> 0 | D10: =VLOOKUP($B10,'Plant utilization'!$B$7:$M$158,7,0) -> 0 | E10: =IFERROR(C10/D10,0) -> 0 | F10: =VLOOKUP($B10,'Plant utilization'!$B$7:$M$158,10,0) -> 0 | G10: =VLOOKUP($B10,'Plant utilization'!$B$7:$M$158,11,0) -> 0 | H10: =IFERROR(F10/G10,0) -> 0 | K10: ='Plant utilization'!Q73 -> #DIV/0! | M10: ='Plant utilization'!AJ73 | N10: ='Plant utilization'!AN73 | O10: ='Plant utilization'!AR73 | P10: ='Plant utilization'!AV73 | Q10: ='Plant utilization'!AZ73 | R10: ='Plant utilization'!BD73
B11: Water Tanker | C11: =VLOOKUP($B11,'Plant utilization'!$B$7:$M$158,6,0) -> 0 | D11: =VLOOKUP($B11,'Plant utilization'!$B$7:$M$158,7,0) -> 0 | E11: =IFERROR(C11/D11,0) -> 0 | F11: =VLOOKUP($B11,'Plant utilization'!$B$7:$M$158,10,0) -> 0 | G11: =VLOOKUP($B11,'Plant utilization'!$B$7:$M$158,11,0) -> 0 | H11: =IFERROR(F11/G11,0) -> 0 | K11: ='Plant utilization'!Q88 -> #DIV/0! | M11: ='Plant utilization'!AJ88 | N11: ='Plant utilization'!AN88 | O11: ='Plant utilization'!AR88 | P11: ='Plant utilization'!AV88 | Q11: ='Plant utilization'!AZ88 | R11: ='Plant utilization'!BD88
B12: Tipper | C12: =VLOOKUP($B12,'Plant utilization'!$B$7:$M$158,6,0) -> 0 | D12: =VLOOKUP($B12,'Plant utilization'!$B$7:$M$158,7,0) -> 0 | E12: =IFERROR(C12/D12,0) -> 0 | F12: =VLOOKUP($B12,'Plant utilization'!$B$7:$M$158,10,0) -> 0 | G12: =VLOOKUP($B12,'Plant utilization'!$B$7:$M$158,11,0) -> 0 | H12: =IFERROR(F12/G12,0) -> 0 | K12: ='Plant utilization'!Q113 -> #DIV/0! | M12: ='Plant utilization'!AJ113 | N12: ='Plant utilization'!AN113 | O12: ='Plant utilization'!AR113 | P12: ='Plant utilization'!AV113 | Q12: ='Plant utilization'!AZ113 | R12: ='Plant utilization'!BD113
B13: JCB | C13: =VLOOKUP($B13,'Plant utilization'!$B$7:$M$158,6,0) -> 0 | D13: =VLOOKUP($B13,'Plant utilization'!$B$7:$M$158,7,0) -> 0 | E13: =IFERROR(C13/D13,0) -> 0 | F13: =VLOOKUP($B13,'Plant utilization'!$B$7:$M$158,10,0) -> 0 | G13: =VLOOKUP($B13,'Plant utilization'!$B$7:$M$158,11,0) -> 0 | H13: =IFERROR(F13/G13,0) -> 0 | K13: ='Plant utilization'!Q145 -> #DIV/0! | M13: ='Plant utilization'!AJ145 | N13: ='Plant utilization'!AN145 | O13: ='Plant utilization'!AR145 | P13: ='Plant utilization'!AV145 | Q13: ='Plant utilization'!AZ145 | R13: ='Plant utilization'!BD145
B15: AVERAGE | E15: =AVERAGE(E6:E13) -> 0 | H15: =AVERAGE(H6:H13) -> 0 | K15: =AVERAGE(K6:K13) -> #DIV/0!
B16: Manpower
B17: Mason | C17: =VLOOKUP($B17,'Manpower utilization'!$B$7:$N$115,6,0) -> 0 | D17: =VLOOKUP($B17,'Manpower utilization'!$B$7:$N$115,7,0) -> 0 | E17: =IFERROR(C17/D17,0) -> 0 | F17: =VLOOKUP($B17,'Manpower utilization'!$B$7:$N$115,10,0) -> 0 | G17: =VLOOKUP($B17,'Manpower utilization'!$B$7:$N$115,11,0) -> 0 | H17: =IFERROR(F17/G17,0) -> 0 | K17: ='Manpower utilization'!T7 -> #DIV/0! | M17: ='Manpower utilization'!AF7 | N17: ='Manpower utilization'!AJ7 | O17: ='Manpower utilization'!AN7 | P17: ='Manpower utilization'!AR7 | Q17: ='Manpower utilization'!AV7 | R17: ='Manpower utilization'!AZ7
B18: Carpenter | C18: =VLOOKUP($B18,'Manpower utilization'!$B$7:$N$115,6,0) -> 0 | D18: =VLOOKUP($B18,'Manpower utilization'!$B$7:$N$115,7,0) -> 0 | E18: =IFERROR(C18/D18,0) -> 0 | F18: =VLOOKUP($B18,'Manpower utilization'!$B$7:$N$115,10,0) -> 0 | G18: =VLOOKUP($B18,'Manpower utilization'!$B$7:$N$115,11,0) -> 0 | H18: =IFERROR(F18/G18,0) -> 0 | K18: ='Manpower utilization'!T28 -> #DIV/0! | M18: ='Manpower utilization'!AF28 | N18: ='Manpower utilization'!AJ28 | O18: ='Manpower utilization'!AN28 | P18: ='Manpower utilization'!AR28 | Q18: ='Manpower utilization'!AV28 | R18: ='Manpower utilization'!AZ28
B19: Steel Fixer | C19: =VLOOKUP($B19,'Manpower utilization'!$B$7:$N$115,6,0) -> 0 | D19: =VLOOKUP($B19,'Manpower utilization'!$B$7:$N$115,7,0) -> 0 | E19: =IFERROR(C19/D19,0) -> 0 | F19: =VLOOKUP($B19,'Manpower utilization'!$B$7:$N$115,10,0) -> 0 | G19: =VLOOKUP($B19,'Manpower utilization'!$B$7:$N$115,11,0) -> 0 | H19: =IFERROR(F19/G19,0) -> 0 | K19: ='Manpower utilization'!T47 -> #DIV/0! | M19: ='Manpower utilization'!AF47 | N19: ='Manpower utilization'!AJ47 | O19: ='Manpower utilization'!AN47 | P19: ='Manpower utilization'!AR47 | Q19: ='Manpower utilization'!AV47 | R19: ='Manpower utilization'!AZ47
B20: Helper | C20: =VLOOKUP($B20,'Manpower utilization'!$B$7:$N$115,6,0) -> 0 | D20: =VLOOKUP($B20,'Manpower utilization'!$B$7:$N$115,7,0) -> 0 | E20: =IFERROR(C20/D20,0) -> 0 | F20: =VLOOKUP($B20,'Manpower utilization'!$B$7:$N$115,10,0) -> 0 | G20: =VLOOKUP($B20,'Manpower utilization'!$B$7:$N$115,11,0) -> 0 | H20: =IFERROR(F20/G20,0) -> 0 | K20: ='Manpower utilization'!T62 -> #VALUE! | M20: ='Manpower utilization'!AF62 | N20: ='Manpower utilization'!AJ62 | O20: ='Manpower utilization'!AN62 | P20: ='Manpower utilization'!AR62 | Q20: ='Manpower utilization'!AV62 | R20: ='Manpower utilization'!AZ62
B22: AVERAGE | E22: =AVERAGE(E17:E20) -> 0 | H22: =AVERAGE(H17:H20) -> 0 | K22: =AVERAGE(K17:K20) -> #DIV/0!

Sheet Daily Deployment
A2: Total hours deployed everyday FTM xxxx (Day Shift)
A4: Sl.Nr. | B4: Vehicle/Equipment | C4: Plan hours | I4: 1 | J4: 2 | K4: 3 | L4: 4 | M4: 5 | N4: 6 | O4: 7 | P4: 8 | Q4: 9 | R4: 10 | S4: 11 | T4: 12 | U4: 13 | V4: 14 | W4: 15 | X4: 16 | Y4: 17 | Z4: 18 | AA4: 19 | AB4: 20 | AC4: 21 | AD4: 22 | AE4: 23 | AF4: 24 | AG4: 25 | AH4: 26 | AI4: 27 | AJ4: 28 | AK4: 29 | AL4: 30 | AM4: 31 | AN4: Total
A5: 1 | B5: Dozer | AN5: =SUM(I5:AM5) -> 0
A6: 2 | B6: Grader | AN6: =SUM(I6:AM6) -> 0
A7: 3 | B7: V.Roller | AN7: =SUM(I7:AM7) -> 0
A8: 4 | B8: Shovel | AN8: =SUM(I8:AM8) -> 0
A9: 5 | B9: Excavator | AN9: =SUM(I9:AM9) -> 0
A10: 6 | B10: JCB | AN10: =SUM(I10:AM10) -> 0
A11: 7 | B11: Tipper | AN11: =SUM(I11:AM11) -> 0
A12: 8 | B12: Tipper Trailer | AN12: =SUM(I12:AM12) -> 0
A13: 9 | B13: W.Tanker | AN13: =SUM(I13:AM13) -> 0
A15: Total hours deployed everyday FTM xxxx (Night Shift)
A17: Sl.Nr. | B17: Vehicle/Equipment | C17: =+C4 -> Plan hours | I17: 1 | J17: 2 | K17: 3 | L17: 4 | M17: 5 | N17: 6 | O17: 7 | P17: 8 | Q17: 9 | R17: 10 | S17: 11 | T17: 12 | U17: 13 | V17: 14 | W17: 15 | X17: 16 | Y17: 17 | Z17: 18 | AA17: 19 | AB17: 20 | AC17: 21 | AD17: 22 | AE17: 23 | AF17: 24 | AG17: 25 | AH17: 26 | AI17: 27 | AJ17: 28 | AK17: 29 | AL17: 30 | AM17: 31 | AN17: Total
A18: 1 | B18: Dozer | AN18: =SUM(I18:AM18) -> 0
A19: 2 | B19: Grader | AN19: =SUM(I19:AM19) -> 0
A20: 3 | B20: V.Roller | AN20: =SUM(I20:AM20) -> 0
A21: 4 | B21: Shovel | AN21: =SUM(I21:AM21) -> 0
A22: 5 | B22: Excavator | AN22: =SUM(I22:AM22) -> 0
A23: 6 | B23: JCB | AN23: =SUM(I23:AM23) -> 0
A24: 7 | B24: Tipper | AN24: =SUM(I24:AM24) -> 0
A25: 8 | B25: Tipper/Trailer | AN25: =SUM(I25:AM25) -> 0
A26: 9 | B26: W.Tanker | AN26: =SUM(I26:AM26) -> 0
A28: Total hours deployed everyday FTM XXXX
A30: Sl.Nr. | B30: Vehicle/Equipment | C30: Projection hours | I30: 1 | J30: 2 | K30: 3 | L30: 4 | M30: 5 | N30: 6 | O30: 7 | P30: 8 | Q30: 9 | R30: 10 | S30: 11 | T30: 12 | U30: 13 | V30: 14 | W30: 15 | X30: 16 | Y30: 17 | Z30: 18 | AA30: 19 | AB30: 20 | AC30: 21 | AD30: 22 | AE30: 23 | AF30: 24 | AG30: 25 | AH30: 26 | AI30: 27 | AJ30: 28 | AK30: 29 | AL30: 30 | AM30: 31 | AN30: Total
A31: 1 | B31: Dozer | C31: =C5+C18 -> 0 | I31: =I5+0.9*I18 -> 0 | J31: =J5+0.9*J18 -> 0 | K31: =K5+0.9*K18 -> 0 | L31: =L5+0.9*L18 -> 0 | M31: =M5+0.9*M18 -> 0 | N31: =N5+0.9*N18 -> 0 | O31: =O5+0.9*O18 -> 0 | P31: =P5+0.9*P18 -> 0 | ... AM31: =AM5+0.9*AM18 -> 0 | AN31: =SUM(I31:AM31) -> 0 | AO31: =AL31/10 -> 0 | AQ31: =AN31/10 -> 0
A32: 2 | B32: Grader | C32: =C6+C19 -> 0 | I32: =I6+0.9*I19 -> 0 | J32: =J6+0.9*J19 -> 0 | K32: =K6+0.9*K19 -> 0 | L32: =L6+0.9*L19 -> 0 | M32: =M6+0.9*M19 -> 0 | N32: =N6+0.9*N19 -> 0 | O32: =O6+0.9*O19 -> 0 | P32: =P6+0.9*P19 -> 0 | ... AM32: =AM6+0.9*AM19 -> 0 | AN32: =SUM(I32:AM32) -> 0 | AO32: =AL32/10 -> 0 | AQ32: =AN32/10 -> 0
A33: 3 | B33: V.Roller | C33: =C7+C20 -> 0 | I33: =I7+0.9*I20 -> 0 | J33: =J7+0.9*J20 -> 0 | K33: =K7+0.9*K20 -> 0 | L33: =L7+0.9*L20 -> 0 | M33: =M7+0.9*M20 -> 0 | N33: =N7+0.9*N20 -> 0 | O33: =O7+0.9*O20 -> 0 | P33: =P7+0.9*P20 -> 0 | ... AM33: =AM7+0.9*AM20 -> 0 | AN33: =SUM(I33:AM33) -> 0 | AO33: =AL33/10 -> 0 | AQ33: =AN33/10 -> 0
A34: 4 | B34: Shovel | C34: =C8+C21 -> 0 | I34: =I8+0.9*I21 -> 0 | J34: =J8+0.9*J21 -> 0 | K34: =K8+0.9*K21 -> 0 | L34: =L8+0.9*L21 -> 0 | M34: =M8+0.9*M21 -> 0 | N34: =N8+0.9*N21 -> 0 | O34: =O8+0.9*O21 -> 0 | P34: =P8+0.9*P21 -> 0 | ... AM34: =AM8+0.9*AM21 -> 0 | AN34: =SUM(I34:AM34) -> 0 | AO34: =AL34/10 -> 0 | AQ34: =AN34/10 -> 0
A35: 5 | B35: Excavator | C35: =C9+C22 -> 0 | I35: =I9+0.9*I22 -> 0 | J35: =J9+0.9*J22 -> 0 | K35: =K9+0.9*K22 -> 0 | L35: =L9+0.9*L22 -> 0 | M35: =M9+0.9*M22 -> 0 | N35: =N9+0.9*N22 -> 0 | O35: =O9+0.9*O22 -> 0 | P35: =P9+0.9*P22 -> 0 | ... AM35: =AM9+0.9*AM22 -> 0 | AN35: =SUM(I35:AM35) -> 0 | AO35: =AL35/10 -> 0 | AQ35: =AN35/10 -> 0
A36: 6 | B36: JCB | C36: =C10+C23 -> 0 | I36: =I10+0.9*I23 -> 0 | J36: =J10+0.9*J23 -> 0 | K36: =K10+0.9*K23 -> 0 | L36: =L10+0.9*L23 -> 0 | M36: =M10+0.9*M23 -> 0 | N36: =N10+0.9*N23 -> 0 | O36: =O10+0.9*O23 -> 0 | P36: =P10+0.9*P23 -> 0 | ... AM36: =AM10+0.9*AM23 -> 0 | AN36: =SUM(I36:AM36) -> 0 | AO36: =AL36/10 -> 0 | AQ36: =AN36/10 -> 0
A37: 7 | B37: Tipper | C37: =C11+C24 -> 0 | I37: =I11+0.9*I24 -> 0 | J37: =J11+0.9*J24 -> 0 | K37: =K11+0.9*K24 -> 0 | L37: =L11+0.9*L24 -> 0 | M37: =M11+0.9*M24 -> 0 | N37: =N11+0.9*N24 -> 0 | O37: =O11+0.9*O24 -> 0 | P37: =P11+0.9*P24 -> 0 | ... AM37: =AM11+0.9*AM24 -> 0 | AN37: =SUM(I37:AM37) -> 0 | AO37: =AL37/10 -> 0 | AQ37: =AN37/10 -> 0
A38: 8 | B38: Tipper/Trailer | I38: =I12+0.9*I25 -> 0 | J38: =J12+0.9*J25 -> 0 | K38: =K12+0.9*K25 -> 0 | L38: =L12+0.9*L25 -> 0 | M38: =M12+0.9*M25 -> 0 | N38: =N12+0.9*N25 -> 0 | O38: =O12+0.9*O25 -> 0 | P38: =P12+0.9*P25 -> 0 | ... AM38: =AM12+0.9*AM25 -> 0 | AN38: =SUM(I38:AM38) -> 0 | AO38: =AL38/10 -> 0 | AQ38: =AN38/10 -> 0
A39: 9 | B39: W.Tanker | C39: =C13+C26 -> 0 | I39: =I13+0.9*I26 -> 0 | J39: =J13+0.9*J26 -> 0 | K39: =K13+0.9*K26 -> 0 | L39: =L13+0.9*L26 -> 0 | M39: =M13+0.9*M26 -> 0 | N39: =N13+0.9*N26 -> 0 | O39: =O13+0.9*O26 -> 0 | P39: =P13+0.9*P26 -> 0 | ... AM39: =AM13+0.9*AM26 -> 0 | AN39: =SUM(I39:AM39) -> 0 | AO39: =AL39/10 -> 0 | AQ39: =AN39/10 -> 0

Sheet DPR
A1: Progress for the Month of xxxx
A2: PROJECT : | C2: Date :
A6: CLIENT : | C6: Weather : Clear
A7: ENGINEER :
A8: CONTRACTOR : | E8: Projection | G8: Achived | AQ8: Site Manager 1 | AS8: Site Manager 2 | AU8: Site Manager 3
A9: ITEM NO. | B9: ITEM DESCRIPTION | C9: Unit | D9: Revised Unit Rate (After Rebate) | E9: QTY. | F9: Amount | G9: QTY. | H9: Amount | I9: date 1 | J9: date 2 | K9: date 3 | L9: date 4 | M9: date 5 | N9: date 6 | O9: date 7 | P9: date 8 | Q9: date 9 | R9: date 10 | S9: date 11 | T9: date 12 | U9: date 13 | V9: date 14 | W9: date 15 | X9: date 16 | Y9: date 17 | Z9: date 18 | AA9: date 19 | AB9: date 20 | AC9: date 21 | AD9: date 22 | AE9: date 23 | AF9: date 24 | AG9: date 25 | AH9: date 26 | AI9: date 27 | AJ9: date 28 | AK9: date 29 | AL9: date 30 | AM9: date 31 | AQ9: FTD | AR9: FTM | AS9: FTD | AT9: FTM | AU9: FTD | AV9: FTM | BA9: Week1 | BB9: Week2 | BC9: Week3 | BD9: Week4 | BE9: Week5
A10: 1 | B10: Preliminaries | C10: RO | D10: 1 | F10: =E10*D10 -> 0 | H10: =G10*D10 -> 0 | AW10: =AR10+AT10+AV10 -> 0 | AX10: =G10-AU10 -> 0 | BA10: 1 to 7 | BB10: 9 to 14 | BC10: 16 to 22 | BD10: 23 to 28
A11: 1.3.5(i)a | B11: Soil Investigation and report | C11: LS | D11: 7215 | F11: =E11*D11 -> 0 | H11: =G11*D11 -> 0 | AW11: =AR11+AT11+AV11 -> 0 | AX11: =G11-AU11 -> 0 | BA11: =SUM(I11:O11) -> 0 | BB11: =SUM(Q11:V11) -> 0 | BC11: =SUM(X11:AD11) -> 0 | BD11: =SUM(AE11:AJ11) -> 0
A12: 1.3.5(i)b | B12: Setting up at bore hole position for test up to 30m | C12: Nr. | D12: 32 | F12: =E12*D12 -> 0 | H12: =G12*D12 -> 0 | AW12: =AR12+AT12+AV12 -> 0 | AX12: =G12-AU12 -> 0 | BA12: =SUM(I12:O12) -> 0 | BB12: =SUM(Q12:V12) -> 0 | BC12: =SUM(X12:AD12) -> 0 | BD12: =SUM(AE12:AJ12) -> 0
A13: 1.3.5(i)c | B13: Setting up at bore hole position for test up to 10m | C13: Nr. | D13: 32 | F13: =E13*D13 -> 0 | H13: =G13*D13 -> 0 | AW13: =AR13+AT13+AV13 -> 0 | AX13: =G13-AU13 -> 0 | BA13: =SUM(I13:O13) -> 0 | BB13: =SUM(Q13:V13) -> 0 | BC13: =SUM(X13:AD13) -> 0 | BD13: =SUM(AE13:AJ13) -> 0
A14: 1.3.5(i)d | B14: Rotary core drilling up to 30m deep | C14: lin.m. | D14: 27 | F14: =E14*D14 -> 0 | H14: =G14*D14 -> 0 | AW14: =AR14+AT14+AV14 -> 0 | AX14: =G14-AU14 -> 0 | BA14: =SUM(I14:O14) -> 0 | BB14: =SUM(Q14:V14) -> 0 | BC14: =SUM(X14:AD14) -> 0 | BD14: =SUM(AE14:AJ14) -> 0
A15: 1.3.5(i)e | B15: Establish Location and excavate test pit 3m deep | C15: Nr. | D15: 42 | F15: =E15*D15 -> 0 | H15: =G15*D15 -> 0 | AW15: =AR15+AT15+AV15 -> 0 | AX15: =G15-AU15 -> 0 | BA15: =SUM(I15:O15) -> 0 | BB15: =SUM(Q15:V15) -> 0 | BC15: =SUM(X15:AD15) -> 0 | BD15: =SUM(AE15:AJ15) -> 0
A16: 1.3.5(ii) | B16: Design and approvel of IC construction | C16: LS | D16: 299000 | F16: =E16*D16 -> 0 | H16: =G16*D16 -> 0 | AW16: =AR16+AT16+AV16 -> 0 | AX16: =G16-AU16 -> 0 | BA16: =SUM(I16:O16) -> 0 | BB16: =SUM(Q16:V16) -> 0 | BC16: =SUM(X16:AD16) -> 0 | BD16: =SUM(AE16:AJ16) -> 0
A17: 1.4.3(i) | B17: Mobilization and demobilization | C17: LS | D17: 1624892.1 | F17: =E17*D17 -> 0 | H17: =G17*D17 -> 0 | AW17: =AR17+AT17+AV17 -> 0 | AX17: =G17-AU17 -> 0 | BA17: =SUM(I17:O17) -> 0 | BB17: =SUM(Q17:V17) -> 0 | BC17: =SUM(X17:AD17) -> 0 | BD17: =SUM(AE17:AJ17) -> 0
A18: 1.4.3(ii) | B18: Maintenance of Contractor's site facilities | C18: Month | D18: 138093.25 | F18: =E18*D18 -> 0 | H18: =G18*D18 -> 0 | AW18: =AR18+AT18+AV18 -> 0 | AX18: =G18-AW18 -> 0 | BA18: =SUM(I18:O18) -> 0 | BB18: =SUM(Q18:V18) -> 0 | BC18: =SUM(X18:AD18) -> 0 | BD18: =SUM(AE18:AJ18) -> 0
A19: 1.7.6(i)a | B19: Maintenance and Protection of Traffic | C19: Month | D19: 18184 | F19: =E19*D19 -> 0 | H19: =G19*D19 -> 0 | AW19: =AR19+AT19+AV19 -> 0 | AX19: =G19-AW19 -> 0 | BA19: =SUM(I19:O19) -> 0 | BB19: =SUM(Q19:V19) -> 0 | BC19: =SUM(X19:AD19) -> 0 | BD19: =SUM(AE19:AJ19) -> 0
