Workbook

Sheet Sheet1
A3: Row Labels | B3: Sum of Quantity (m3)
A5: Apr 26 | B5: 1615.1
A6: Dec 25 | B6: 1485.25
A7: Feb 26 | B7: 1870.25
A8: Jan 26 | B8: 2173.75
A9: Mar 26 | B9: 1013.5
A10: (blank)
A11: Grand Total | B11: 8157.85

Sheet Lima
B3: Sl. No. | C3: Date | D3: Location / Chainage | E3: Structure | F3: Element | G3: Grade | H3: Quantity (m3) | I3: Slump | J3: Temperature | K3: Plant | L3: Section | M3: Month
B4: 1 | C4: 45992 | D4: 47147 | E4: Box Culvert | F4: Wall & Top slab | G4: C35 | H4: 124 | I4: 12 | J4: 12 | K4: SCC KM47 | L4: =IF(Lima!$D4="Precast",#REF!,IF(Lima!$D4="","",IF(Lima!$D4<20000,"Khasab",IF(Lima!$D4<50000, "Lima",IF(Lima!$D4<72000,"Daba"))))) -> Lima | M4: =IF(Lima!$C4="","",TEXT(Lima!$C4,"mmm yy")) -> Dec 25 | N4: Unit-03
B5: =+B4+1 -> 2 | C5: 45993 | D5: 29035.572 | E5: Retaining Wall | F5: RW Wall (Segment-32 & 34) | G5: C30 | H5: 60 | I5: 6 | J5: 6 | K5: SCC Lima | L5: =IF(Lima!$D5="Precast",#REF!,IF(Lima!$D5="","",IF(Lima!$D5<20000,"Khasab",IF(Lima!$D5<50000, "Lima",IF(Lima!$D5<72000,"Daba"))))) -> Lima | M5: =IF(Lima!$C5="","",TEXT(Lima!$C5,"mmm yy")) -> Dec 25
B6: =+B5+1 -> 3 | C6: 45993 | D6: 35913 | E6: Box Culvert | F6: Blinding (Apron Slab) | G6: C15 | H6: 12.5 | I6: 2 | J6: 2 | K6: SCC Lima | L6: =IF(Lima!$D6="Precast",#REF!,IF(Lima!$D6="","",IF(Lima!$D6<20000,"Khasab",IF(Lima!$D6<50000, "Lima",IF(Lima!$D6<72000,"Daba"))))) -> Lima | M6: =IF(Lima!$C6="","",TEXT(Lima!$C6,"mmm yy")) -> Dec 25 | N6: outlet side
B7: =+B6+1 -> 4 | C7: 45993 | D7: 38936 | E7: Box Culvert | F7: Blinding (Apron Slab) | G7: C15 | H7: - | I7: - | J7: - | K7: SCC Lima | L7: =IF(Lima!$D7="Precast",#REF!,IF(Lima!$D7="","",IF(Lima!$D7<20000,"Khasab",IF(Lima!$D7<50000, "Lima",IF(Lima!$D7<72000,"Daba"))))) -> Lima | M7: =IF(Lima!$C7="","",TEXT(Lima!$C7,"mmm yy")) -> Dec 25 | N7: inlet & outlet side
B8: =+B7+1 -> 5 | C8: 45993 | D8: 46421 | E8: Box Culvert | F8: Apron Slab | G8: C35 | H8: 44.5 | I8: 5 | J8: 5 | K8: SCC Lima | L8: =IF(Lima!$D8="Precast",#REF!,IF(Lima!$D8="","",IF(Lima!$D8<20000,"Khasab",IF(Lima!$D8<50000, "Lima",IF(Lima!$D8<72000,"Daba"))))) -> Lima | M8: =IF(Lima!$C8="","",TEXT(Lima!$C8,"mmm yy")) -> Dec 25 | N8: inlet side
B9: =+B8+1 -> 6 | C9: 45994 | D9: 47786 | E9: Box Culvert | F9: Wall,Top slab & Headwall | G9: C35 | H9: 121 | I9: 12 | J9: 12 | K9: SCC KM47 | L9: =IF(Lima!$D9="Precast",#REF!,IF(Lima!$D9="","",IF(Lima!$D9<20000,"Khasab",IF(Lima!$D9<50000, "Lima",IF(Lima!$D9<72000,"Daba"))))) -> Lima | M9: =IF(Lima!$C9="","",TEXT(Lima!$C9,"mmm yy")) -> Dec 25 | N9: Unit-01
B10: =+B9+1 -> 7 | C10: 45994 | D10: 47786 | E10: Box Culvert | F10: wingwall | G10: C35 | H10: - | I10: - | J10: - | K10: SCC KM47 | L10: =IF(Lima!$D10="Precast",#REF!,IF(Lima!$D10="","",IF(Lima!$D10<20000,"Khasab",IF(Lima!$D10<50000, "Lima",IF(Lima!$D10<72000,"Daba"))))) -> Lima | M10: =IF(Lima!$C10="","",TEXT(Lima!$C10,"mmm yy")) -> Dec 25 | N10: outlet side
B11: =+B10+1 -> 8 | C11: 45997 | D11: 35913 | E11: Box Culvert | F11: Apron Slab | G11: C35 | H11: 26 | I11: 3 | J11: 3 | K11: SCC Lima | L11: =IF(Lima!$D11="Precast",#REF!,IF(Lima!$D11="","",IF(Lima!$D11<20000,"Khasab",IF(Lima!$D11<50000, "Lima",IF(Lima!$D11<72000,"Daba"))))) -> Lima | M11: =IF(Lima!$C11="","",TEXT(Lima!$C11,"mmm yy")) -> Dec 25 | N11: outlet side
B12: =+B11+1 -> 9 | C12: 45997 | D12: 36103 | E12: Box Culvert | F12: Apron Slab | G12: C35 | H12: - | I12: - | J12: - | K12: SCC Lima | L12: =IF(Lima!$D12="Precast",#REF!,IF(Lima!$D12="","",IF(Lima!$D12<20000,"Khasab",IF(Lima!$D12<50000, "Lima",IF(Lima!$D12<72000,"Daba"))))) -> Lima | M12: =IF(Lima!$C12="","",TEXT(Lima!$C12,"mmm yy")) -> Dec 25 | N12: inlet side
B13: =+B12+1 -> 10 | C13: 45997 | D13: 44590 | E13: Box Culvert | F13: Wall,Top slab & Headwall | G13: C35 | H13: 26.75 | I13: 3 | J13: 3 | K13: SCC Lima | L13: =IF(Lima!$D13="Precast",#REF!,IF(Lima!$D13="","",IF(Lima!$D13<20000,"Khasab",IF(Lima!$D13<50000, "Lima",IF(Lima!$D13<72000,"Daba"))))) -> Lima | M13: =IF(Lima!$C13="","",TEXT(Lima!$C13,"mmm yy")) -> Dec 25
B14: =+B13+1 -> 11 | C14: 45997 | D14: 48853 | E14: Box Culvert | F14: Blinding (Apron Slab) | G14: C15 | H14: 18 | I14: 2 | J14: 2 | K14: SCC KM47 | L14: =IF(Lima!$D14="Precast",#REF!,IF(Lima!$D14="","",IF(Lima!$D14<20000,"Khasab",IF(Lima!$D14<50000, "Lima",IF(Lima!$D14<72000,"Daba"))))) -> Lima | M14: =IF(Lima!$C14="","",TEXT(Lima!$C14,"mmm yy")) -> Dec 25 | N14: outlet side
B15: =+B14+1 -> 12 | C15: 45997 | D15: 47147 | E15: Box Culvert | F15: Base Slab | G15: C35 | H15: 110.5 | I15: 11 | J15: 11 | K15: SCC KM47 | L15: =IF(Lima!$D15="Precast",#REF!,IF(Lima!$D15="","",IF(Lima!$D15<20000,"Khasab",IF(Lima!$D15<50000, "Lima",IF(Lima!$D15<72000,"Daba"))))) -> Lima | M15: =IF(Lima!$C15="","",TEXT(Lima!$C15,"mmm yy")) -> Dec 25 | N15: unit-04
B16: =+B15+1 -> 13 | C16: 45998 | D16: 28980 | E16: Retaining Wall | F16: RW Wall (Segment-27 & 29) | G16: C30 | H16: 62 | I16: 6 | J16: 6 | K16: SCC Lima | L16: =IF(Lima!$D16="Precast",#REF!,IF(Lima!$D16="","",IF(Lima!$D16<20000,"Khasab",IF(Lima!$D16<50000, "Lima",IF(Lima!$D16<72000,"Daba"))))) -> Lima | M16: =IF(Lima!$C16="","",TEXT(Lima!$C16,"mmm yy")) -> Dec 25
B17: =+B16+1 -> 14 | C17: 45999 | D17: 36103 | E17: Box Culvert | F17: Wingwall | G17: C35 | H17: 7 | I17: 1 | J17: 1 | K17: SCC Lima | L17: =IF(Lima!$D17="Precast",#REF!,IF(Lima!$D17="","",IF(Lima!$D17<20000,"Khasab",IF(Lima!$D17<50000, "Lima",IF(Lima!$D17<72000,"Daba"))))) -> Lima | M17: =IF(Lima!$C17="","",TEXT(Lima!$C17,"mmm yy")) -> Dec 25 | N17: inlet side
B18: =+B17+1 -> 15 | C18: 45999 | D18: 35913 | E18: Box Culvert | F18: Wingwall | G18: C35 | H18: - | I18: - | J18: - | K18: SCC Lima | L18: =IF(Lima!$D18="Precast",#REF!,IF(Lima!$D18="","",IF(Lima!$D18<20000,"Khasab",IF(Lima!$D18<50000, "Lima",IF(Lima!$D18<72000,"Daba"))))) -> Lima | M18: =IF(Lima!$C18="","",TEXT(Lima!$C18,"mmm yy")) -> Dec 25 | N18: outlet side
B19: =+B18+1 -> 16 | C19: 45999 | D19: 36103 | E19: Box Culvert | F19: Blinding (Apron Slab) | G19: C15 | H19: 5 | I19: 1 | J19: 1 | K19: SCC Lima | L19: =IF(Lima!$D19="Precast",#REF!,IF(Lima!$D19="","",IF(Lima!$D19<20000,"Khasab",IF(Lima!$D19<50000, "Lima",IF(Lima!$D19<72000,"Daba"))))) -> Lima | M19: =IF(Lima!$C19="","",TEXT(Lima!$C19,"mmm yy")) -> Dec 25 | N19: outlet side
B20: =+B19+1 -> 17 | C20: 45999 | D20: 22100 | E20: Utility Duct | F20: Concrete Encasement (Future Duct) | G20: C25 | H20: 10 | I20: 1 | J20: 1 | K20: SCC Lima | L20: =IF(Lima!$D20="Precast",#REF!,IF(Lima!$D20="","",IF(Lima!$D20<20000,"Khasab",IF(Lima!$D20<50000, "Lima",IF(Lima!$D20<72000,"Daba"))))) -> Lima | M20: =IF(Lima!$C20="","",TEXT(Lima!$C20,"mmm yy")) -> Dec 25
B21: =+B20+1 -> 18 | C21: 45999 | D21: 21800 | E21: Utility Duct | F21: Concrete Encasement (Future Duct) | G21: C25 | H21: - | I21: - | J21: - | K21: SCC Lima | L21: =IF(Lima!$D21="Precast",#REF!,IF(Lima!$D21="","",IF(Lima!$D21<20000,"Khasab",IF(Lima!$D21<50000, "Lima",IF(Lima!$D21<72000,"Daba"))))) -> Lima | M21: =IF(Lima!$C21="","",TEXT(Lima!$C21,"mmm yy")) -> Dec 25
B22: =+B21+1 -> 19 | C22: 45999 | D22: 21110 | E22: OBB Duct | F22: Concrete Encasement (OBB Road Cross) | G22: C25 | H22: 10 | I22: 1 | J22: 1 | K22: SCC Lima | L22: =IF(Lima!$D22="Precast",#REF!,IF(Lima!$D22="","",IF(Lima!$D22<20000,"Khasab",IF(Lima!$D22<50000, "Lima",IF(Lima!$D22<72000,"Daba"))))) -> Lima | M22: =IF(Lima!$C22="","",TEXT(Lima!$C22,"mmm yy")) -> Dec 25
B23: =+B22+1 -> 20 | C23: 45999 | D23: 22110 | E23: OBB Duct | F23: Concrete Encasement (OBB Road Cross) | G23: C25 | H23: - | I23: - | J23: - | K23: SCC Lima | L23: =IF(Lima!$D23="Precast",#REF!,IF(Lima!$D23="","",IF(Lima!$D23<20000,"Khasab",IF(Lima!$D23<50000, "Lima",IF(Lima!$D23<72000,"Daba"))))) -> Lima | M23: =IF(Lima!$C23="","",TEXT(Lima!$C23,"mmm yy")) -> Dec 25
B24: =+B23+1 -> 21 | C24: 45999 | D24: 47786 | E24: Box Culvert | F24: Apron Slab | G24: C35 | H24: 37 | I24: 5 | J24: 5 | K24: SCC KM47 | L24: =IF(Lima!$D24="Precast",#REF!,IF(Lima!$D24="","",IF(Lima!$D24<20000,"Khasab",IF(Lima!$D24<50000, "Lima",IF(Lima!$D24<72000,"Daba"))))) -> Lima | M24: =IF(Lima!$C24="","",TEXT(Lima!$C24,"mmm yy")) -> Dec 25 | N24: inlet side
B25: =+B24+1 -> 22 | C25: 46000 | D25: 44590 | E25: Box Culvert | F25: Apron Slab | G25: C35 | H25: 7 | I25: 1 | J25: 1 | K25: SCC Lima | L25: =IF(Lima!$D25="Precast",#REF!,IF(Lima!$D25="","",IF(Lima!$D25<20000,"Khasab",IF(Lima!$D25<50000, "Lima",IF(Lima!$D25<72000,"Daba"))))) -> Lima | M25: =IF(Lima!$C25="","",TEXT(Lima!$C25,"mmm yy")) -> Dec 25 | N25: inlet side
B26: =+B25+1 -> 23 | C26: 46000 | D26: 48853 | E26: Box Culvert | F26: Apron Slab | G26: C35 | H26: 39 | I26: 5 | J26: 5 | L26: =IF(Lima!$D26="Precast",#REF!,IF(Lima!$D26="","",IF(Lima!$D26<20000,"Khasab",IF(Lima!$D26<50000, "Lima",IF(Lima!$D26<72000,"Daba"))))) -> Lima | M26: =IF(Lima!$C26="","",TEXT(Lima!$C26,"mmm yy")) -> Dec 25 | N26: outlet side
B27: =+B26+1 -> 24 | C27: 46001 | D27: 38452 | E27: Box Culvert | F27: Blinding | G27: C15 | H27: 13 | I27: 2 | J27: 2 | K27: SCC Lima | L27: =IF(Lima!$D27="Precast",#REF!,IF(Lima!$D27="","",IF(Lima!$D27<20000,"Khasab",IF(Lima!$D27<50000, "Lima",IF(Lima!$D27<72000,"Daba"))))) -> Lima | M27: =IF(Lima!$C27="","",TEXT(Lima!$C27,"mmm yy")) -> Dec 25
B28: =+B27+1 -> 25 | C28: 46001 | D28: 36103 | E28: Box Culvert | F28: Apron Slab | G28: C35 | H28: 13 | I28: 2 | J28: 2 | K28: SCC Lima | L28: =IF(Lima!$D28="Precast",#REF!,IF(Lima!$D28="","",IF(Lima!$D28<20000,"Khasab",IF(Lima!$D28<50000, "Lima",IF(Lima!$D28<72000,"Daba"))))) -> Lima | M28: =IF(Lima!$C28="","",TEXT(Lima!$C28,"mmm yy")) -> Dec 25 | N28: outlet side
B29: =+B28+1 -> 26 | C29: 46001 | D29: 28300 | E29: Box Culvert | F29: Concrete Encasement (Existing Electric Cable) | G29: C25 | H29: 20 | I29: 2 | J29: 2 | K29: SCC Lima | L29: =IF(Lima!$D29="Precast",#REF!,IF(Lima!$D29="","",IF(Lima!$D29<20000,"Khasab",IF(Lima!$D29<50000, "Lima",IF(Lima!$D29<72000,"Daba"))))) -> Lima | M29: =IF(Lima!$C29="","",TEXT(Lima!$C29,"mmm yy")) -> Dec 25
B30: =+B29+1 -> 27 | C30: 46002 | D30: 44590 | E30: Box Culvert | F30: Wingwall | G30: C35 | H30: 7 | I30: 1 | J30: 1 | K30: SCC Lima | L30: =IF(Lima!$D30="Precast",#REF!,IF(Lima!$D30="","",IF(Lima!$D30<20000,"Khasab",IF(Lima!$D30<50000, "Lima",IF(Lima!$D30<72000,"Daba"))))) -> Lima | M30: =IF(Lima!$C30="","",TEXT(Lima!$C30,"mmm yy")) -> Dec 25 | N30: inlet side
B31: =+B30+1 -> 28 | C31: 46002 | D31: 44590 | E31: Box Culvert | F31: Blinding (Apron Slab) | G31: C35 | H31: - | I31: - | J31: - | K31: SCC Lima | L31: =IF(Lima!$D31="Precast",#REF!,IF(Lima!$D31="","",IF(Lima!$D31<20000,"Khasab",IF(Lima!$D31<50000, "Lima",IF(Lima!$D31<72000,"Daba"))))) -> Lima | M31: =IF(Lima!$C31="","",TEXT(Lima!$C31,"mmm yy")) -> Dec 25 | N31: outlet side
B32: =+B31+1 -> 29 | C32: 46002 | D32: 21700 | E32: Box Culvert | F32: Wall,Top slab & Headwall | G32: C35 | H32: 255 | I32: 24 | J32: 24 | K32: SCC Lima | L32: =IF(Lima!$D32="Precast",L4,IF(Lima!$D32="","",IF(Lima!$D32<20000,"Khasab",IF(Lima!$D32<50000, "Lima",IF(Lima!$D32<72000,"Daba"))))) -> Lima | M32: =IF(Lima!$C32="","",TEXT(Lima!$C32,"mmm yy")) -> Dec 25 | N32: Unit-01
B33: =+B32+1 -> 30 | C33: 46002 | D33: 47786 | E33: Box Culvert | F33: Wall,Top slab & Headwall | G33: C35 | H33: 115 | I33: 10 | J33: 10 | K33: SCC KM47 | L33: =IF(Lima!$D33="Precast",L5,IF(Lima!$D33="","",IF(Lima!$D33<20000,"Khasab",IF(Lima!$D33<50000, "Lima",IF(Lima!$D33<72000,"Daba"))))) -> Lima | M33: =IF(Lima!$C33="","",TEXT(Lima!$C33,"mmm yy")) -> Dec 25 | N33: unit-02
B34: =+B33+1 -> 31 | C34: 46004 | D34: 36103 | E34: Box Culvert | F34: Wingwall | G34: C35 | H34: 4 | I34: 1 | J34: 1 | K34: SCC Lima | L34: =IF(Lima!$D34="Precast",L6,IF(Lima!$D34="","",IF(Lima!$D34<20000,"Khasab",IF(Lima!$D34<50000, "Lima",IF(Lima!$D34<72000,"Daba"))))) -> Lima | M34: =IF(Lima!$C34="","",TEXT(Lima!$C34,"mmm yy")) -> Dec 25 | N34: outlet side
B35: =+B34+1 -> 32 | C35: 46004 | D35: 44590 | E35: Box Culvert | F35: Apron Slab | G35: C35 | H35: 13 | I35: 2 | J35: 2 | K35: SCC KM47 | L35: =IF(Lima!$D35="Precast",L7,IF(Lima!$D35="","",IF(Lima!$D35<20000,"Khasab",IF(Lima!$D35<50000, "Lima",IF(Lima!$D35<72000,"Daba"))))) -> Lima | M35: =IF(Lima!$C35="","",TEXT(Lima!$C35,"mmm yy")) -> Dec 25 | N35: outlet side
B36: =+B35+1 -> 33 | C36: 46004 | D36: 46421 | E36: Box Culvert | F36: Wingwall | G36: C35 | H36: - | I36: - | J36: - | K36: SCC KM47 | L36: =IF(Lima!$D36="Precast",L8,IF(Lima!$D36="","",IF(Lima!$D36<20000,"Khasab",IF(Lima!$D36<50000, "Lima",IF(Lima!$D36<72000,"Daba"))))) -> Lima | M36: =IF(Lima!$C36="","",TEXT(Lima!$C36,"mmm yy")) -> Dec 25 | N36: inlet side
B37: =+B36+1 -> 34 | C37: 46005 | D37: 44590 | E37: Box Culvert | F37: Wingwall | G37: C35 | H37: 13 | I37: 2 | J37: 2 | K37: SCC Lima | L37: =IF(Lima!$D37="Precast",L9,IF(Lima!$D37="","",IF(Lima!$D37<20000,"Khasab",IF(Lima!$D37<50000, "Lima",IF(Lima!$D37<72000,"Daba"))))) -> Lima | M37: =IF(Lima!$C37="","",TEXT(Lima!$C37,"mmm yy")) -> Dec 25 | N37: outlet side
B38: =+B37+1 -> 35 | C38: 46005 | D38: 48853 | E38: Box Culvert | F38: Wingwall | G38: C35 | H38: - | I38: - | J38: - | K38: SCC Lima | L38: =IF(Lima!$D38="Precast",L10,IF(Lima!$D38="","",IF(Lima!$D38<20000,"Khasab",IF(Lima!$D38<50000, "Lima",IF(Lima!$D38<72000,"Daba"))))) -> Lima | M38: =IF(Lima!$C38="","",TEXT(Lima!$C38,"mmm yy")) -> Dec 25 | N38: outlet side
B39: =+B38+1 -> 36 | C39: 46005 | D39: 47786 | E39: Box Culvert | F39: Wingwall | G39: C35 | H39: - | I39: - | J39: - | K39: SCC Lima | L39: =IF(Lima!$D39="Precast",L11,IF(Lima!$D39="","",IF(Lima!$D39<20000,"Khasab",IF(Lima!$D39<50000, "Lima",IF(Lima!$D39<72000,"Daba"))))) -> Lima | M39: =IF(Lima!$C39="","",TEXT(Lima!$C39,"mmm yy")) -> Dec 25 | N39: inlet side
B40: =+B39+1 -> 37 | C40: 46005 | D40: 47147 | E40: Box Culvert | F40: Base Slab | G40: C35 | H40: 113.5 | I40: 12 | J40: 12 | K40: SCC KM47 | L40: =IF(Lima!$D40="Precast",L12,IF(Lima!$D40="","",IF(Lima!$D40<20000,"Khasab",IF(Lima!$D40<50000, "Lima",IF(Lima!$D40<72000,"Daba"))))) -> Lima | M40: =IF(Lima!$C40="","",TEXT(Lima!$C40,"mmm yy")) -> Dec 25 | N40: Unit-05
B41: =+B40+1 -> 38 | C41: 46006 | D41: 40135 | E41: Box Culvert | F41: Blinding (Apron Slab) | G41: C15 | H41: 19 | I41: 2 | J41: 2 | K41: SCC Lima | L41: =IF(Lima!$D41="Precast",L13,IF(Lima!$D41="","",IF(Lima!$D41<20000,"Khasab",IF(Lima!$D41<50000, "Lima",IF(Lima!$D41<72000,"Daba"))))) -> Lima | M41: =IF(Lima!$C41="","",TEXT(Lima!$C41,"mmm yy")) -> Dec 25 | N41: inlet & outlet side
B42: =+B41+1 -> 39 | C42: 46006 | D42: 47147 | E42: Box Culvert | F42: Wall,Top slab & Headwall | G42: C35 | H42: 124 | I42: 14 | J42: 14 | K42: SCC KM47 | L42: =IF(Lima!$D42="Precast",L14,IF(Lima!$D42="","",IF(Lima!$D42<20000,"Khasab",IF(Lima!$D42<50000, "Lima",IF(Lima!$D42<72000,"Daba"))))) -> Lima | M42: =IF(Lima!$C42="","",TEXT(Lima!$C42,"mmm yy")) -> Dec 25 | N42: Unit-02
...
