Workbook
Name _____Jan02: [1]data!$K$3:$K$295
Name _____Jan03: [1]data!$W$3:$W$295
Name _____Job1: '[2]BP Data'!$B$5:$B$280
Name _____Jul02: [1]data!$Q$3:$Q$295
Name _____Jun02: [1]data!$P$3:$P$295
Name _____Jun03: [1]data!$AB$3:$AB$295
Name ____Jan02: [3]data!$K$3:$K$295
Name ____Jan03: [3]data!$W$3:$W$295
Name ____Jun02: [3]data!$P$3:$P$295
Name ____Jun03: [3]data!$AB$3:$AB$295
Name ____tf3: [4]Intro!$J$148
Name ____tf4: [4]Intro!$J$150
Name ____tfd1: [4]Intro!$L$141
Name ____tfd2: [4]Intro!$L$143
Name ____tfd3: [4]Intro!$L$147
Name ____tfd4: [4]Intro!$L$149
Name ____tr1: [4]Intro!$C$140
Name ____tr2: [4]Intro!$C$142
Name ____tr3: [4]Intro!$C$150
Name ____trd1: [4]Intro!$B$140
Name ____trd2: [4]Intro!$B$142
Name ____trd3: [4]Intro!$B$148
Name ___Jun02: [3]data!$P$3:$P$295
Name ___Jun03: [3]data!$AB$3:$AB$295
Name ___tf2: [4]Intro!$J$142
Name ___tf3: [4]Intro!$J$148
Name ___tf4: [4]Intro!$J$150
Name ___tfd1: [4]Intro!$L$141
Name ___tfd2: [4]Intro!$L$143
Name ___tfd3: [4]Intro!$L$147
Name ___tfd4: [4]Intro!$L$149
Name ___tr1: [4]Intro!$C$140
Name ___tr2: [4]Intro!$C$142
Name ___tr3: [4]Intro!$C$150
Name ___trd1: [4]Intro!$B$140
Name ___trd2: [4]Intro!$B$142
Name ___trd3: [4]Intro!$B$148
Name __Jun02: [6]data!$P$3:$P$295
Name __Jun03: [6]data!$AB$3:$AB$295
Name __pg18: [7]Sheet10!$A$1:$S$66
Name __pg19: [7]Sheet9!$A$1:$M$52
Name __pg2: [7]Sheet1!$A$40:$J$76
Name __pg20: [7]Sheet11!$A$1:$W$26
Name __Pg21: [7]Sheet12!$A$1
Name __pg22: [7]Sheet13!$A$3
Name __pg23: [7]sheet14!$B$8
Name __pg24: '[8]Cash flow_curv'!$A$1
Name __pg25: [7]Sheet16!$C$36
Name __pg26: [7]Sheet17!$A$4
Name __pg27: [7]Sheet18!$A$1
Name __pg28: [7]Sheet19!$A$1
Name __pg3: [7]Sheet1!$A$78:$J$108
Name __pg4: [7]Sheet1!$A$110:$J$142
Name __pg5: [7]Sheet1!$A$144:$J$165
Name __pg6: [7]Sheet1!$A$168:$J$196
Name __pg7: '[7]Sheet1(2)'!$B$1:$D$25
Name __pg8: [7]Sheet2!$A$1:$G$41
Name __pg9: [7]Sheet2!$A$45:$G$87
Name __tf1: [4]Intro!$J$140
Name __tf2: [4]Intro!$J$142

Sheet MP & Eqpt Summary
B1: =SUMPRODUCT(--(#REF!='MP & Eqpt Summary'!G1),#REF!*1) -> #REF! | G1: ='Summary-Financial'!AB2 -> xxxx | H1: Major Equipment deployment
B2: SL No | C2: Resource Code | D2: Item Code | E2: Unit | F2: Description | G2: Rate | H2: Prelims | I2: T Swamy | J2: A K Singh | K2: A Nagarajan | L2: Off Road | M2: Total | N2: Available @ site | O2: Variation
A3: GRAD | B3: 1 | C3: E | D3: GRA | E3: Day | F3: Grader | G3: =VLOOKUP(F3,'MP & Eqpt Summary 1'!$D$3:$E$61,2,0) -> 0 | H3: =VLOOKUP($F3,'MP & Eqpt Summary 1'!$D$3:$AB$81,14,0) -> 0 | M3: =SUM(H3:L3) -> 0 | N3: =VLOOKUP($F3,'MP & Eqpt Summary 1'!$D$3:$AB$81,19,0) -> 0 | O3: =N3-M3 -> 0 | P3: 0 | Q3: =P3-N3 -> 0
A4: VIBR | B4: =B3+1 -> 2 | C4: E | D4: V.ROL | E4: Day | F4: Vibratory Roller | G4: =VLOOKUP(F4,'MP & Eqpt Summary 1'!$D$3:$E$61,2,0) -> 0 | H4: =VLOOKUP($F4,'MP & Eqpt Summary 1'!$D$3:$AB$81,14,0) -> 0 | M4: =SUM(H4:L4) -> 0 | N4: =VLOOKUP($F4,'MP & Eqpt Summary 1'!$D$3:$AB$81,19,0) -> 0 | O4: =N4-M4 -> 0 | P4: 0 | Q4: =P4-N4 -> 0
A5: VIBRH | B5: =B4+1 -> 3 | C5: E | D5: V.ROL (H) | E5: Day | F5: Vibratory Roller (Hire) | G5: 0 | M5: =SUM(H5:L5) -> 0 | O5: =N5-M5 -> 0 | P5: 0 | Q5: =P5-N5 -> 0
A6: DOZ | B6: =B5+1 -> 4 | C6: E | D6: DOZ | E6: Day | F6: Bull Dozer | G6: =VLOOKUP(F6,'MP & Eqpt Summary 1'!$D$3:$E$61,2,0) -> 0 | H6: =VLOOKUP($F6,'MP & Eqpt Summary 1'!$D$3:$AB$81,14,0) -> 0 | M6: =SUM(H6:L6) -> 0 | N6: =VLOOKUP($F6,'MP & Eqpt Summary 1'!$D$3:$AB$81,19,0) -> 0 | O6: =N6-M6 -> 0 | P6: 0 | Q6: =P6-N6 -> 0
A7: SVL | B7: =B6+1 -> 5 | C7: E | D7: SHL | E7: Day | F7: Wheel Loader | G7: =VLOOKUP(F7,'MP & Eqpt Summary 1'!$D$3:$E$61,2,0) -> 0 | H7: =VLOOKUP($F7,'MP & Eqpt Summary 1'!$D$3:$AB$81,14,0) -> 0 | M7: =SUM(H7:L7) -> 0 | N7: =VLOOKUP($F7,'MP & Eqpt Summary 1'!$D$3:$AB$81,19,0) -> 0 | O7: =N7-M7 -> 0 | P7: 0 | Q7: =P7-N7 -> 0
A8: JCB | B8: =B7+1 -> 6 | C8: E | D8: BHL | E8: Day | F8: Back Hoe Loader | G8: =VLOOKUP(F8,'MP & Eqpt Summary 1'!$D$3:$E$61,2,0) -> 0 | H8: =VLOOKUP($F8,'MP & Eqpt Summary 1'!$D$3:$AB$81,14,0) -> 0 | M8: =SUM(H8:L8) -> 0 | N8: =VLOOKUP($F8,'MP & Eqpt Summary 1'!$D$3:$AB$81,19,0) -> 0 | O8: =N8-M8 -> 0 | P8: 0 | Q8: =P8-N8 -> 0
A9: JCBH | B9: =B8+1 -> 7 | C9: E | D9: BHL (H) | E9: Day | F9: Back Hoe Loader (Hire) | G9: =VLOOKUP(F9,'MP & Eqpt Summary 1'!$D$3:$E$61,2,0) -> 0 | H9: =VLOOKUP($F9,'MP & Eqpt Summary 1'!$D$3:$AB$81,14,0) -> 0 | M9: =SUM(H9:L9) -> 0 | N9: =VLOOKUP($F9,'MP & Eqpt Summary 1'!$D$3:$AB$81,19,0) -> 0 | O9: =N9-M9 -> 0 | P9: 0 | Q9: =P9-N9 -> 0
A10: Mnt | B10: =B9+1 -> 8 | C10: Manlift | D10: 50.96 | E10: 0 | F10: Manlift | G10: =VLOOKUP(F10,'MP & Eqpt Summary 1'!$D$3:$E$61,2,0) -> 0 | H10: =VLOOKUP($F10,'MP & Eqpt Summary 1'!$D$3:$AB$81,14,0) -> 0 | M10: =SUM(H10:L10) -> 0 | N10: =VLOOKUP($F10,'MP & Eqpt Summary 1'!$D$3:$AB$81,19,0) -> 0 | O10: =N10-M10 -> 0 | P10: 0 | Q10: =P10-N10 -> 0
A11: EXC | B11: =B10+1 -> 9 | C11: E | D11: EXC | E11: Day | F11: Excavator | G11: =VLOOKUP(F11,'MP & Eqpt Summary 1'!$D$3:$E$61,2,0) -> 0 | H11: =VLOOKUP($F11,'MP & Eqpt Summary 1'!$D$3:$AB$81,14,0) -> 0 | M11: =SUM(H11:L11) -> 0 | N11: =VLOOKUP($F11,'MP & Eqpt Summary 1'!$D$3:$AB$81,19,0) -> 0 | O11: =N11-M11 -> 0 | P11: 0 | Q11: =P11-N11 -> 0
A12: WATB | B12: =B11+1 -> 10 | C12: E | D12: Tanker Bra | E12: Day | F12: Brackish Water Tanker | G12: =VLOOKUP(F12,'MP & Eqpt Summary 1'!$D$3:$E$61,2,0) -> 0 | H12: =VLOOKUP($F12,'MP & Eqpt Summary 1'!$D$3:$AB$81,14,0) -> 0 | M12: =SUM(H12:L12) -> 0 | N12: =VLOOKUP($F12,'MP & Eqpt Summary 1'!$D$3:$AB$81,19,0) -> 0 | O12: =N12-M12 -> 0 | P12: 0 | Q12: =P12-N12 -> 0
A13: WATT | B13: =B12+1 -> 11 | C13: E | D13: Tanker Tra | E13: Day | F13: Trailer Tanker (Brackish) | G13: =VLOOKUP(F13,'MP & Eqpt Summary 1'!$D$3:$E$61,2,0) -> 0 | H13: =VLOOKUP($F13,'MP & Eqpt Summary 1'!$D$3:$AB$81,14,0) -> 0 | M13: =SUM(H13:L13) -> 0 | N13: =VLOOKUP($F13,'MP & Eqpt Summary 1'!$D$3:$AB$81,19,0) -> 0 | O13: =N13-M13 -> 0 | P13: 0 | Q13: =P13-N13 -> 0 | T13: =36.68+80 -> 116.68
A14: TPRTR | B14: =B13+1 -> 12 | C14: E | D14: Tipper Tra | E14: Day | F14: Trailer Tipper | G14: =VLOOKUP(F14,'MP & Eqpt Summary 1'!$D$3:$E$61,2,0) -> 0 | H14: =VLOOKUP($F14,'MP & Eqpt Summary 1'!$D$3:$AB$81,14,0) -> 0 | M14: =SUM(H14:L14) -> 0 | N14: =VLOOKUP($F14,'MP & Eqpt Summary 1'!$D$3:$AB$81,19,0) -> 0 | O14: =N14-M14 -> 0 | P14: 0 | Q14: =P14-N14 -> 0 | T14: =T13/2 -> 58.34
A15: TPR | B15: =B14+1 -> 13 | C15: E | D15: TIP | E15: Day | F15: Tipper | G15: =VLOOKUP(F15,'MP & Eqpt Summary 1'!$D$3:$E$61,2,0) -> 0 | H15: =VLOOKUP($F15,'MP & Eqpt Summary 1'!$D$3:$AB$81,14,0) -> 0 | M15: =SUM(H15:L15) -> 0 | N15: =VLOOKUP($F15,'MP & Eqpt Summary 1'!$D$3:$AB$81,19,0) -> 0 | O15: =N15-M15 -> 0 | P15: 0 | Q15: =P15-N15 -> 0
A16: BDT | B16: =B15+1 -> 14 | C16: E | D16: Tanker Bit | E16: Day | F16: Bitumen Distributor | G16: =VLOOKUP(F16,'MP & Eqpt Summary 1'!$D$3:$E$61,2,0) -> 0 | H16: =VLOOKUP($F16,'MP & Eqpt Summary 1'!$D$3:$AB$81,14,0) -> 0 | M16: =SUM(H16:L16) -> 0 | N16: =VLOOKUP($F16,'MP & Eqpt Summary 1'!$D$3:$AB$81,19,0) -> 0 | O16: =N16-M16 -> 0 | P16: 0 | Q16: =P16-N16 -> 0
A17: TR | B17: =B16+1 -> 15 | C17: E | D17: Tandem H | E17: Day | F17: Tandem Roller | G17: =VLOOKUP(F17,'MP & Eqpt Summary 1'!$D$3:$E$61,2,0) -> 0 | H17: =VLOOKUP($F17,'MP & Eqpt Summary 1'!$D$3:$AB$81,14,0) -> 0 | M17: =SUM(H17:L17) -> 0 | N17: =VLOOKUP($F17,'MP & Eqpt Summary 1'!$D$3:$AB$81,19,0) -> 0 | O17: =N17-M17 -> 0 | P17: 0 | Q17: =P17-N17 -> 0
A18: PTR | B18: =B17+1 -> 16 | C18: E | D18: PTR | E18: Day | F18: Ptr | G18: =VLOOKUP(F18,'MP & Eqpt Summary 1'!$D$3:$E$61,2,0) -> 0 | H18: =VLOOKUP($F18,'MP & Eqpt Summary 1'!$D$3:$AB$81,14,0) -> 0 | M18: =SUM(H18:L18) -> 0 | N18: =VLOOKUP($F18,'MP & Eqpt Summary 1'!$D$3:$AB$81,19,0) -> 0 | O18: =N18-M18 -> 0 | P18: 0 | Q18: =P18-N18 -> 0
A19: MTR | B19: =B18+1 -> 17 | C19: E | D19: Tandem M | E19: Day | F19: Mini Tandem Roller | G19: =VLOOKUP(F19,'MP & Eqpt Summary 1'!$D$3:$E$61,2,0) -> 0 | H19: =VLOOKUP($F19,'MP & Eqpt Summary 1'!$D$3:$AB$81,14,0) -> 0 | M19: =SUM(H19:L19) -> 0 | N19: =VLOOKUP($F19,'MP & Eqpt Summary 1'!$D$3:$AB$81,19,0) -> 0 | O19: =N19-M19 -> 0 | P19: 0 | Q19: =P19-N19 -> 0
A20: PVA | B20: =B19+1 -> 18 | C20: E | D20: PAV | E20: Day | F20: Paver Asphalt | G20: =VLOOKUP(F20,'MP & Eqpt Summary 1'!$D$3:$E$61,2,0) -> 0 | H20: =VLOOKUP($F20,'MP & Eqpt Summary 1'!$D$3:$AB$81,14,0) -> 0 | M20: =SUM(H20:L20) -> 0 | N20: =VLOOKUP($F20,'MP & Eqpt Summary 1'!$D$3:$AB$81,19,0) -> 0 | O20: =N20-M20 -> 0 | P20: 0 | Q20: =P20-N20 -> 0
A21: HIAB | B21: =B20+1 -> 19 | C21: E | D21: Hiab | E21: Day | F21: Cargo With L/E | G21: =VLOOKUP(F21,'MP & Eqpt Summary 1'!$D$3:$E$61,2,0) -> 0 | H21: =VLOOKUP($F21,'MP & Eqpt Summary 1'!$D$3:$AB$81,14,0) -> 0 | M21: =SUM(H21:L21) -> 0 | N21: =VLOOKUP($F21,'MP & Eqpt Summary 1'!$D$3:$AB$81,19,0) -> 0 | O21: =N21-M21 -> 0 | P21: 0 | Q21: =P21-N21 -> 0
A22: CRA25 | B22: =B21+1 -> 20 | C22: E | D22: CRA | E22: Day | F22: Crane | G22: =VLOOKUP(F22,'MP & Eqpt Summary 1'!$D$3:$E$61,2,0) -> 0 | H22: =VLOOKUP($F22,'MP & Eqpt Summary 1'!$D$3:$AB$81,14,0) -> 0 | M22: =SUM(H22:L22) -> 0 | N22: =VLOOKUP($F22,'MP & Eqpt Summary 1'!$D$3:$AB$81,19,0) -> 0 | O22: =N22-M22 -> 0 | P22: 0 | Q22: =P22-N22 -> 0
A23: TRH | B23: =B22+1 -> 21 | C23: E | D23: High Bed | E23: Day | F23: Trailer High Bed | G23: =VLOOKUP(F23,'MP & Eqpt Summary 1'!$D$3:$E$61,2,0) -> 0 | H23: =VLOOKUP($F23,'MP & Eqpt Summary 1'!$D$3:$AB$81,14,0) -> 0 | M23: =SUM(H23:L23) -> 0 | N23: =VLOOKUP($F23,'MP & Eqpt Summary 1'!$D$3:$AB$81,19,0) -> 0 | O23: =N23-M23 -> 0 | P23: 0 | Q23: =P23-N23 -> 0
A24: LBT | B24: =B23+1 -> 22 | F24: Low bed trailer | G24: =VLOOKUP(F24,'MP & Eqpt Summary 1'!$D$3:$E$61,2,0) -> 0 | H24: =VLOOKUP($F24,'MP & Eqpt Summary 1'!$D$3:$AB$81,14,0) -> 0 | M24: =SUM(H24:L24) -> 0 | N24: =VLOOKUP($F24,'MP & Eqpt Summary 1'!$D$3:$AB$81,19,0) -> 0 | O24: =N24-M24 -> 0
A25: LAL | B25: =B24+1 -> 23 | C25: E | D25: LA | E25: Day | F25: Loadall | G25: =VLOOKUP(F25,'MP & Eqpt Summary 1'!$D$3:$E$61,2,0) -> 0 | H25: =VLOOKUP($F25,'MP & Eqpt Summary 1'!$D$3:$AB$81,14,0) -> 0 | M25: =SUM(H25:L25) -> 0 | N25: =VLOOKUP($F25,'MP & Eqpt Summary 1'!$D$3:$AB$81,19,0) -> 0 | O25: =N25-M25 -> 0 | P25: 0 | Q25: =P25-N25 -> 0
A26: tc | B26: =B25+1 -> 24 | C26: E | D26: TC | E26: Day | F26: Tool Carrier | G26: =VLOOKUP(F26,'MP & Eqpt Summary 1'!$D$3:$E$61,2,0) -> 0 | H26: =VLOOKUP($F26,'MP & Eqpt Summary 1'!$D$3:$AB$81,14,0) -> 0 | M26: =SUM(H26:L26) -> 0 | N26: =VLOOKUP($F26,'MP & Eqpt Summary 1'!$D$3:$AB$81,19,0) -> 0 | O26: =N26-M26 -> 0 | P26: 0 | Q26: =P26-N26 -> 0
A27: SKID | B27: =B26+1 -> 25 | C27: E | D27: Skid | E27: Day | F27: Skid Loader | G27: =VLOOKUP(F27,'MP & Eqpt Summary 1'!$D$3:$E$61,2,0) -> 0 | H27: =VLOOKUP($F27,'MP & Eqpt Summary 1'!$D$3:$AB$81,14,0) -> 0 | M27: =SUM(H27:L27) -> 0 | N27: =VLOOKUP($F27,'MP & Eqpt Summary 1'!$D$3:$AB$81,19,0) -> 0 | O27: =N27-M27 -> 0 | P27: 0 | Q27: =P27-N27 -> 0
A28: PDM | B28: =B27+1 -> 26 | C28: E | D28: Guard | E28: Day | F28: Guard Rail M/C | G28: =VLOOKUP(F28,'MP & Eqpt Summary 1'!$D$3:$E$61,2,0) -> 0 | H28: =VLOOKUP($F28,'MP & Eqpt Summary 1'!$D$3:$AB$81,14,0) -> 0 | M28: =SUM(H28:L28) -> 0 | N28: =VLOOKUP($F28,'MP & Eqpt Summary 1'!$D$3:$AB$81,19,0) -> 0 | O28: =N28-M28 -> 0 | P28: 0 | Q28: =P28-N28 -> 0
A29: AC | B29: =B28+1 -> 27 | C29: E | D29: Asp Cut | E29: Day | F29: Asphalt Cutter | G29: =VLOOKUP(F29,'MP & Eqpt Summary 1'!$D$3:$E$61,2,0) -> 0 | H29: =VLOOKUP($F29,'MP & Eqpt Summary 1'!$D$3:$AB$81,14,0) -> 0 | M29: =SUM(H29:L29) -> 0 | N29: =VLOOKUP($F29,'MP & Eqpt Summary 1'!$D$3:$AB$81,19,0) -> 0 | O29: =N29-M29 -> 0 | P29: 0 | Q29: =P29-N29 -> 0
A30: PC | B30: =B29+1 -> 28 | C30: E | D30: Plate | E30: Day | F30: Plate Compactor | G30: =VLOOKUP(F30,'MP & Eqpt Summary 1'!$D$3:$E$61,2,0) -> 0 | H30: =VLOOKUP($F30,'MP & Eqpt Summary 1'!$D$3:$AB$81,14,0) -> 0 | M30: =SUM(H30:L30) -> 0 | N30: =VLOOKUP($F30,'MP & Eqpt Summary 1'!$D$3:$AB$81,19,0) -> 0 | O30: =N30-M30 -> 0 | P30: 0 | Q30: =P30-N30 -> 0
A31: VIB | B31: =B30+1 -> 29 | C31: E | D31: Vibrator | E31: Day | F31: Vibrator | G31: =VLOOKUP(F31,'MP & Eqpt Summary 1'!$D$3:$E$61,2,0) -> 0 | H31: =VLOOKUP($F31,'MP & Eqpt Summary 1'!$D$3:$AB$81,14,0) -> 0 | M31: =SUM(H31:L31) -> 0 | N31: =VLOOKUP($F31,'MP & Eqpt Summary 1'!$D$3:$AB$81,19,0) -> 0 | O31: =N31-M31 -> 0 | P31: 0 | Q31: =P31-N31 -> 0
A32: PEDR | B32: =B31+1 -> 30 | C32: E | D32: Roller Ped | E32: Day | F32: Pedestrian Roller | G32: =VLOOKUP(F32,'MP & Eqpt Summary 1'!$D$3:$E$61,2,0) -> 0 | H32: =VLOOKUP($F32,'MP & Eqpt Summary 1'!$D$3:$AB$81,14,0) -> 0 | M32: =SUM(H32:L32) -> 0 | N32: =VLOOKUP($F32,'MP & Eqpt Summary 1'!$D$3:$AB$81,19,0) -> 0 | O32: =N32-M32 -> 0 | P32: 0 | Q32: =P32-N32 -> 0
A33: BBM | B33: =B32+1 -> 31 | C33: E | D33: Bar Bend | E33: Day | F33: Bar Bending Machine | G33: =VLOOKUP(F33,'MP & Eqpt Summary 1'!$D$3:$E$61,2,0) -> 0 | H33: =VLOOKUP($F33,'MP & Eqpt Summary 1'!$D$3:$AB$81,14,0) -> 0 | M33: =SUM(H33:L33) -> 0 | N33: =VLOOKUP($F33,'MP & Eqpt Summary 1'!$D$3:$AB$81,19,0) -> 0 | O33: =N33-M33 -> 0 | P33: 0 | Q33: =P33-N33 -> 0
A34: BCM | B34: =B33+1 -> 32 | C34: E | D34: Bar Cut | E34: Day | F34: Bar Cutting Machine | G34: =VLOOKUP(F34,'MP & Eqpt Summary 1'!$D$3:$E$61,2,0) -> 0 | H34: =VLOOKUP($F34,'MP & Eqpt Summary 1'!$D$3:$AB$81,14,0) -> 0 | M34: =SUM(H34:L34) -> 0 | N34: =VLOOKUP($F34,'MP & Eqpt Summary 1'!$D$3:$AB$81,19,0) -> 0 | O34: =N34-M34 -> 0 | P34: 0 | Q34: =P34-N34 -> 0
A35: DUMP | B35: =B34+1 -> 33 | C35: E | D35: Dum | E35: Day | F35: Dumper | G35: =VLOOKUP(F35,'MP & Eqpt Summary 1'!$D$3:$E$61,2,0) -> 0 | H35: =VLOOKUP($F35,'MP & Eqpt Summary 1'!$D$3:$AB$81,14,0) -> 0 | M35: =SUM(H35:L35) -> 0 | N35: =VLOOKUP($F35,'MP & Eqpt Summary 1'!$D$3:$AB$81,19,0) -> 0 | O35: =N35-M35 -> 0 | P35: 0 | Q35: =P35-N35 -> 0
A36: PTL | B36: =B35+1 -> 34 | C36: E | D36: Tower Light | E36: Day | F36: Tower Light | G36: =VLOOKUP(F36,'MP & Eqpt Summary 1'!$D$3:$E$61,2,0) -> 0 | H36: =VLOOKUP($F36,'MP & Eqpt Summary 1'!$D$3:$AB$81,14,0) -> 0 | M36: =SUM(H36:L36) -> 0 | N36: =VLOOKUP($F36,'MP & Eqpt Summary 1'!$D$3:$AB$81,19,0) -> 0 | O36: =N36-M36 -> 0 | P36: 0 | Q36: =P36-N36 -> 0
... A40: MIXM | B40: =B39+1 -> 38 | C40: E | D40: Batch | E40: Day | F40: Weigh Batcher | G40: =VLOOKUP(F40,'MP & Eqpt Summary 1'!$D$3:$E$61,2,0) -> 0 | H40: =VLOOKUP($F40,'MP & Eqpt Summary 1'!$D$3:$AB$81,14,0) -> 0 | M40: =SUM(H40:L40) -> 0 | N40: =VLOOKUP($F40,'MP & Eqpt Summary 1'!$D$3:$AB$81,19,0) -> 0 | O40: =N40-M40 -> 0 | P40: 0 | Q40: =P40-N40 -> 0
A41: PG80 | B41: =B40+1 -> 39 | F41: Generator 1000 kva | G41: =VLOOKUP(F41,'MP & Eqpt Summary 1'!$D$3:$E$61,2,0) -> 0 | H41: =VLOOKUP($F41,'MP & Eqpt Summary 1'!$D$3:$AB$81,14,0) -> 0 | M41: =SUM(H41:L41) -> 0 | N41: =VLOOKUP($F41,'MP & Eqpt Summary 1'!$D$3:$AB$81,19,0) -> 0 | O41: =N41-M41 -> 0 | P41: #N/A | Q41: =P41-N41 -> #N/A
A42: PG50 | B42: =B41+1 -> 40 | F42: Generator upto 30 kva | G42: =VLOOKUP(F42,'MP & Eqpt Summary 1'!$D$3:$E$61,2,0) -> 0 | H42: =VLOOKUP($F42,'MP & Eqpt Summary 1'!$D$3:$AB$81,14,0) -> 0 | M42: =SUM(H42:L42) -> 0 | N42: =VLOOKUP($F42,'MP & Eqpt Summary 1'!$D$3:$AB$81,19,0) -> 0 | O42: =N42-M42 -> 0 | P42: #N/A | Q42: =P42-N42 -> #N/A
B43: =B42+1 -> 41 | F43: Generator upto 50 to 100 kva | G43: =VLOOKUP(F43,'MP & Eqpt Summary 1'!$D$3:$E$61,2,0) -> 0 | H43: =VLOOKUP($F43,'MP & Eqpt Summary 1'!$D$3:$AB$81,14,0) -> 0 | M43: =SUM(H43:L43) -> 0 | N43: =VLOOKUP($F43,'MP & Eqpt Summary 1'!$D$3:$AB$81,19,0) -> 0 | O43: =N43-M43 -> 0
...

Sheet Sheet2
N1: As on | O1: ='Summary-Financial'!AB2 -> xxxx
N2: Time Elapsed | O2: 1
N3: Progress Achieved | O3: 0.9670153 | S3: 38.19
A4: 6155_Dualization of Barka Nakhal Road Project | N4: Shortfall | O4: =O3-O2 -> -0.032984705
A5: Cumulative | R5: As on Date (Planned) % | S5: Diff
A6: Sl No | B6: PM/CM | C6: As on Date Planned amount | D6: As on Date Planned prelims | E6: As on Date Planned Total | F6: Achieved Amount to date | G6: Prelims Income | H6: Achieved Amount to date (Incl Prelims) | I6: % Achieved | J6: Cost | K6: Prelims Cost | L6: Cost to date including prelims | M6: % of Cost | N6: Contribution | O6: Contribution % | P6: Indicate | Q6: As on Date Planned Contribution
A7: 1 | B7: T Swamy | C7: =C9+C11+C12+C13+C14+C16+C8+C15 -> 296173.75 | D7: =$F$31*M7 -> #REF! | E7: =C7+D7 -> #REF! | F7: =F9+F10+F11+F12+F16+F8+F15 -> #REF! | G7: =$F$31*M7 -> #REF! | H7: =H9+H10+H11+H12+H16+H8+H15 -> #REF! | I7: =H7/E7 -> #REF! | J7: =J9+J10+J11+J12+J16+J8+J15 -> #REF! | K7: =K9+K10+K11+K12+K16+K8+K15 -> #REF! | L7: =SUM(J7:K7) -> #REF! | M7: =J7/$J$30 -> #REF! | N7: =IFERROR(H7-L7,"") | O7: =IFERROR(N7/H7,"") | P7: =IF(N7>=1,"Profit","Loss") -> Profit | R7: =-4.15%/26*23 -> -0.036711538 | S7: =O7-R7 -> #VALUE!
A8: a | B8: Prelims Others | C8: 58423.962 | D8: =$F$31*M8 -> #REF! | E8: =C8+D8 -> #REF! | F8: =#REF! -> #REF! | G8: =$F$31*M8 -> #REF! | H8: =SUM(F8:G8) -> #REF! | I8: =H8/E8 -> #REF! | J8: =#REF! -> #REF! | K8: =$J$31*M8 -> #REF! | L8: =SUM(J8:K8) -> #REF! | M8: =J8/$J$30 -> #REF! | N8: =IFERROR(H8-L8,"") | O8: =IFERROR(N8/H8,"") | P8: =IF(N8>=1,"Profit","Loss") -> Profit | S8: =O8-R8 -> #VALUE!
A9: b | B9: Manoj | C9: 180252.24 | D9: =$F$31*M9 -> #REF! | E9: =C9+D9 -> #REF! | F9: =#REF!+F14+F13 -> #REF! | G9: =$F$31*M9 -> #REF! | H9: =SUM(F9:G9) -> #REF! | I9: =H9/E9 -> #REF! | J9: =#REF!+J14+J13-5500 -> #REF! | K9: =$J$31*M9 -> #REF! | L9: =SUM(J9:K9) -> #REF! | M9: =J9/$J$30 -> #REF! | N9: =IFERROR(H9-L9,"") | O9: =IFERROR(N9/H9,"") | P9: =IF(N9>=1,"Profit","Loss") -> Profit | Q9: =(15992/27*20)+(3834/27*20)+(28854/27*20)+Q14+(Q13*0.1) -> -14348.444 | R9: =-3%/26*23 -> -0.026538462 | S9: =O9-R9 -> #VALUE!
A10: c | B10: Nassar/Essa | C10: 0 | D10: =$F$31*M10 -> #REF! | E10: =C10+D10 -> #REF! | F10: ='Summary-Financial'!F10 -> 0 | G10: =$F$31*M10 -> #REF! | H10: =SUM(F10:G10) -> #REF! | I10: =H10/E10 -> #REF! | J10: ='Summary-Financial'!I10 -> #REF! | K10: =$J$31*M10 -> #REF! | L10: =SUM(J10:K10) -> #REF! | M10: =J10/$J$30 -> #REF! | N10: =IFERROR(H10-L10,"") | O10: =IFERROR(N10/H10,"") | P10: =IF(N10>=1,"Profit","Loss") -> Profit
A11: d | B11: Liju | C11: 14297.5 | D11: =$F$31*M11 -> #REF! | E11: =C11+D11 -> #REF! | F11: =#REF! -> #REF! | G11: =$F$31*M11 -> #REF! | H11: =SUM(F11:G11) -> #REF! | I11: =H11/E11 -> #REF! | J11: =#REF! -> #REF! | K11: =$J$31*M11 -> #REF! | L11: =SUM(J11:K11) -> #REF! | M11: =J11/$J$30 -> #REF! | N11: =IFERROR(H11-L11,"") | O11: =IFERROR(N11/H11,"") | P11: =IF(N11>=1,"Profit","Loss") -> Profit | Q11: =618/27*20 -> 457.77778 | R11: =8%/26*23 -> 0.070769231 | S11: =O11-R11 -> #VALUE!
A12: e | B12: Anish | C12: 37809.115 | D12: =$F$31*M12 -> #REF! | E12: =C12+D12 -> #REF! | F12: =#REF! -> #REF! | G12: =$F$31*M12 -> #REF! | H12: =SUM(F12:G12) -> #REF! | I12: =H12/E12 -> #REF! | J12: =#REF! -> #REF! | K12: =$J$31*M12 -> #REF! | L12: =SUM(J12:K12) -> #REF! | M12: =J12/$J$30 -> #REF! | N12: =IFERROR(H12-L12,"") | O12: =IFERROR(N12/H12,"") | P12: =IF(N12>=1,"Profit","Loss") -> Profit | Q12: =14459/27*20 -> 10710.37 | R12: =30%/26*23 -> 0.26538462 | S12: =O12-R12 -> #VALUE!
A13: f | B13: Reji/Kishor | D13: =$F$31*M13 -> #REF! | E13: =C13+D13 -> #REF! | F13: =#REF! -> #REF! | G13: =$F$31*M13 -> #REF! | H13: =SUM(F13:G13) -> #REF! | J13: =#REF! -> #REF! | K13: =$J$31*M13 -> #REF! | L13: =SUM(J13:K13) -> #REF! | M13: =J13/$J$30 -> #REF! | N13: =IFERROR(H13-L13,"") | O13: =IFERROR(N13/H13,"") | P13: =IF(N13>=1,"Profit","Loss") -> Profit | Q13: =-61864/27*20 -> -45825.185 | S13: =O13-R13 -> #VALUE!
A14: g | B14: Mustafiz/Krishna | D14: =$F$31*M14 -> #REF! | E14: =C14+D14 -> #REF! | F14: =#REF! -> #REF! | G14: =$F$31*M14 -> #REF! | H14: =SUM(F14:G14) -> #REF! | J14: =#REF!+10000 -> #REF! | K14: =$J$31*M14 -> #REF! | L14: =SUM(J14:K14) -> #REF! | M14: =J14/$J$30 -> #REF! | N14: =IFERROR(H14-L14,"") | O14: =IFERROR(N14/H14,"") | P14: =IF(N14>=1,"Profit","Loss") -> Profit | Q14: =-61864/27*20 -> -45825.185 | S14: =O14-R14 -> #VALUE!
A15: h | B15: Static Crusher | D15: =$F$31*M15 -> #REF! | E15: =C15+D15 -> #REF! | F15: ='Summary-Financial'!F15 -> #REF! | G15: =$F$31*M15 -> #REF! | H15: =SUM(F15:G15) -> #REF! | I15: =H15/E15 -> #REF! | J15: =#REF! -> #REF! | K15: =$J$31*M15 -> #REF! | L15: =SUM(J15:K15) -> #REF! | M15: =J15/$J$30 -> #REF! | N15: =IFERROR(H15-L15,"") | O15: =IFERROR(N15/H15,"") | P15: =IF(N15>=1,"Profit","Loss") -> Profit | S15: =O15-R15 -> #VALUE!
A16: i | B16: Saiful Islam | C16: 5390.9308 | D16: =$F$31*M16 -> #REF! | E16: =C16+D16 -> #REF! | F16: =#REF! -> #REF! | G16: =$F$31*M16 -> #REF! | H16: =SUM(F16:G16) -> #REF! | I16: =H16/E16 -> #REF! | J16: =#REF! -> #REF! | K16: =$J$31*M16 -> #REF! | L16: =SUM(J16:K16) -> #REF! | M16: =J16/$J$30 -> #REF! | N16: =IFERROR(H16-L16,"") | O16: =IFERROR(N16/H16,"") | P16: =IF(N16>=1,"Profit","Loss") -> Profit | Q16: =5543/27*20 -> 4105.9259 | R16: 0 | S16: =O16-R16 -> #VALUE!
A17: 2 | B17: A K Singh | C17: =C18+C19+C20+C21+C22 -> 187836.08 | D17: =$F$31*M17 -> #REF! | E17: =C17+D17 -> #REF! | F17: =F18+F19+F20+F21+F22 -> #REF! | G17: =G18+G19+G20+G21+G22 -> #REF! | H17: =SUM(F17:G17) -> #REF! | I17: =H17/E17 -> #REF! | J17: =J18+J19+J20+J21+J22 -> #REF! | K17: =$J$31*M17 -> #REF! | L17: =SUM(J17:K17) -> #REF! | M17: =J17/$J$30 -> #REF! | N17: =IFERROR(H17-L17,"") | O17: =IFERROR(N17/H17,"") | P17: =IF(N17>=1,"Profit","Loss") -> Profit | R17: =8.14%/26*23 -> 0.072007692 | S17: =O17-R17 -> #VALUE!
A18: a | B18: Paul | C18: 52902.233 | D18: =$F$31*M18 -> #REF! | E18: =C18+D18 -> #REF! | F18: =#REF! -> #REF! | G18: =$F$31*M18 -> #REF! | H18: =SUM(F18:G18) -> #REF! | I18: =H18/E18 -> #REF! | J18: =#REF! -> #REF! | K18: =$J$31*M18 -> #REF! | L18: =SUM(J18:K18) -> #REF! | M18: =J18/$J$30 -> #REF! | N18: =IFERROR(H18-L18,"") | O18: =IFERROR(N18/H18,"") | P18: =IF(N18>=1,"Profit","Loss") -> Profit | Q18: =36214/27*20 -> 26825.185 | R18: =11%/26*23 -> 0.097307692 | S18: =O18-R18 -> #VALUE!
A19: b | B19: Santhosh | C19: 0 | D19: =$F$31*M19 -> #REF! | E19: =C19+D19 -> #REF! | F19: =#REF! -> #REF! | G19: =$F$31*M19 -> #REF! | H19: =SUM(F19:G19) -> #REF! | I19: =H19/E19 -> #REF! | J19: =#REF! -> #REF! | K19: =$J$31*M19 -> #REF! | L19: =SUM(J19:K19) -> #REF! | M19: =J19/$J$30 -> #REF! | N19: =IFERROR(H19-L19,"") | O19: =IFERROR(N19/H19,"") | P19: =IF(N19>=1,"Profit","Loss") -> Profit | Q19: =6836/27*20 -> 5063.7037 | R19: =5%/26*10 -> 0.019230769 | S19: =O19-R19 -> #VALUE!
A20: c | B20: Waqas | C20: 30701.445 | D20: =$F$31*M20 -> #REF! | E20: =C20+D20 -> #REF! | F20: =#REF! -> #REF! | G20: =$F$31*M20 -> #REF! | H20: =SUM(F20:G20) -> #REF! | I20: =H20/E20 -> #REF! | J20: =#REF! -> #REF! | K20: =$J$31*M20 -> #REF! | L20: =SUM(J20:K20) -> #REF! | M20: =J20/$J$30 -> #REF! | N20: =IFERROR(H20-L20,"") | O20: =IFERROR(N20/H20,"") | P20: =IF(N20>=1,"Profit","Loss") -> Profit | Q20: =8633/27*20 -> 6394.8148 | R20: =5%/26*23 -> 0.044230769 | S20: =O20-R20 -> #VALUE!
A21: d | B21: Joynal | C21: 71310.583 | D21: =$F$31*M21 -> #REF! | E21: =C21+D21 -> #REF! | F21: =#REF! -> #REF! | G21: =$F$31*M21 -> #REF! | H21: =SUM(F21:G21) -> #REF! | I21: =H21/E21 -> #REF! | J21: =#REF!+10000 -> #REF! | K21: =$J$31*M21 -> #REF! | L21: =SUM(J21:K21) -> #REF! | M21: =J21/$J$30 -> #REF! | N21: =IFERROR(H21-L21,"") | O21: =IFERROR(N21/H21,"") | P21: =IF(N21>=1,"Profit","Loss") -> Profit | Q21: =9971/27*20 -> 7385.9259 | R21: =8%/26*23 -> 0.070769231 | S21: =O21-R21 -> #VALUE!
A22: e | B22: Baskar | C22: 32921.824 | D22: =$F$31*M22 -> #REF! | E22: =C22+D22 -> #REF! | F22: =#REF! -> #REF! | G22: =$F$31*M22 -> #REF! | H22: =SUM(F22:G22) -> #REF! | I22: =H22/E22 -> #REF! | J22: =#REF!+5000 -> #REF! | K22: =$J$31*M22 -> #REF! | L22: =SUM(J22:K22) -> #REF! | M22: =J22/$J$30 -> #REF! | N22: =IFERROR(H22-L22,"") | O22: =IFERROR(N22/H22,"") | P22: =IF(N22>=1,"Profit","Loss") -> Profit | Q22: =11498/27*20 -> 8517.037 | R22: =11%/26*23 -> 0.097307692 | S22: =O22-R22 -> #VALUE!
A23: =A17+1 -> 3 | B23: A Nagarajan | C23: =C28+C25 -> 31886.022 | D23: =D25+D27+D28 -> #REF! | E23: =C23+D23 -> #REF! | F23: =F25+F27+F28 -> #REF! | G23: =$F$31*M23 -> #REF! | H23: =SUM(F23:G23) -> #REF! | I23: =H23/E23 -> #REF! | J23: =J28+J25+J27 -> #REF! | K23: =$J$31*M23 -> #REF! | L23: =SUM(J23:K23) -> #REF! | M23: =J23/$J$30 -> #REF! | N23: =IFERROR(H23-L23,"") | O23: =IFERROR(N23/H23,"") | P23: =IF(N23>=1,"Profit","Loss") -> Profit | R23: =2%/26*23 -> 0.017692308 | S23: =O23-R23 -> #VALUE!
A24: a | B24: Jithendra | C24: 22712.885 | D24: =$F$31*M24 -> #REF! | E24: =C24+D24 -> #REF! | F24: =#REF! -> #REF! | G24: =$F$31*M24 -> #REF! | H24: =SUM(F24:G24) -> #REF! | I24: =H24/E24 -> #REF! | J24: =#REF! -> #REF! | K24: =$J$31*M24 -> #REF! | L24: =SUM(J24:K24) -> #REF! | M24: =J24/$J$30 -> #REF! | N24: =IFERROR(H24-L24,"") | O24: =IFERROR(N24/H24,"") | P24: =IF(N24>=1,"Profit","Loss") -> Profit | Q24: =21590/27*20 -> 15992.593 | R24: =23%/26*16 -> 0.14153846 | S24: =O24-R24 -> #VALUE!
A25: b | B25: Mukesh Chabra | C25: 9173.1369 | D25: =$F$31*M25 -> #REF! | E25: =C25+D25 -> #REF! | F25: ='Summary-Financial'!F25 -> #REF! | G25: =$F$31*M25 -> #REF! | H25: =SUM(F25:G25) -> #REF! | I25: =H25/E25 -> #REF! | J25: ='Summary-Financial'!I25 -> #REF! | K25: =$J$31*M25 -> #REF! | L25: =SUM(J25:K25) -> #REF! | M25: =J25/$J$30 -> #REF! | N25: =IFERROR(H25-L25,"") | O25: =IFERROR(N25/H25,"") | P25: =IF(N25>=1,"Profit","Loss") -> Profit | R25: =38%/26*23 -> 0.33615385 | S25: =O25-R25 -> #VALUE!
A26: c | B26: Nassar/Essa | C26: 0 | D26: =$F$31*M26 -> #REF! | E26: =C26+D26 -> #REF! | F26: ='Summary-Financial'!F26 -> #REF! | G26: =$F$31*M26 -> #REF! | H26: =SUM(F26:G26) -> #REF! | I26: =H26/E26 -> #REF! | J26: ='Summary-Financial'!I26 -> #REF! | K26: =$J$31*M26 -> #REF! | L26: =SUM(J26:K26) -> #REF! | M26: =J26/$J$30 -> #REF! | N26: =IFERROR(H26-L26,"") | O26: =IFERROR(N26/H26,"") | P26: =IF(N26>=1,"Profit","Loss") -> Profit
A27: d | B27: Jayan | C27: 159189.14 | D27: =$F$31*M27+D26 -> #REF! | E27: =C27+D27 -> #REF! | F27: ='Summary-Financial'!F27+F26 -> #REF! | G27: =$F$31*M27 -> #REF! | H27: =SUM(F27:G27) -> #REF! | I27: =H27/E27 -> #REF! | J27: ='Summary-Financial'!I27+J26 -> #REF! | K27: =$J$31*M27 -> #REF! | L27: =SUM(J27:K27) -> #REF! | M27: =J27/$J$30 -> #REF! | N27: =IFERROR(H27-L27,"") | O27: =IFERROR(N27/H27,"") | P27: =IF(N27>=1,"Profit","Loss") -> Profit
A28: e | B28: Mohan | C28: =0+C24 -> 22712.885 | D28: =$F$31*M28+D24 -> #REF! | E28: =C28+D28 -> #REF! | F28: =#REF!+F24 -> #REF! | G28: =$F$31*M28 -> #REF! | H28: =SUM(F28:G28) -> #REF! | I28: =H28/E28 -> #REF! | J28: =#REF!+J24 -> #REF! | K28: =$J$31*M28 -> #REF! | L28: =SUM(J28:K28) -> #REF! | M28: =J28/$J$30 -> #REF! | N28: =IFERROR(H28-L28,"") | O28: =IFERROR(N28/H28,"") | P28: =IF(N28>=1,"Profit","Loss") -> Profit | Q28: =-134/27*20 -> -99.259259 | R28: =-2%/26*23 -> -0.017692308 | S28: =O28-R28 -> #VALUE!
S29: 0
A30: Total | C30: =C23+C17+C7+C15 -> 515895.86 | F30: =F23+F17+F7 -> #REF! | G30: =G23+G17+G7 -> #REF! | H30: =H23+H17+H7 -> #REF! | J30: =J23+J17+J7 -> #REF! | K30: =K23+K17+K7 -> #REF! | L30: =L23+L17+L7 -> #REF! | M30: =J30/$J$30 -> #REF! | N30: =H30-L30 -> #REF! | O30: =IFERROR(N30/SUM(H30),0) -> 0 | P30: =IF(N30>=1,"Profit","Loss") -> #REF! | S30: =O30-R30 -> 0
A31: 1 | B31: Prelims | C31: =F31 -> 0 | F31: =PRE!I74 -> 0 | J31: =PRE!I75 -> 0 | N31: =F31-J31 -> 0 | O31: =IFERROR(N31/F31,0) -> 0 | P31: =IF(N31>=1,"Profit","Loss") -> Loss | Q31: =-61361/27*20 -> -45452.593 | R31: 0
A33: Sub Contractor
A34: 1 | B34: Sub contractor | C34: 120486.41 | F34: =DPR!N205+DPR!N206 -> 0 | H34: =F34 -> 0 | J34: =#REF!+#REF!+#REF!+#REF! -> #REF! | L34: =J34 -> #REF! | N34: =F34-L34 -> #REF! | O34: =IFERROR(N34/H34,0) -> 0 | P34: =IF(N34>=1,"Profit","Loss") -> #REF! | Q34: =23416/27*20 -> 17345.185 | R34: 0 | S34: =O34-R34 -> 0
A35: 2 | B35: PCT | C35: =DPR!H208+DPR!H209+DPR!H210 -> 0 | F35: =DPR!N208+DPR!#REF! -> #REF! | H35: =F35 -> #REF! | J35: =#REF!+#REF! -> #REF! | L35: =J35 -> #REF! | N35: =F35-L35 -> #REF! | O35: =IFERROR(N35/H35,0) -> 0 | P35: =IF(N35>=1,"Profit","Loss") -> #REF! | S35: =O35-R35 -> 0
A36: 3 | B36: Bahwan | C36: 0 | F36: =DPR!N207 -> 0 | H36: =F36 -> 0 | J36: =#REF! -> #REF! | L36: =J36 -> #REF! | N36: =F36-L36 -> #REF! | O36: =IFERROR(N36/F36,0) -> 0 | P36: =IF(N36>=1,"Profit","Loss") -> #REF! | S36: =O36-R36 -> 0
A38: Grand Total | C38: =C30+C31+C34 -> 636382.27 | F38: =F30+F31+F34+F36 -> #REF! | H38: =H30+H31+H34+H36 -> #REF! | J38: =J30+J31+J34+J36 -> #REF! | L38: =L30+L31+L34+L36 -> #REF! | N38: =H38-L38 -> #REF! | O38: =IFERROR(N38/H38,0) -> 0 | P38: =IF(N38>=1,"Profit","Loss") -> #REF! | Q38: =Q34+Q31+Q28+Q24+Q22+Q21+Q20+Q19+Q18+Q16+Q12+Q11+Q10+Q9 -> 42898.222 | R38: =2.5%/26*23 -> 0.022115385 | S38: =O38-R38 -> -0.022115385
F41: =F38-F15 -> #REF!
F43: 1616216.6

Sheet Summary-Financial
AC1: 42767 | AF1: Fuel taken | AG1: ='Summary-Financial (NEW)'!AH1 -> 0.4911
AA2: As on | AB2: ='Summary-Financial (NEW)'!AC2 -> xxxx | AC2: =EOMONTH(AB2,0) -> #VALUE! | AD2: 26 | AE2: 26
AA3: Time Elapsed | AB3: =AD2/AE2 -> 1
C4: 6155_Dualization of Barka Nakhal Road Project
C5: Cumulative | R5: For the Day
C6: Sl No | D6: PM/CM | E6: Projection Amount | F6: Achieved Amount to date | G6: Prelims Income | H6: Achieved Amount to date (Incl Prelims) | I6: Cost | J6: Prelims Cost | K6: Cost to date including prelims | L6: % of Cost | M6: % of Income | N6: Contribution | O6: Contribution % | P6: Indicate | R6: Achieved Amount to date | S6: Prelims Income | T6: Bahwan Income | U6: Achieved Amount to date (Incl Prelims) | V6: Cost | W6: Prelims Cost | X6: Cost to date including prelims | Y6: % of Cost | Z6: Contribution | AA6: Contribution % | AB6: Indicate
C7: 1 | D7: T Swamy | E7: =E9+E11+E12+E16+E8 -> #REF! | F7: =F9+F11+F12+F16+F8 -> #REF! | G7: =$F$31*L7 -> #REF! | H7: =H9+H10+H11+H12+H16+H8+H15 -> #REF! | I7: =I9+I10+I11+I12+I16+I8+I15 -> #REF! | J7: =J9+J10+J11+J12+J16+J8+J15 -> #REF! | K7: =SUM(I7:J7) -> #REF! | L7: =I7/$I$30 -> #REF! | M7: =H7/$H$30 -> #REF! | N7: =IFERROR(H7-K7,"") | O7: =IFERROR(N7/H7,"") | P7: =IF(N7>=1,"Profit","Loss") -> Profit | R7: =R9+R10+R11+R12+R16+R8+R15 -> #REF! | S7: =$R$31*Y7 -> #REF! | U7: =SUM(R7:S7) -> #REF! | V7: =V9+V10+V11+V12+V16+V8+V15 -> #REF! | W7: =$V$31*Y7 -> #REF! | X7: =SUM(V7:W7) -> #REF! | Y7: =V7/$V$30 -> #REF! | Z7: =IFERROR(U7-X7,"") | AA7: =IFERROR(Z7/U7,"") | AB7: =IF(Z7>=1,"Profit","Loss") -> Profit | AC7: =F7+H7 -> #REF!
C8: a | D8: Prelims Others | E8: =#REF! -> #REF! | F8: =#REF! -> #REF! | G8: =$F$31*L8 -> #REF! | H8: =SUM(F8:G8) -> #REF! | I8: =#REF! -> #REF! | J8: =$I$31*L8 -> #REF! | K8: =SUM(I8:J8) -> #REF! | L8: =I8/$I$30 -> #REF! | N8: =IFERROR(H8-K8,"") | O8: =IFERROR(N8/H8,"") | P8: =IF(N8>=1,"Profit","Loss") -> Profit | R8: =#REF! -> #REF! | S8: =$R$31*Y8 -> #REF! | U8: =SUM(R8:S8) -> #REF! | V8: =#REF! -> #REF! | W8: =$V$31*Y8 -> #REF! | X8: =SUM(V8:W8) -> #REF! | Y8: =V8/$V$30 -> #REF! | Z8: =IFERROR(U8-X8,"") | AA8: =IFERROR(Z8/U8,"") | AB8: =IF(Z8>=1,"Profit","Loss") -> Profit
C9: b | D9: Manoj | E9: 404132.66 | F9: =#REF!+F14+(F13*0.1) -> #REF! | G9: =$F$31*L9 -> #REF! | H9: =SUM(F9:G9) -> #REF! | I9: =#REF!+I14+(I13*0.1) -> #REF! | J9: =$I$31*L9-3000 -> #REF! | K9: =SUM(I9:J9) -> #REF! | L9: =I9/$I$30 -> #REF! | N9: =IFERROR(H9-K9,"") | O9: =IFERROR(N9/H9,"") | P9: =IF(N9>=1,"Profit","Loss") -> Profit | R9: =#REF!+R14+(R13*0.1) -> #REF! | S9: =$R$31*Y9 -> #REF! | U9: =SUM(R9:S9) -> #REF! | V9: =#REF!+V14+(V13*0.1) -> #REF! | W9: =$V$31*Y9 -> #REF! | X9: =SUM(V9:W9) -> #REF! | Y9: =V9/$V$30 -> #REF! | Z9: =IFERROR(U9-X9,"") | AA9: =IFERROR(Z9/U9,"") | AB9: =IF(Z9>=1,"Profit","Loss") -> Profit
C10: c | D10: Nassar/essa | E10: =#REF! -> #REF! | G10: =$F$31*L10 -> #REF! | I10: =#REF! -> #REF! | J10: =$I$31*L10 -> #REF! | K10: =SUM(I10:J10) -> #REF! | L10: =I10/$I$30 -> #REF! | N10: =IFERROR(H10-K10,"") | O10: =IFERROR(N10/H10,"") | P10: =IF(N10>=1,"Profit","Loss") -> Profit
C11: d | D11: Liju | E11: 13456.17 | F11: =#REF! -> #REF! | G11: =$F$31*L11 -> #REF! | H11: =SUM(F11:G11) -> #REF! | I11: =#REF! -> #REF! | J11: =$I$31*L11 -> #REF! | K11: =SUM(I11:J11) -> #REF! | L11: =I11/$I$30 -> #REF! | N11: =IFERROR(H11-K11,"") | O11: =IFERROR(N11/H11,"") | P11: =IF(N11>=1,"Profit","Loss") -> Profit | R11: =#REF! -> #REF! | S11: =$R$31*Y11 -> #REF! | U11: =SUM(R11:S11) -> #REF! | V11: =#REF! -> #REF! | W11: =$V$31*Y11 -> #REF! | X11: =SUM(V11:W11) -> #REF! | Y11: =V11/$V$30 -> #REF! | Z11: =IFERROR(U11-X11,"") | AA11: =IFERROR(Z11/U11,"") | AB11: =IF(Z11>=1,"Profit","Loss") -> Profit
C12: e | D12: Anish | E12: 89367 | F12: =#REF! -> #REF! | G12: =$F$31*L12 -> #REF! | H12: =SUM(F12:G12) -> #REF! | I12: =#REF! -> #REF! | J12: =$I$31*L12 -> #REF! | K12: =SUM(I12:J12) -> #REF! | L12: =I12/$I$30 -> #REF! | N12: =IFERROR(H12-K12,"") | O12: =IFERROR(N12/H12,"") | P12: =IF(N12>=1,"Profit","Loss") -> Profit | R12: =#REF! -> #REF! | S12: =$R$31*Y12 -> #REF! | U12: =SUM(R12:S12) -> #REF! | V12: =#REF! -> #REF! | W12: =$V$31*Y12 -> #REF! | X12: =SUM(V12:W12) -> #REF! | Y12: =V12/$V$30 -> #REF! | Z12: =IFERROR(U12-X12,"") | AA12: =IFERROR(Z12/U12,"") | AB12: =IF(Z12>=1,"Profit","Loss") -> Profit
C13: f | D13: Reji/Kishor | E13: - | F13: =#REF! -> #REF! | G13: =$F$31*L13 -> #REF! | H13: =SUM(F13:G13) -> #REF! | I13: =#REF! -> #REF! | J13: =$I$31*L13 -> #REF! | K13: =SUM(I13:J13) -> #REF! | L13: =I13/$I$30 -> #REF! | N13: =IFERROR(H13-K13,"") | O13: =IFERROR(N13/H13,"") | P13: =IF(N13>=1,"Profit","Loss") -> Profit | R13: =#REF! -> #REF! | S13: =$R$31*Y13 -> #REF! | U13: =SUM(R13:S13) -> #REF! | V13: =#REF! -> #REF! | W13: =$V$31*Y13 -> #REF! | X13: =SUM(V13:W13) -> #REF! | Y13: =V13/$V$30 -> #REF! | Z13: =IFERROR(U13-X13,"") | AA13: =IFERROR(Z13/U13,"") | AB13: =IF(Z13>=1,"Profit","Loss") -> Profit
C14: g | D14: Mustafiz/Krishna | E14: - | F14: =#REF! -> #REF! | G14: =$F$31*L14 -> #REF! | H14: =SUM(F14:G14) -> #REF! | I14: =#REF! -> #REF! | J14: =$I$31*L14 -> #REF! | K14: =SUM(I14:J14) -> #REF! | L14: =I14/$I$30 -> #REF! | N14: =IFERROR(H14-K14,"") | O14: =IFERROR(N14/H14,"") | P14: =IF(N14>=1,"Profit","Loss") -> Profit | R14: =#REF! -> #REF! | S14: =$R$31*Y14 -> #REF! | U14: =SUM(R14:S14) -> #REF! | V14: =#REF! -> #REF! | W14: =$V$31*Y14 -> #REF! | X14: =SUM(V14:W14) -> #REF! | Y14: =V14/$V$30 -> #REF! | Z14: =IFERROR(U14-X14,"") | AA14: =IFERROR(Z14/U14,"") | AB14: =IF(Z14>=1,"Profit","Loss") -> Profit
C15: h | D15: Static Crusher | F15: =#REF! -> #REF! | G15: =$F$31*L15 -> #REF! | H15: =SUM(F15:G15) -> #REF! | I15: =#REF! -> #REF! | J15: =$I$31*L15 -> #REF! | K15: =SUM(I15:J15) -> #REF! | L15: =I15/$I$30 -> #REF! | N15: =IFERROR(H15-K15,"") | O15: =IFERROR(N15/H15,"") | P15: =IF(N15>=1,"Profit","Loss") -> Profit | R15: =#REF! -> #REF! | S15: =$R$31*Y15 -> #REF! | U15: =SUM(R15:S15) -> #REF! | V15: =#REF! -> #REF! | W15: =$V$31*Y15 -> #REF! | X15: =SUM(V15:W15) -> #REF! | Y15: =V15/$V$30 -> #REF! | Z15: =IFERROR(U15-X15,"") | AA15: =IFERROR(Z15/U15,"") | AB15: =IF(Z15>=1,"Profit","Loss") -> Profit
C16: i | D16: Saiful Islam | E16: =#REF! -> #REF! | F16: =#REF! -> #REF! | G16: =$F$31*L16 -> #REF! | H16: =SUM(F16:G16) -> #REF! | I16: =#REF! -> #REF! | J16: =$I$31*L16 -> #REF! | K16: =SUM(I16:J16) -> #REF! | L16: =I16/$I$30 -> #REF! | N16: =IFERROR(H16-K16,"") | O16: =IFERROR(N16/H16,"") | P16: =IF(N16>=1,"Profit","Loss") -> Profit | R16: =#REF! -> #REF! | S16: =$R$31*Y16 -> #REF! | U16: =SUM(R16:S16) -> #REF! | V16: =#REF! -> #REF! | W16: =$V$31*Y16 -> #REF! | X16: =SUM(V16:W16) -> #REF! | Y16: =V16/$V$30 -> #REF! | Z16: =IFERROR(U16-X16,"") | AA16: =IFERROR(Z16/U16,"") | AB16: =IF(Z16>=1,"Profit","Loss") -> Profit
C17: 2 | D17: A K Singh | E17: =E18+E19+E20+E21+E22 -> #REF! | F17: =F18+F19+F20+F21+F22 -> #REF! | G17: =G18+G19+G20+G21+G22 -> #REF! | H17: =SUM(F17:G17) -> #REF! | I17: =I18+I19+I20+I21+I22 -> #REF! | J17: =$I$31*L17 -> #REF! | K17: =SUM(I17:J17) -> #REF! | L17: =I17/$I$30 -> #REF! | M17: =H17/$H$30 -> #REF! | N17: =IFERROR(H17-K17,"") | O17: =IFERROR(N17/H17,"") | P17: =IF(N17>=1,"Profit","Loss") -> Profit | R17: =R18+R19+R20+R21+R22 -> #REF! | S17: =$R$31*Y17 -> #REF! | U17: =SUM(R17:S17) -> #REF! | V17: =V18+V19+V20+V21+V22 -> #REF! | W17: =$V$31*Y17 -> #REF! | X17: =SUM(V17:W17) -> #REF! | Y17: =V17/$V$30 -> #REF! | Z17: =IFERROR(U17-X17,"") | AA17: =IFERROR(Z17/U17,"") | AB17: =IF(Z17>=1,"Profit","Loss") -> Profit | AC17: =F17+H17 -> #REF!
C18: a | D18: Paul | E18: 148678.01 | F18: =#REF! -> #REF! | G18: =$F$31*L18 -> #REF! | H18: =SUM(F18:G18) -> #REF! | I18: =#REF! -> #REF! | J18: =$I$31*L18 -> #REF! | K18: =SUM(I18:J18) -> #REF! | L18: =I18/$I$30 -> #REF! | N18: =IFERROR(H18-K18,"") | O18: =IFERROR(N18/H18,"") | P18: =IF(N18>=1,"Profit","Loss") -> Profit | R18: =#REF! -> #REF! | S18: =$R$31*Y18 -> #REF! | U18: =SUM(R18:S18) -> #REF! | V18: =#REF! -> #REF! | W18: =$V$31*Y18 -> #REF! | X18: =SUM(V18:W18) -> #REF! | Y18: =V18/$V$30 -> #REF! | Z18: =IFERROR(U18-X18,"") | AA18: =IFERROR(Z18/U18,"") | AB18: =IF(Z18>=1,"Profit","Loss") -> Profit
C19: b | D19: Santhosh | E19: =#REF! -> #REF! | F19: =#REF! -> #REF! | G19: =$F$31*L19 -> #REF! | H19: =SUM(F19:G19) -> #REF! | I19: =#REF! -> #REF! | J19: =$I$31*L19 -> #REF! | K19: =SUM(I19:J19) -> #REF! | L19: =I19/$I$30 -> #REF! | N19: =IFERROR(H19-K19,"") | O19: =IFERROR(N19/H19,"") | P19: =IF(N19>=1,"Profit","Loss") -> Profit | R19: =#REF! -> #REF! | S19: =$R$31*Y19 -> #REF! | U19: =SUM(R19:S19) -> #REF! | V19: =#REF! -> #REF! | W19: =$V$31*Y19 -> #REF! | X19: =SUM(V19:W19) -> #REF! | Y19: =V19/$V$30 -> #REF! | Z19: =IFERROR(U19-X19,"") | AA19: =IFERROR(Z19/U19,"") | AB19: =IF(Z19>=1,"Profit","Loss") -> Profit
C20: c | D20: Waqas | E20: 96203.415 | F20: =#REF! -> #REF! | G20: =$F$31*L20 -> #REF! | H20: =SUM(F20:G20) -> #REF! | I20: =#REF! -> #REF! | J20: =$I$31*L20 -> #REF! | K20: =SUM(I20:J20) -> #REF! | L20: =I20/$I$30 -> #REF! | N20: =IFERROR(H20-K20,"") | O20: =IFERROR(N20/H20,"") | P20: =IF(N20>=1,"Profit","Loss") -> Profit | R20: =#REF! -> #REF! | S20: =$R$31*Y20 -> #REF! | U20: =SUM(R20:S20) -> #REF! | V20: =#REF! -> #REF! | W20: =$V$31*Y20 -> #REF! | X20: =SUM(V20:W20) -> #REF! | Y20: =V20/$V$30 -> #REF! | Z20: =IFERROR(U20-X20,"") | AA20: =IFERROR(Z20/U20,"") | AB20: =IF(Z20>=1,"Profit","Loss") -> Profit
C21: d | D21: Joynal | E21: 103017.29 | F21: =#REF! -> #REF! | G21: =$F$31*L21 -> #REF! | H21: =SUM(F21:G21) -> #REF! | I21: =#REF! -> #REF! | J21: =$I$31*L21+1500 -> #REF! | K21: =SUM(I21:J21) -> #REF! | L21: =I21/$I$30 -> #REF! | N21: =IFERROR(H21-K21,"") | O21: =IFERROR(N21/H21,"") | P21: =IF(N21>=1,"Profit","Loss") -> Profit | R21: =#REF! -> #REF! | S21: =$R$31*Y21 -> #REF! | U21: =SUM(R21:S21) -> #REF! | V21: =#REF! -> #REF! | W21: =$V$31*Y21 -> #REF! | X21: =SUM(V21:W21) -> #REF! | Y21: =V21/$V$30 -> #REF! | Z21: =IFERROR(U21-X21,"") | AA21: =IFERROR(Z21/U21,"") | AB21: =IF(Z21>=1,"Profit","Loss") -> Profit
C22: e | D22: Baskar | E22: 77815.22 | F22: =#REF! -> #REF! | G22: =$F$31*L22 -> #REF! | H22: =SUM(F22:G22) -> #REF! | I22: =#REF!+3500 -> #REF! | J22: =$I$31*L22+1000 -> #REF! | K22: =SUM(I22:J22) -> #REF! | L22: =I22/$I$30 -> #REF! | N22: =IFERROR(H22-K22,"") | O22: =IFERROR(N22/H22,"") | P22: =IF(N22>=1,"Profit","Loss") -> Profit | R22: =#REF! -> #REF! | S22: =$R$31*Y22 -> #REF! | U22: =SUM(R22:S22) -> #REF! | V22: =#REF! -> #REF! | W22: =$V$31*Y22 -> #REF! | X22: =SUM(V22:W22) -> #REF! | Y22: =V22/$V$30 -> #REF! | Z22: =IFERROR(U22-X22,"") | AA22: =IFERROR(Z22/U22,"") | AB22: =IF(Z22>=1,"Profit","Loss") -> Profit
C23: =C17+1 -> 3 | D23: A Nagarajan | E23: =E24+E25+E27+E26+E28+E34+E36 -> #REF! | F23: =F24+F28+F25+F27+F34+F36+F26 -> #REF! | G23: =$F$31*L23 -> #REF! | H23: =SUM(F23:G23) -> #REF! | I23: =I24+I28+I25+I26 -> #REF! | J23: =$I$31*L23 -> #REF! | K23: =SUM(I23:J23) -> #REF! | L23: =I23/$I$30 -> #REF! | M23: =H23/$H$30 -> #REF! | N23: =IFERROR(H23-K23,"") | O23: =IFERROR(N23/H23,"") | P23: =IF(N23>=1,"Profit","Loss") -> Profit | R23: =R24+R28 -> #REF! | S23: =$R$31*Y23 -> #REF! | U23: =SUM(R23:S23) -> #REF! | V23: =V24+V28 -> #REF! | W23: =$V$31*Y23 -> #REF! | X23: =SUM(V23:W23) -> #REF! | Y23: =V23/$V$30 -> #REF! | Z23: =IFERROR(U23-X23,"") | AA23: =IFERROR(Z23/U23,"") | AB23: =IF(Z23>=1,"Profit","Loss") -> Profit | AC23: =F23+H23 -> #REF!
C24: a | D24: Jithender | E24: 53685 | F24: =#REF! -> #REF! | G24: =$F$31*L24 -> #REF! | H24: =SUM(F24:G24) -> #REF! | I24: =#REF!+5500 -> #REF! | J24: =$I$31*L24+7500 -> #REF! | K24: =SUM(I24:J24) -> #REF! | L24: =I24/$I$30 -> #REF! | M24: =H24/$H$30 -> #REF! | N24: =IFERROR(H24-K24,"") | O24: =IFERROR(N24/H24,"") | P24: =IF(N24>=1,"Profit","Loss") -> Profit | R24: =#REF! -> #REF! | S24: =$R$31*Y24 -> #REF! | U24: =SUM(R24:S24) -> #REF! | V24: =#REF! -> #REF! | W24: =$V$31*Y24 -> #REF! | X24: =SUM(V24:W24) -> #REF! | Y24: =V24/$V$30 -> #REF! | Z24: =IFERROR(U24-X24,"") | AA24: =IFERROR(Z24/U24,"") | AB24: =IF(Z24>=1,"Profit","Loss") -> Profit
C25: b | D25: Mukesh | E25: =#REF! -> #REF! | F25: =#REF! -> #REF! | G25: =$F$31*L25 -> #REF! | H25: =SUM(F25:G25) -> #REF! | I25: =#REF! -> #REF! | J25: =$I$31*L25 -> #REF! | K25: =SUM(I25:J25) -> #REF! | L25: =I25/$I$30 -> #REF! | N25: =IFERROR(H25-K25,"") | O25: =IFERROR(N25/H25,"") | P25: =IF(N25>=1,"Profit","Loss") -> Profit
C26: c | D26: Nassar/essa | E26: =#REF! -> #REF! | F26: =#REF! -> #REF! | G26: =$F$31*L26 -> #REF! | H26: =SUM(F26:G26) -> #REF! | I26: =#REF! -> #REF! | J26: =$I$31*L26 -> #REF! | K26: =SUM(I26:J26) -> #REF! | L26: =I26/$I$30 -> #REF! | N26: =IFERROR(H26-K26,"") | O26: =IFERROR(N26/H26,"")
C27: d | D27: Jayan | E27: 208870.46 | F27: =#REF! -> #REF! | G27: =$F$31*L27 -> #REF! | H27: =SUM(F27:G27) -> #REF! | I27: =#REF! -> #REF! | J27: =$I$31*L27-3500 -> #REF! | K27: =SUM(I27:J27) -> #REF! | L27: =I27/$I$30 -> #REF! | N27: =IFERROR(H27-K27,"") | O27: =IFERROR(N27/H27,"") | P27: =IF(N27>=1,"Profit","Loss") -> Profit | R27: =#REF!+(R30*0.9) -> #REF! | S27: =$R$31*Y27 -> #REF! | U27: =SUM(R27:S27) -> #REF! | V27: =#REF!+(V30*0.9) -> #REF! | W27: =$V$31*Y27 -> #REF! | X27: =SUM(V27:W27) -> #REF! | Y27: =V27/$V$30 -> #REF! | Z27: =IFERROR(U27-X27,"") | AA27: =IFERROR(Z27/U27,"") | AB27: =IF(Z27>=1,"Profit","Loss") -> Profit
C28: e | D28: Mohan | E28: =#REF! -> #REF! | F28: =#REF! -> #REF! | G28: =$F$31*L28 -> #REF! | H28: =SUM(F28:G28) -> #REF! | I28: =#REF!-5500 -> #REF! | J28: =$I$31*L28 -> #REF! | K28: =SUM(I28:J28) -> #REF! | L28: =I28/$I$30 -> #REF! | M28: =H28/$H$30 -> #REF! | N28: =IFERROR(H28-K28,"") | O28: =IFERROR(N28/H28,"") | P28: =IF(N28>=1,"Profit","Loss") -> Profit | R28: =#REF! -> #REF! | S28: =$R$31*Y28 -> #REF! | U28: =SUM(R28:S28) -> #REF! | V28: =#REF! -> #REF! | W28: =$V$31*Y28 -> #REF! | X28: =SUM(V28:W28) -> #REF! | Y28: =V28/$V$30 -> #REF! | Z28: =IFERROR(U28-X28,"") | AA28: =IFERROR(Z28/U28,"") | AB28: =IF(Z28>=1,"Profit","Loss") -> Profit
C30: Total | E30: =E23+E17+E7+E15+E31 -> #REF! | F30: =F23+F17+F7 -> #REF! | G30: =G23+G17+G7 -> #REF! | H30: =H23+H17+H7 -> #REF! | I30: =I23+I17+I7 -> #REF! | J30: =J23+J17+J7 -> #REF! | K30: =K23+K17+K7 -> #REF! | L30: =I30/$I$30 -> #REF! | M30: =F30/E30 -> #REF! | N30: =H30-K30 -> #REF! | O30: =IFERROR(N30/SUM(H30),0) -> 0 | P30: =IF(N30>=1,"Profit","Loss") -> #REF! | R30: =R23+R17+R7 -> #REF! | S30: =S23+S17+S7 -> #REF! | T30: =T23+T17+T7+T15 -> 0 | U30: =U23+U17+U7 -> #REF! | V30: =V23+V17+V7 -> #REF! | W30: =W23+W17+W7 -> #REF! | X30: =X23+X17+X7 -> #REF! | Y30: =V30/$V$30 -> #REF! | Z30: =U30-X30 -> #REF! | AA30: =Z30/U30 -> #REF! | AB30: =IF(Z30>=1,"Profit","Loss") -> #REF!
C31: 1 | D31: Prelims | E31: =DPR!H5 -> 0 | F31: =PRE!I74 -> 0 | I31: =PRE!I75 -> 0 | M31: =F31/E31 -> #DIV/0! | N31: =F31-I31 -> 0 | O31: =IFERROR(N31/F31,0) -> 0 | P31: =IF(N31>=1,"Profit","Loss") -> Loss | R31: =PRE!K74 -> 0 | V31: =PRE!K75 -> #REF! | Z31: =R31-V31 -> #REF! | AA31: =Z31/R31 -> #REF! | AB31: =IF(Z31>=1,"Profit","Loss") -> #REF!
C33: Sub Contractor
C34: 1 | D34: Grand Enterprizes | E34: =DPR!H205+DPR!H206 -> 0 | F34: =DPR!N205+DPR!N206 -> 0 | H34: =F34 -> 0 | I34: =#REF!+#REF!+#REF!+#REF! -> #REF! | K34: =I34 -> #REF! | M34: =F34/E34 -> #DIV/0! | N34: =F34-K34 -> #REF! | O34: =IFERROR(N34/H34,0) -> 0 | P34: =IF(N34>=1,"Profit","Loss") -> #REF! | R34: 0 | V34: 0 | Z34: =R34-U34 -> 0 | AA34: =R34-V34 -> 0
C35: 2 | D35: PCT | E35: =DPR!H208+DPR!H209+DPR!H210 -> 0 | F35: =DPR!N208+DPR!#REF! -> #REF! | H35: =F35 -> #REF! | I35: =#REF!+#REF! -> #REF! | K35: =I35 -> #REF! | N35: =F35-K35 -> #REF! | O35: =IFERROR(N35/H35,0) -> 0 | P35: =IF(N35>=1,"Profit","Loss") -> #REF!
C36: 3 | D36: Bahwan | E36: =DPR!H207 -> 0 | F36: =DPR!N207+DPR!N206 -> 0 | H36: =F36 -> 0 | I36: =#REF! -> #REF! | K36: =I36 -> #REF! | N36: =F36-K36 -> #REF! | O36: =IFERROR(N36/F36,0) -> 0 | P36: =IF(N36>=1,"Profit","Loss") -> #REF!
C38: Grand Total | E38: =E30+E31+E34+E36+E35 -> #REF! | F38: =F30+F31+F34+F36+F35 -> #REF! | H38: =H30+H31+H34+H36+H35 -> #REF! | I38: =I30+I31+I34+I36+I35 -> #REF! | K38: =K30+K31+K34+K36+K35 -> #REF! | N38: =H38-K38 -> #REF! | O38: =IFERROR(N38/H38,0) -> 0 | P38: =IF(N38>=1,"Profit","Loss") -> #REF! | R38: =R31+R23+R17+R7 -> #REF! | S38: =S31+S23+S17+S7 -> #REF! | U38: =U30+U31+U34 -> #REF! | V38: =V30+V31+V34 -> #REF! | X38: =X30+X31+X34 -> #REF! | Z38: =U38-X38 -> #REF! | AA38: =Z38/U38 -> #REF! | AB38: =IF(Z38>=1,"Profit","Loss") -> #REF!
D41: Description | E41: Cum. Amount | H41: For the Day
D42: A.Man Power: | E42: =VLOOKUP(D42,#REF!,2,0)+VLOOKUP(D42,PRE!$B$71:$E$76,2,0)+VLOOKUP(D42,#REF!,2,0)+VLOOKUP(D42,#REF!,2,0)+VLOOKUP(D42,#REF!,2,0)+VLOOKUP(D42,#REF!,2,0)+VLOOKUP(D42,#REF!,2,0)+VLOOKUP(D42,#REF!,2,0)+VLOOKUP(D42,#REF!,2,0)+VLOOKUP(D42,#REF!,2,0)+VLOOKUP(D42,#REF!,2,0)+VLOOKUP(D42,#REF!,2,0)+VLOOKUP(D42,#REF!,2,0)+VLOOKUP(D42,#REF!,2,0)+VLOOKUP(D42,#REF!,2,0)+VLOOKUP(D42,#REF!,2,0)+#REF!+#REF! -> #REF! | F42: #REF! | H42: =VLOOKUP(D42,#REF!,4,0)+VLOOKUP(D42,PRE!B71:E76,4,0)+VLOOKUP(D42,#REF!,4,0)+VLOOKUP(D42,#REF!,4,0)+VLOOKUP(D42,#REF!,4,0)+VLOOKUP(D42,#REF!,4,0)+VLOOKUP(D42,#REF!,4,0)+VLOOKUP(D42,#REF!,4,0)+VLOOKUP(D42,#REF!,4,0)+VLOOKUP(D42,#REF!,4,0)+VLOOKUP(D42,#REF!,4,0)+VLOOKUP(D42,#REF!,4,0)+VLOOKUP(D42,#REF!,4,0)+VLOOKUP(D42,#REF!,4,0)+VLOOKUP(D42,#REF!,4,0)+VLOOKUP(D42,#REF!,4,0)+#REF! -> #REF! | K42: =306256 -> 306256 | N42: =K42/27 -> 11342.815 | O42: =N42*21 -> 238199.11
D43: B.Catering/Admin: | E43: =VLOOKUP(D43,#REF!,2,0)+VLOOKUP(D43,PRE!$B$71:$E$76,2,0)+VLOOKUP(D43,#REF!,2,0)+VLOOKUP(D43,#REF!,2,0)+VLOOKUP(D43,#REF!,2,0)+VLOOKUP(D43,#REF!,2,0)+VLOOKUP(D43,#REF!,2,0)+VLOOKUP(D43,#REF!,2,0)+#REF!+VLOOKUP(D43,#REF!,2,0)+VLOOKUP(D43,#REF!,2,0)+VLOOKUP(D43,#REF!,2,0)+VLOOKUP(D43,#REF!,2,0)+VLOOKUP(D43,#REF!,2,0)+VLOOKUP(D43,#REF!,2,0)+VLOOKUP(D43,#REF!,2,0)+VLOOKUP(D43,#REF!,2,0) -> #REF! | H43: =VLOOKUP(D43,#REF!,4,0)+VLOOKUP(D43,PRE!B72:E78,4,0)+VLOOKUP(D43,#REF!,4,0)+VLOOKUP(D43,#REF!,4,0)+VLOOKUP(D43,#REF!,4,0)+VLOOKUP(D43,#REF!,4,0)+VLOOKUP(D43,#REF!,4,0)+VLOOKUP(D43,#REF!,4,0)+VLOOKUP(D43,#REF!,4,0)+VLOOKUP(D43,#REF!,4,0)+VLOOKUP(D43,#REF!,4,0)+VLOOKUP(D43,#REF!,4,0)+VLOOKUP(D43,#REF!,4,0)+VLOOKUP(D43,#REF!,4,0)+VLOOKUP(D43,#REF!,4,0)+VLOOKUP(D43,#REF!,4,0) -> #REF! | K43: 39256 | N43: =K43/27 -> 1453.9259 | O43: =N43*21 -> 30532.444
D44: C.Machinery: | E44: =VLOOKUP(D44,#REF!,2,0)+VLOOKUP(D44,PRE!$B$71:$E$76,2,0)+VLOOKUP(D44,#REF!,2,0)+VLOOKUP(D44,#REF!,2,0)+VLOOKUP(D44,#REF!,2,0)+VLOOKUP(D44,#REF!,2,0)+VLOOKUP(D44,#REF!,2,0)+VLOOKUP(D44,#REF!,2,0)+VLOOKUP(D44,#REF!,2,0)+VLOOKUP(D44,#REF!,2,0)+VLOOKUP(D44,#REF!,2,0)+VLOOKUP(D44,#REF!,2,0)+VLOOKUP(D44,#REF!,2,0)+VLOOKUP(D44,#REF!,2,0)+VLOOKUP(D44,#REF!,2,0)+VLOOKUP(D44,#REF!,2,0)+#REF!+#REF! -> #REF! | H44: =VLOOKUP(D44,#REF!,4,0)+VLOOKUP(D44,PRE!B73:E79,4,0)+VLOOKUP(D44,#REF!,4,0)+VLOOKUP(D44,#REF!,4,0)+VLOOKUP(D44,#REF!,4,0)+VLOOKUP(D44,#REF!,4,0)+VLOOKUP(D44,#REF!,4,0)+VLOOKUP(D44,#REF!,4,0)+VLOOKUP(D44,#REF!,4,0)+VLOOKUP(D44,#REF!,4,0)+VLOOKUP(D44,#REF!,4,0)+VLOOKUP(D44,#REF!,4,0)+VLOOKUP(D44,#REF!,4,0)+VLOOKUP(D44,#REF!,4,0)+VLOOKUP(D44,#REF!,4,0)+VLOOKUP(D44,#REF!,4,0)+#REF! -> #REF! | K44: =278236+10355 -> 288591 | N44: =K44/27 -> 10688.556 | O44: =N44*21 -> 224459.67
D45: D.Fuel Charge | E45: =VLOOKUP(D45,#REF!,2,0)+VLOOKUP(D45,PRE!$B$71:$E$76,2,0)+VLOOKUP(D45,#REF!,2,0)+VLOOKUP(D45,#REF!,2,0)+VLOOKUP(D45,#REF!,2,0)+VLOOKUP(D45,#REF!,2,0)+VLOOKUP(D45,#REF!,2,0)+VLOOKUP(D45,#REF!,2,0)+VLOOKUP(D45,#REF!,2,0)+VLOOKUP(D45,#REF!,2,0)+VLOOKUP(D45,#REF!,2,0)+VLOOKUP(D45,#REF!,2,0)+VLOOKUP(D45,#REF!,2,0)+VLOOKUP(D45,#REF!,2,0)+VLOOKUP(D45,#REF!,2,0)+VLOOKUP(D45,#REF!,2,0)+#REF!+#REF! -> #REF! | H45: =VLOOKUP(D45,#REF!,4,0)+VLOOKUP(D45,PRE!B74:E80,4,0)+VLOOKUP(D45,#REF!,4,0)+VLOOKUP(D45,#REF!,4,0)+VLOOKUP(D45,#REF!,4,0)+VLOOKUP(D45,#REF!,4,0)+VLOOKUP(D45,#REF!,4,0)+VLOOKUP(D45,#REF!,4,0)+VLOOKUP(D45,#REF!,4,0)+VLOOKUP(D45,#REF!,4,0)+VLOOKUP(D45,#REF!,4,0)+VLOOKUP(D45,#REF!,4,0)+VLOOKUP(D45,#REF!,4,0)+VLOOKUP(D45,#REF!,4,0)+VLOOKUP(D45,#REF!,4,0)+VLOOKUP(D45,#REF!,4,0)+#REF! -> #REF! | K45: =K44*0.53 -> 152953.23 | N45: =K45/27 -> 5664.9344 | O45: =N45*21 -> 118963.62
...

Sheet Summary-Financial (NEW)
AD1: 42948 | AG1: Fuel taken | AH1: 0.4911
R2: 0.009 | AB2: As on | AC2: xxxx | AD2: =EOMONTH(AC2,0) -> #VALUE! | AE2: =AE3 -> 29 | AF2: 25 | AI2: 31
AB3: Time Elapsed | AC3: 0 | AE3: 29
C4: Project:
C5: Cumulative | T5: For the Day
C6: Sl No | D6: PM/CM | E6: Plan Amount | F6: Achieved Amount to date | G6: Prelims Income | H6: Achieved Amount to date (Incl Prelims) | I6: Cost | J6: Prelims Cost | K6: Cost to date including prelims | L6: % of Cost | M6: % of Income | N6: Planned Contribution | O6: Contribution | P6: Contribution % | Q6: Indicate | T6: Achieved Amount to date | U6: Prelims Income | V6: Achieved Amount to date (Incl Prelims) | W6: Cost | X6: Prelims Cost | Y6: Cost to date including prelims | Z6: % of Cost | AA6: Contribution | AB6: Contribution % | AC6: Indicate
C7: 1 | D7: Site Manager 1 | E7: =SUM(E8:E13) -> 0 | F7: =SUM(F8:F13) -> 0 | G7: =SUM(G8:G13) -> 0 | H7: =SUM(F7:G7) -> 0 | I7: =I8+I9+I10+I11+I12+I13 -> 0 | J7: =J8+J9+J10+J11+J12+J13 -> 0 | K7: =SUM(I7:J7) -> 0 | L7: =IFERROR(I7/$I$28,0) -> 0 | M7: =IFERROR(H7/$H$28,0) -> 0 | N7: =2131.98168179438+10000 -> 12131.982 | O7: 13000 | P7: =IFERROR(O7/H7,"") | Q7: =IF(O7>=1,"Profit","Loss") -> Profit | R7: =H7*$R$2 -> 0 | T7: =SUM(T8:T12) -> 0 | U7: =SUM(U8:U12) -> 0 | V7: =SUM(T7:U7) -> 0 | W7: =SUM(W8:W12) -> 0 | X7: =SUM(X8:X12) -> 0 | Y7: =SUM(W7:X7) -> 0 | Z7: =IFERROR(W7/$W$28,0) -> 0 | AA7: =IFERROR(V7-Y7,"") -> 0 | AB7: =IFERROR(AA7/V7,"") | AC7: =IF(AA7>=1,"Profit","Loss") -> Loss | AK7: =O7/#REF! -> #REF! | AL7: =O7/$H$35 -> #DIV/0! | AM7: =N7/$H$28 -> #DIV/0!
C8: a | D8: Preliminaries | E8: =DPR!H14+DPR!H18+DPR!H19 -> 0 | F8: =DPR!N14+DPR!N18+DPR!N19 -> 0 | G8: =$F$29*L8 -> 0 | H8: =SUM(F8:G8) -> 0 | J8: =IFERROR($I$29*L8,0) -> 0 | K8: =SUM(I8:J8) -> 0 | L8: =IFERROR(I8/$I$28,0) -> 0 | N8: 90.419192 | O8: =IFERROR(H8-K8,"") -> 0 | P8: =IFERROR(O8/H8,"") | Q8: =IF(O8>=1,"Profit","Loss") -> Loss | R8: =H8*$R$2 -> 0 | U8: =$T$29*Z8 -> 0 | V8: =SUM(T8:U8) -> 0 | X8: =$W$29*Z8 -> 0 | Y8: =SUM(W8:X8) -> 0 | Z8: =IFERROR(W8/$W$28,0) -> 0 | AA8: =IFERROR(V8-Y8,"") -> 0 | AB8: =IFERROR(AA8/V8,"") | AC8: =IF(AA8>=1,"Profit","Loss") -> Loss | AK8: =O8/#REF! -> #REF! | AL8: =O8/$H$35 -> #DIV/0! | AM8: =N8/$H$28 -> #DIV/0!
C9: b | D9: xxxx | F9: =DPR!P215 -> 0 | G9: =$F$29*L9 -> 0 | H9: =SUM(F9:G9) -> 0 | J9: =IFERROR($I$29*L9,0) -> 0 | K9: =SUM(I9:J9) -> 0 | L9: =IFERROR(I9/$I$28,0) -> 0 | N9: 435.78181 | O9: =IFERROR(H9-K9,"") -> 0 | P9: =IFERROR(O9/H9,"") | Q9: =IF(O9>=1,"Profit","Loss") -> Loss | R9: =H9*$R$2 -> 0 | U9: =$T$29*Z9 -> 0 | V9: =SUM(T9:U9) -> 0 | X9: =$W$29*Z9 -> 0 | Y9: =SUM(W9:X9) -> 0 | Z9: =IFERROR(W9/$W$28,0) -> 0 | AA9: =IFERROR(V9-Y9,"") -> 0 | AB9: =IFERROR(AA9/V9,"") | AC9: =IF(AA9>=1,"Profit","Loss") -> Loss | AK9: =O9/#REF! -> #REF! | AL9: =O9/$H$35 -> #DIV/0! | AM9: =N9/$H$28 -> #DIV/0!
C10: c | D10: xxxx | F10: =DPR!Q215 -> 0 | G10: =$F$29*L10 -> 0 | H10: =SUM(F10:G10) -> 0 | J10: =IFERROR($I$29*L10,0) -> 0 | K10: =SUM(I10:J10) -> 0 | L10: =IFERROR(I10/$I$28,0) -> 0 | N10: 211.30837 | O10: =IFERROR(H10-K10,"") -> 0 | P10: =IFERROR(O10/H10,"") | Q10: =IF(O10>=1,"Profit","Loss") -> Loss | R10: =H10*$R$2 -> 0 | U10: =$T$29*Z10 -> 0 | V10: =SUM(T10:U10) -> 0 | X10: =$W$29*Z10 -> 0 | Y10: =SUM(W10:X10) -> 0 | Z10: =IFERROR(W10/$W$28,0) -> 0 | AA10: =IFERROR(V10-Y10,"") -> 0 | AB10: =IFERROR(AA10/V10,"") | AC10: =IF(AA10>=1,"Profit","Loss") -> Loss | AK10: =O10/#REF! -> #REF! | AL10: =O10/$H$35 -> #DIV/0! | AM10: =N10/$H$28 -> #DIV/0!
C11: d | D11: xxxx | F11: 0 | G11: =$F$29*L11 -> 0 | H11: =SUM(F11:G11) -> 0 | J11: =IFERROR($I$29*L11,0) -> 0 | K11: =SUM(I11:J11) -> 0 | L11: =IFERROR(I11/$I$28,0) -> 0 | N11: 1387.1193 | O11: =IFERROR(H11-K11,"") -> 0 | P11: =IFERROR(O11/H11,"") | Q11: =IF(O11>=1,"Profit","Loss") -> Loss | R11: =H11*$R$2 -> 0 | U11: =$T$29*Z11 -> 0 | V11: =SUM(T11:U11) -> 0 | X11: =$W$29*Z11 -> 0 | Y11: =SUM(W11:X11) -> 0 | Z11: =IFERROR(W11/$W$28,0) -> 0 | AA11: =IFERROR(V11-Y11,"") -> 0 | AB11: =IFERROR(AA11/V11,"") | AC11: =IF(AA11>=1,"Profit","Loss") -> Loss | AK11: =O11/#REF! -> #REF! | AL11: =O11/$H$35 -> #DIV/0! | AM11: =N11/$H$28 -> #DIV/0!
C12: e | D12: xxxx | F12: 0 | G12: =$F$29*L12 -> 0 | H12: =SUM(F12:G12) -> 0 | J12: =IFERROR($I$29*L12,0) -> 0 | K12: =SUM(I12:J12) -> 0 | L12: =IFERROR(I12/$I$28,0) -> 0 | N12: 1.1200604 | O12: =IFERROR(H12-K12,"") -> 0 | P12: =IFERROR(O12/H12,"") | Q12: =IF(O12>=1,"Profit","Loss") -> Loss | R12: =H12*$R$2 -> 0 | U12: =$T$29*Z12 -> 0 | V12: =SUM(T12:U12) -> 0 | X12: =$W$29*Z12 -> 0 | Y12: =SUM(W12:X12) -> 0 | Z12: =IFERROR(W12/$W$28,0) -> 0 | AA12: =IFERROR(V12-Y12,"") -> 0 | AB12: =IFERROR(AA12/V12,"") | AC12: =IF(AA12>=1,"Profit","Loss") -> Loss | AK12: =O12/#REF! -> #REF! | AL12: =O12/$H$35 -> #DIV/0! | AM12: =N12/$H$28 -> #DIV/0!
C13: f | D13: xxxx | F13: 0 | G13: =$F$29*L13 -> 0 | H13: =SUM(F13:G13) -> 0 | J13: =IFERROR($I$29*L13,0) -> 0 | K13: =SUM(I13:J13) -> 0 | L13: =IFERROR(I13/$I$28,0) -> 0 | N13: 6.23295 | O13: =IFERROR(H13-K13,"") -> 0 | P13: =IFERROR(O13/H13,"") | Q13: =IF(O13>=1,"Profit","Loss") -> Loss | R13: =H13*$R$2 -> 0 | U13: =$T$29*Z13 -> 0 | V13: =SUM(T13:U13) -> 0 | X13: =$W$29*Z13 -> 0 | Y13: =SUM(W13:X13) -> 0 | Z13: =IFERROR(W13/$W$28,0) -> 0 | AA13: =IFERROR(V13-Y13,"") -> 0 | AB13: =IFERROR(AA13/V13,"") | AC13: =IF(AA13>=1,"Profit","Loss") -> Loss | AK13: =O13/#REF! -> #REF! | AL13: =O13/$H$35 -> #DIV/0! | AM13: =N13/$H$28 -> #DIV/0!
C14: 2 | D14: Site Manager 2 | E14: =SUM(E15:E22) -> 0 | F14: =SUM(F15:F22) -> 0 | G14: =SUM(G15:G22) -> 0 | H14: =SUM(F14:G14) -> 0 | I14: =SUM(I15:I22) -> 0 | J14: =SUM(J15:J22) -> 0 | K14: =SUM(I14:J14) -> 0 | L14: =IFERROR(I14/$I$28,0) -> 0 | N14: =1755.07822362555+25000 -> 26755.078 | O14: =IFERROR(H14-K14,"") -> 0 | P14: =IFERROR(O14/H14,"") | Q14: =IF(O14>=1,"Profit","Loss") -> Loss | R14: =H14*$R$2 -> 0 | T14: =SUM(T15:T22) -> 0 | U14: =SUM(U15:U22) -> 0 | V14: =SUM(T14:U14) -> 0 | W14: =SUM(W15:W22) -> 0 | X14: =SUM(X15:X22) -> 0 | Y14: =SUM(W14:X14) -> 0 | Z14: =IFERROR(W14/$W$28,0) -> 0 | AA14: =IFERROR(V14-Y14,"") -> 0 | AB14: =IFERROR(AA14/V14,"") | AC14: =IF(AA14>=1,"Profit","Loss") -> Loss | AK14: =O14/#REF! -> #REF! | AL14: =O14/$H$35 -> #DIV/0! | AM14: =N14/$H$28 -> #DIV/0!
C15: a | D15: xxxx | G15: =$F$29*L15 -> 0 | H15: =SUM(F15:G15) -> 0 | J15: =IFERROR($I$29*L15,0) -> 0 | K15: =SUM(I15:J15) -> 0 | L15: =IFERROR(I15/$I$28,0) -> 0 | N15: 335.68109 | O15: =IFERROR(H15-K15,"") -> 0 | P15: =IFERROR(O15/H15,"") | Q15: =IF(O15>=1,"Profit","Loss") -> Loss | R15: =H15*$R$2 -> 0 | U15: =$T$29*Z15 -> 0 | V15: =SUM(T15:U15) -> 0 | X15: =$W$29*Z15 -> 0 | Y15: =SUM(W15:X15) -> 0 | Z15: =IFERROR(W15/$W$28,0) -> 0 | AA15: =IFERROR(V15-Y15,"") -> 0 | AB15: =IFERROR(AA15/V15,"") | AC15: =IF(AA15>=1,"Profit","Loss") -> Loss | AK15: =O15/#REF! -> #REF! | AL15: =O15/$H$35 -> #DIV/0! | AM15: =N15/$H$28 -> #DIV/0!
C16: b | D16: xxxx | G16: =$F$29*L16 -> 0 | H16: =SUM(F16:G16) -> 0 | J16: =IFERROR($I$29*L16,0) -> 0 | K16: =SUM(I16:J16) -> 0 | L16: =IFERROR(I16/$I$28,0) -> 0 | N16: 442.27762 | O16: =IFERROR(H16-K16,"") -> 0 | P16: =IFERROR(O16/H16,"") | Q16: =IF(O16>=1,"Profit","Loss") -> Loss | R16: =H16*$R$2 -> 0 | U16: =$T$29*Z16 -> 0 | V16: =SUM(T16:U16) -> 0 | X16: =$W$29*Z16 -> 0 | Y16: =SUM(W16:X16) -> 0 | Z16: =IFERROR(W16/$W$28,0) -> 0 | AA16: =IFERROR(V16-Y16,"") -> 0 | AB16: =IFERROR(AA16/V16,"") | AC16: =IF(AA16>=1,"Profit","Loss") -> Loss | AK16: =O16/#REF! -> #REF! | AL16: =O16/$H$35 -> #DIV/0! | AM16: =N16/$H$28 -> #DIV/0!
C17: c | D17: xxxx | G17: =$F$29*L17 -> 0 | H17: =SUM(F17:G17) -> 0 | J17: =IFERROR($I$29*L17,0) -> 0 | K17: =SUM(I17:J17) -> 0 | L17: =IFERROR(I17/$I$28,0) -> 0 | N17: 35.444981 | O17: =IFERROR(H17-K17,"") -> 0 | P17: =IFERROR(O17/H17,"") | Q17: =IF(O17>=1,"Profit","Loss") -> Loss | R17: =H17*$R$2 -> 0 | U17: =$T$29*Z17 -> 0 | V17: =SUM(T17:U17) -> 0 | X17: =$W$29*Z17 -> 0 | Y17: =SUM(W17:X17) -> 0 | Z17: =IFERROR(W17/$W$28,0) -> 0 | AA17: =IFERROR(V17-Y17,"") -> 0 | AB17: =IFERROR(AA17/V17,"") | AK17: =O17/#REF! -> #REF! | AL17: =O17/$H$35 -> #DIV/0! | AM17: =N17/$H$28 -> #DIV/0!
C18: d | D18: xxxx | G18: =$F$29*L18 -> 0 | H18: =SUM(F18:G18) -> 0 | J18: =IFERROR($I$29*L18,0) -> 0 | K18: =SUM(I18:J18) -> 0 | L18: =IFERROR(I18/$I$28,0) -> 0 | N18: 98.628151 | O18: =IFERROR(H18-K18,"") -> 0 | P18: =IFERROR(O18/H18,"") | Q18: =IF(O18>=1,"Profit","Loss") -> Loss | R18: =H18*$R$2 -> 0 | U18: =$T$29*Z18 -> 0 | V18: =SUM(T18:U18) -> 0 | X18: =$W$29*Z18 -> 0 | Y18: =SUM(W18:X18) -> 0 | Z18: =IFERROR(W18/$W$28,0) -> 0 | AA18: =IFERROR(V18-Y18,"") -> 0 | AB18: =IFERROR(AA18/V18,"") | AK18: =O18/#REF! -> #REF! | AL18: =O18/$H$35 -> #DIV/0! | AM18: =N18/$H$28 -> #DIV/0!
C19: e | D19: xxxx | G19: =$F$29*L19 -> 0 | H19: =SUM(F19:G19) -> 0 | J19: =IFERROR($I$29*L19,0) -> 0 | K19: =SUM(I19:J19) -> 0 | L19: =IFERROR(I19/$I$28,0) -> 0 | N19: 767.72531 | O19: =IFERROR(H19-K19,"") -> 0 | P19: =IFERROR(O19/H19,"") | Q19: =IF(O19>=1,"Profit","Loss") -> Loss | R19: =H19*$R$2 -> 0 | U19: =$T$29*Z19 -> 0 | V19: =SUM(T19:U19) -> 0 | X19: =$W$29*Z19 -> 0 | Y19: =SUM(W19:X19) -> 0 | Z19: =IFERROR(W19/$W$28,0) -> 0 | AA19: =IFERROR(V19-Y19,"") -> 0 | AB19: =IFERROR(AA19/V19,"") | AC19: =IF(AA19>=1,"Profit","Loss") -> Loss | AK19: =O19/#REF! -> #REF! | AL19: =O19/$H$35 -> #DIV/0! | AM19: =N19/$H$28 -> #DIV/0!
C20: f | D20: xxxx | G20: =$F$29*L20 -> 0 | H20: =SUM(F20:G20) -> 0 | J20: =IFERROR($I$29*L20,0) -> 0 | K20: =SUM(I20:J20) -> 0 | L20: =IFERROR(I20/$I$28,0) -> 0 | N20: 21.034334 | O20: =IFERROR(H20-K20,"") -> 0 | P20: =IFERROR(O20/H20,"") | Q20: =IF(O20>=1,"Profit","Loss") -> Loss | R20: =H20*$R$2 -> 0 | U20: =$T$29*Z20 -> 0 | V20: =SUM(T20:U20) -> 0 | X20: =$W$29*Z20 -> 0 | Y20: =SUM(W20:X20) -> 0 | Z20: =IFERROR(W20/$W$28,0) -> 0 | AA20: =IFERROR(V20-Y20,"") -> 0 | AB20: =IFERROR(AA20/V20,"") | AK20: =O20/#REF! -> #REF! | AL20: =O20/$H$35 -> #DIV/0! | AM20: =N20/$H$28 -> #DIV/0!
C21: g | D21: xxxx | G21: =$F$29*L21 -> 0 | H21: =SUM(F21:G21) -> 0 | J21: =IFERROR($I$29*L21,0) -> 0 | K21: =SUM(I21:J21) -> 0 | L21: =IFERROR(I21/$I$28,0) -> 0 | N21: 37.366737 | O21: =IFERROR(H21-K21,"") -> 0 | P21: =IFERROR(O21/H21,"") | Q21: =IF(O21>=1,"Profit","Loss") -> Loss | R21: =H21*$R$2 -> 0 | U21: =$T$29*Z21 -> 0 | V21: =SUM(T21:U21) -> 0 | X21: =$W$29*Z21 -> 0 | Y21: =SUM(W21:X21) -> 0 | Z21: =IFERROR(W21/$W$28,0) -> 0 | AA21: =IFERROR(V21-Y21,"") -> 0 | AB21: =IFERROR(AA21/V21,"") | AC21: =IF(AA21>=1,"Profit","Loss") -> Loss | AK21: =O21/#REF! -> #REF! | AL21: =O21/$H$35 -> #DIV/0! | AM21: =N21/$H$28 -> #DIV/0!
C22: h | D22: xxxx | G22: =$F$29*L22 -> 0 | H22: =SUM(F22:G22) -> 0 | J22: =IFERROR($I$29*L22,0) -> 0 | K22: =SUM(I22:J22) -> 0 | L22: =IFERROR(I22/$I$28,0) -> 0 | N22: 16.92 | O22: =IFERROR(H22-K22,"") -> 0 | P22: =IFERROR(O22/H22,"") | Q22: =IF(O22>=1,"Profit","Loss") -> Loss | R22: =H22*$R$2 -> 0 | U22: =$T$29*Z22 -> 0 | V22: =SUM(T22:U22) -> 0 | X22: =$W$29*Z22 -> 0 | Y22: =SUM(W22:X22) -> 0 | Z22: =IFERROR(W22/$W$28,0) -> 0 | AA22: =IFERROR(V22-Y22,"") -> 0 | AB22: =IFERROR(AA22/V22,"") | AC22: =IF(AA22>=1,"Profit","Loss") -> Loss | AK22: =O22/#REF! -> #REF! | AL22: =O22/$H$35 -> #DIV/0! | AM22: =N22/$H$28 -> #DIV/0!
